Workbook
Name BT_I: BT!$A$4:$BK$13
Name CSE_I: CSE!$A$4:$BJ$15
Name GT_I: Geotechnology!$A$4:$BJ$12
Name PE_I: Production!$A$4:$BJ$12
Name PS_I: PowerSystems!$A$4:$BJ$12

Sheet CSE
A1: UTTARKHAND TECHNICAL UNIVERSITY, DEHRADUN
A2: G.B. PANT INSTITUTE OF ENGINEERING & TECHNOLOGY, PAURI GARHWAL
A3: TABULATION CHART FOR M.TECH. COMPUTER SCIENCE & ENGINEERING FIRST YEAR ( I SEMESTER) EXAMINATION DECEMBER 2025
B4: Roll No. | C4: Enrollment No. | D4: Institute ID | E4: Student Name | F4: Father Name | G4: Subject and Subject Code | AQ4: SGPA | AR4: CGPA | AS4: Credits Earned | AT4: Result | AU4: Remarks | AV4: Cumilative Earned Credits I
A5: SC | G5: AHT 301 | K5: CST 301 | O5: CST 302 | S5: CST 304 | W5: CST 307 | AA5: AHT 302 | AE5: AHT 303 | AH5: CSP 301 | AL5: CSP 302 | AP5: Grand Total
A6: SN | G6: Advanced Mathematics | K6: Open Source Software Technologies | O6: Advanced Data Structures and Algorithms | S6: Wireless Sensor Networks | W6: Data Science | AA6: Research Methodology and IPR | AE6: Technical Writing and Presentation Skill ($) | AH6: Open Source Software Technologies Lab | AL6: Advanced Data Structures and Algorithms Lab
G7: Credits
A8: C | G8: 4 | J8: Grade | K8: 4 | N8: Grade | O8: 4 | R8: Grade | S8: 3 | V8: Grade | W8: 3 | Z8: Grade | AA8: 2 | AD8: Grade | AE8: 0 | AG8: Grade | AH8: 1 | AK8: Grade | AL8: 1 | AO8: Grade | AP8: =SUM(AL8,AH8,AE8,AA8,W8,S8,O8,K8,G8) -> 22
G9: Th. Ex. | H9: Ses. | I9: Total | K9: Th. Ex. | L9: Ses. | M9: Total | O9: Th. Ex. | P9: Ses. | Q9: Total | S9: Th. Ex. | T9: Ses. | U9: Total | W9: Th. Ex. | X9: Ses. | Y9: Total | AA9: Th. Ex. | AB9: Ses. | AC9: Total | AE9: Ses. | AF9: Total | AH9: Pr. Exa. | AI9: Ses. | AJ9: Total | AL9: Pr. Exa. | AM9: Ses. | AN9: Total | AP9: =SUM(AN10,AJ10,AC10,Y10,U10,Q10,M10,I10) -> 950 | BA9: Grade Point Summary | BJ9: TGP I
A10: M.M. | G10: 100 | H10: 50 | I10: 150 | K10: 100 | L10: 50 | M10: 150 | O10: 100 | P10: 50 | Q10: 150 | S10: 100 | T10: 50 | U10: 150 | W10: 100 | X10: 50 | Y10: 150 | AA10: 50 | AB10: 50 | AC10: 100 | AE10: 50 | AF10: 50 | AH10: 25 | AI10: 25 | AJ10: 50 | AL10: 25 | AM10: 25 | AN10: 50 | BA10: =OFFSET($G$8,0,(COLUMN(G8)-7)*4) -> 4 | BB10: =OFFSET($G$8,0,(COLUMN(H8)-7)*4) -> 4 | BC10: =OFFSET($G$8,0,(COLUMN(I8)-7)*4) -> 4 | BD10: =OFFSET($G$8,0,(COLUMN(J8)-7)*4) -> 3 | BE10: =OFFSET($G$8,0,(COLUMN(K8)-7)*4) -> 3 | BF10: =OFFSET($G$8,0,(COLUMN(L8)-7)*4) -> 2 | BG10: =OFFSET($G$8,0,(COLUMN(M8)-7)*4) -> 0 | BH10: =OFFSET($G$8,0,(COLUMN(N8)-7)*4-1) -> 1 | BI10: =OFFSET($G$8,0,(COLUMN(O8)-7)*4-1) -> 1
A11: 1 | B11: 250090705001 | C11: UTU/2507100023 | D11: 255301 | E11: Anshika Paliwal | F11: Vishwanath Paliwal | G11: 71 | H11: 48 | I11: =SUM(G11:H11) -> 119 | J11: =IF(ISTEXT(G11),IF(G11="A","Ab",IF(G11="D","Dt",IF(G11="UFM","UFM",IF(G11="NA","")))),IF(AND(ISBLANK(G11),ISBLANK(I11)),"",IF(G11<0.4*G$10,"F",IF(ISBLANK(I11),"",IF(ISTEXT(I11),I11,IF(I11>=0.9*I$10,"O",IF(I11>=0.85*I$10,"A+",IF(I11>=0.8*I$10,"A",IF(I11>=0.7*I$10,"B",IF(I11>=0.6*I$10,"C",IF(I11>=0.5*I$10,"P",IF(I11<0.5*I$10,"F",I11)))))))))))) -> B | K11: 80 | L11: 24 | M11: =SUM(K11:L11) -> 104 | N11: =IF(ISTEXT(K11),IF(K11="A","Ab",IF(K11="D","Dt",IF(K11="UFM","UFM",IF(K11="NA","")))),IF(AND(ISBLANK(K11),ISBLANK(M11)),"",IF(K11<0.4*K$10,"F",IF(ISBLANK(M11),"",IF(ISTEXT(M11),M11,IF(M11>=0.9*M$10,"O",IF(M11>=0.85*M$10,"A+",IF(M11>=0.8*M$10,"A",IF(M11>=0.7*M$10,"B",IF(M11>=0.6*M$10,"C",IF(M11>=0.5*M$10,"P",IF(M11<0.5*M$10,"F",M11)))))))))))) -> C | O11: 91 | P11: 49 | Q11: =SUM(O11:P11) -> 140 | R11: =IF(ISTEXT(O11),IF(O11="A","Ab",IF(O11="D","Dt",IF(O11="UFM","UFM",IF(O11="NA","")))),IF(AND(ISBLANK(O11),ISBLANK(Q11)),"",IF(O11<0.4*O$10,"F",IF(ISBLANK(Q11),"",IF(ISTEXT(Q11),Q11,IF(Q11>=0.9*Q$10,"O",IF(Q11>=0.85*Q$10,"A+",IF(Q11>=0.8*Q$10,"A",IF(Q11>=0.7*Q$10,"B",IF(Q11>=0.6*Q$10,"C",IF(Q11>=0.5*Q$10,"P",IF(Q11<0.5*Q$10,"F",Q11)))))))))))) -> O | S11: 76 | T11: 49 | U11: =SUM(S11:T11) -> 125 | V11: =IF(ISTEXT(S11),IF(S11="A","Ab",IF(S11="D","Dt",IF(S11="UFM","UFM",IF(S11="NA","")))),IF(AND(ISBLANK(S11),ISBLANK(U11)),"",IF(S11<0.4*S$10,"F",IF(ISBLANK(U11),"",IF(ISTEXT(U11),U11,IF(U11>=0.9*U$10,"O",IF(U11>=0.85*U$10,"A+",IF(U11>=0.8*U$10,"A",IF(U11>=0.7*U$10,"B",IF(U11>=0.6*U$10,"C",IF(U11>=0.5*U$10,"P",IF(U11<0.5*U$10,"F",U11)))))))))))) -> A | W11: 88 | X11: 49 | Y11: =SUM(W11:X11) -> 137 | Z11: =IF(ISTEXT(W11),IF(W11="A","Ab",IF(W11="D","Dt",IF(W11="UFM","UFM",IF(W11="NA","")))),IF(AND(ISBLANK(W11),ISBLANK(Y11)),"",IF(W11<0.4*W$10,"F",IF(ISBLANK(Y11),"",IF(ISTEXT(Y11),Y11,IF(Y11>=0.9*Y$10,"O",IF(Y11>=0.85*Y$10,"A+",IF(Y11>=0.8*Y$10,"A",IF(Y11>=0.7*Y$10,"B",IF(Y11>=0.6*Y$10,"C",IF(Y11>=0.5*Y$10,"P",IF(Y11<0.5*Y$10,"F",Y11)))))))))))) -> O | AA11: 44 | AB11: 48 | AC11: =SUM(AA11:AB11) -> 92 | AD11: =IF(ISTEXT(AA11),IF(AA11="A","Ab",IF(AA11="D","Dt",IF(AA11="UFM","UFM",IF(AA11="NA","")))),IF(AND(ISBLANK(AA11),ISBLANK(AC11)),"",IF(AA11<0.4*AA$10,"F",IF(ISBLANK(AC11),"",IF(ISTEXT(AC11),AC11,IF(AC11>=0.9*AC$10,"O",IF(AC11>=0.85*AC$10,"A+",IF(AC11>=0.8*AC$10,"A",IF(AC11>=0.7*AC$10,"B",IF(AC11>=0.6*AC$10,"C",IF(AC11>=0.5*AC$10,"P",IF(AC11<0.5*AC$10,"F",AC11)))))))))))) -> O | AE11: 38 | AF11: =SUM(AE11) -> 38 | AG11: =IF(ISBLANK(AF11),"",IF(ISTEXT(AF11),AF11,IF(AF11>=0.9*AF$10,"O",IF(AF11>=0.85*AF$10,"A+",IF(AF11>=0.8*AF$10,"A",IF(AF11>=0.7*AF$10,"B",IF(AF11>=0.6*AF$10,"C",IF(AF11>=0.5*AF$10,"P",IF(AF11<0.5*AF$10,"F",AF11))))))))) -> B | AH11: 23 | AI11: 24 | AJ11: =SUM(AH11:AI11) -> 47 | AK11: =IF(ISTEXT(AH11),IF(AH11="A","Ab",IF(AH11="D","Dt",IF(AH11="UFM","UFM",IF(AH11="NA","")))),IF(AND(ISBLANK(AH11),ISBLANK(AJ11)),"",IF(AH11<0.4*AH$10,"F",IF(ISBLANK(AJ11),"",IF(ISTEXT(AJ11),AJ11,IF(AJ11>=0.9*AJ$10,"O",IF(AJ11>=0.85*AJ$10,"A+",IF(AJ11>=0.8*AJ$10,"A",IF(AJ11>=0.7*AJ$10,"B",IF(AJ11>=0.6*AJ$10,"C",IF(AJ11>=0.5*AJ$10,"P",IF(AJ11<0.5*AJ$10,"F",AJ11)))))))))))) -> O | AL11: 22 | AM11: 23 | AN11: =SUM(AL11:AM11) -> 45 | AO11: =IF(ISTEXT(AL11),IF(AL11="A","Ab",IF(AL11="D","Dt",IF(AL11="UFM","UFM",IF(AL11="NA","")))),IF(AND(ISBLANK(AL11),ISBLANK(AN11)),"",IF(AL11<0.4*AL$10,"F",IF(ISBLANK(AN11),"",IF(ISTEXT(AN11),AN11,IF(AN11>=0.9*AN$10,"O",IF(AN11>=0.85*AN$10,"A+",IF(AN11>=0.8*AN$10,"A",IF(AN11>=0.7*AN$10,"B",IF(AN11>=0.6*AN$10,"C",IF(AN11>=0.5*AN$10,"P",IF(AN11<0.5*AN$10,"F",AN11)))))))))))) -> O | AP11: =SUM(AN11,AJ11,AC11,Y11,U11,Q11,M11,I11) -> 809 | AQ11: =BJ11/$AP$8 -> 8.4545455 | AR11: =AQ11 -> 8.4545455 | AS11: =SUMIF(BA11:BI11,">0",$BA$10:$BI$10) -> 22 | AT11: =IF(OR(J11=$AX$19,N11=$AX$19,R11=$AX$19, V11=$AX$19, Z11=$AX$19, AD11=$AX$19, AG11=$AX$19, AK11=$AX$19, AO11=$AX$19), "CARRY OVER", "PASS") -> PASS | AU11: =IF(AT11="CARRY OVER",_xlfn.TEXTJOIN(" ", TRUE, "BACK IN:", IF(J11=$AX$19, $G$5, ""), IF(N11=$AX$19, $K$5, ""),IF(R11=$AX$19, $O$5, ""),IF(V11=$AX$19, $S$5, ""),IF(Z11=$AX$19, $W$5, ""), IF(AD11=$AX$19, $AA$5, ""),IF(AG11=$AX$19, $AE$5, ""),IF(AK11=$AX$19, $AH$5, ""),IF(AO11=$AX$19, $AL$5, "")), " ") | AV11: =AS11 -> 22 | BA11: =INDEX($AY$13:$AY$23,MATCH(INDIRECT(ADDRESS(ROW($J11),COLUMN($J11)+(COLUMN(J11)-10)*4,1)),$AX$13:$AX$23,0)) -> 7 | BB11: =INDEX($AY$13:$AY$23,MATCH(INDIRECT(ADDRESS(ROW($J11),COLUMN($J11)+(COLUMN(K11)-10)*4,1)),$AX$13:$AX$23,0)) -> 6 | BC11: =INDEX($AY$13:$AY$23,MATCH(INDIRECT(ADDRESS(ROW($J11),COLUMN($J11)+(COLUMN(L11)-10)*4,1)),$AX$13:$AX$23,0)) -> 10 | BD11: =INDEX($AY$13:$AY$23,MATCH(INDIRECT(ADDRESS(ROW($J11),COLUMN($J11)+(COLUMN(M11)-10)*4,1)),$AX$13:$AX$23,0)) -> 8 | BE11: =INDEX($AY$13:$AY$23,MATCH(INDIRECT(ADDRESS(ROW($J11),COLUMN($J11)+(COLUMN(N11)-10)*4,1)),$AX$13:$AX$23,0)) -> 10 | BF11: =INDEX($AY$13:$AY$23,MATCH(INDIRECT(ADDRESS(ROW($J11),COLUMN($J11)+(COLUMN(O11)-10)*4,1)),$AX$13:$AX$23,0)) -> 10 | BG11: =INDEX($AY$13:$AY$23,MATCH(INDIRECT(ADDRESS(ROW($J11),COLUMN($J11)+(COLUMN(P11)-10)*4-1,1)),$AX$13:$AX$23,0)) -> 7 | BH11: =INDEX($AY$13:$AY$23,MATCH(INDIRECT(ADDRESS(ROW($J11),COLUMN($J11)+(COLUMN(Q11)-10)*4-1,1)),$AX$13:$AX$23,0)) -> 10 | BI11: =INDEX($AY$13:$AY$23,MATCH(INDIRECT(ADDRESS(ROW($J11),COLUMN($J11)+(COLUMN(R11)-10)*4-1,1)),$AX$13:$AX$23,0)) -> 10 | BJ11: =SUMPRODUCT(BA11:BI11,$BA$10:$BI$10) -> 186
A12: 2 | B12: 250090705002 | C12: UTU/2507100031 | D12: 255302 | E12: Himanshu Mandrwal | F12: Sunil Kumar | G12: 46 | H12: 34 | I12: =SUM(G12:H12) -> 80 | J12: =IF(ISTEXT(G12),IF(G12="A","Ab",IF(G12="D","Dt",IF(G12="UFM","UFM",IF(G12="NA","")))),IF(AND(ISBLANK(G12),ISBLANK(I12)),"",IF(G12<0.4*G$10,"F",IF(ISBLANK(I12),"",IF(ISTEXT(I12),I12,IF(I12>=0.9*I$10,"O",IF(I12>=0.85*I$10,"A+",IF(I12>=0.8*I$10,"A",IF(I12>=0.7*I$10,"B",IF(I12>=0.6*I$10,"C",IF(I12>=0.5*I$10,"P",IF(I12<0.5*I$10,"F",I12)))))))))))) -> P | K12: 65 | L12: 23 | M12: =SUM(K12:L12) -> 88 | N12: =IF(ISTEXT(K12),IF(K12="A","Ab",IF(K12="D","Dt",IF(K12="UFM","UFM",IF(K12="NA","")))),IF(AND(ISBLANK(K12),ISBLANK(M12)),"",IF(K12<0.4*K$10,"F",IF(ISBLANK(M12),"",IF(ISTEXT(M12),M12,IF(M12>=0.9*M$10,"O",IF(M12>=0.85*M$10,"A+",IF(M12>=0.8*M$10,"A",IF(M12>=0.7*M$10,"B",IF(M12>=0.6*M$10,"C",IF(M12>=0.5*M$10,"P",IF(M12<0.5*M$10,"F",M12)))))))))))) -> P | O12: 58 | P12: 38 | Q12: =SUM(O12:P12) -> 96 | R12: =IF(ISTEXT(O12),IF(O12="A","Ab",IF(O12="D","Dt",IF(O12="UFM","UFM",IF(O12="NA","")))),IF(AND(ISBLANK(O12),ISBLANK(Q12)),"",IF(O12<0.4*O$10,"F",IF(ISBLANK(Q12),"",IF(ISTEXT(Q12),Q12,IF(Q12>=0.9*Q$10,"O",IF(Q12>=0.85*Q$10,"A+",IF(Q12>=0.8*Q$10,"A",IF(Q12>=0.7*Q$10,"B",IF(Q12>=0.6*Q$10,"C",IF(Q12>=0.5*Q$10,"P",IF(Q12<0.5*Q$10,"F",Q12)))))))))))) -> C | S12: 59 | T12: 43 | U12: =SUM(S12:T12) -> 102 | V12: =IF(ISTEXT(S12),IF(S12="A","Ab",IF(S12="D","Dt",IF(S12="UFM","UFM",IF(S12="NA","")))),IF(AND(ISBLANK(S12),ISBLANK(U12)),"",IF(S12<0.4*S$10,"F",IF(ISBLANK(U12),"",IF(ISTEXT(U12),U12,IF(U12>=0.9*U$10,"O",IF(U12>=0.85*U$10,"A+",IF(U12>=0.8*U$10,"A",IF(U12>=0.7*U$10,"B",IF(U12>=0.6*U$10,"C",IF(U12>=0.5*U$10,"P",IF(U12<0.5*U$10,"F",U12)))))))))))) -> C | W12: 76 | X12: 41 | Y12: =SUM(W12:X12) -> 117 | Z12: =IF(ISTEXT(W12),IF(W12="A","Ab",IF(W12="D","Dt",IF(W12="UFM","UFM",IF(W12="NA","")))),IF(AND(ISBLANK(W12),ISBLANK(Y12)),"",IF(W12<0.4*W$10,"F",IF(ISBLANK(Y12),"",IF(ISTEXT(Y12),Y12,IF(Y12>=0.9*Y$10,"O",IF(Y12>=0.85*Y$10,"A+",IF(Y12>=0.8*Y$10,"A",IF(Y12>=0.7*Y$10,"B",IF(Y12>=0.6*Y$10,"C",IF(Y12>=0.5*Y$10,"P",IF(Y12<0.5*Y$10,"F",Y12)))))))))))) -> B | AA12: 39 | AB12: 41 | AC12: =SUM(AA12:AB12) -> 80 | AD12: =IF(ISTEXT(AA12),IF(AA12="A","Ab",IF(AA12="D","Dt",IF(AA12="UFM","UFM",IF(AA12="NA","")))),IF(AND(ISBLANK(AA12),ISBLANK(AC12)),"",IF(AA12<0.4*AA$10,"F",IF(ISBLANK(AC12),"",IF(ISTEXT(AC12),AC12,IF(AC12>=0.9*AC$10,"O",IF(AC12>=0.85*AC$10,"A+",IF(AC12>=0.8*AC$10,"A",IF(AC12>=0.7*AC$10,"B",IF(AC12>=0.6*AC$10,"C",IF(AC12>=0.5*AC$10,"P",IF(AC12<0.5*AC$10,"F",AC12)))))))))))) -> A | AE12: 36 | AF12: =SUM(AE12) -> 36 | AG12: =IF(ISBLANK(AF12),"",IF(ISTEXT(AF12),AF12,IF(AF12>=0.9*AF$10,"O",IF(AF12>=0.85*AF$10,"A+",IF(AF12>=0.8*AF$10,"A",IF(AF12>=0.7*AF$10,"B",IF(AF12>=0.6*AF$10,"C",IF(AF12>=0.5*AF$10,"P",IF(AF12<0.5*AF$10,"F",AF12))))))))) -> B | AH12: 22 | AI12: 23 | AJ12: =SUM(AH12:AI12) -> 45 | AK12: =IF(ISTEXT(AH12),IF(AH12="A","Ab",IF(AH12="D","Dt",IF(AH12="UFM","UFM",IF(AH12="NA","")))),IF(AND(ISBLANK(AH12),ISBLANK(AJ12)),"",IF(AH12<0.4*AH$10,"F",IF(ISBLANK(AJ12),"",IF(ISTEXT(AJ12),AJ12,IF(AJ12>=0.9*AJ$10,"O",IF(AJ12>=0.85*AJ$10,"A+",IF(AJ12>=0.8*AJ$10,"A",IF(AJ12>=0.7*AJ$10,"B",IF(AJ12>=0.6*AJ$10,"C",IF(AJ12>=0.5*AJ$10,"P",IF(AJ12<0.5*AJ$10,"F",AJ12)))))))))))) -> O | AL12: 23 | AM12: 24 | AN12: =SUM(AL12:AM12) -> 47 | AO12: =IF(ISTEXT(AL12),IF(AL12="A","Ab",IF(AL12="D","Dt",IF(AL12="UFM","UFM",IF(AL12="NA","")))),IF(AND(ISBLANK(AL12),ISBLANK(AN12)),"",IF(AL12<0.4*AL$10,"F",IF(ISBLANK(AN12),"",IF(ISTEXT(AN12),AN12,IF(AN12>=0.9*AN$10,"O",IF(AN12>=0.85*AN$10,"A+",IF(AN12>=0.8*AN$10,"A",IF(AN12>=0.7*AN$10,"B",IF(AN12>=0.6*AN$10,"C",IF(AN12>=0.5*AN$10,"P",IF(AN12<0.5*AN$10,"F",AN12)))))))))))) -> O | AP12: =SUM(AN12,AJ12,AC12,Y12,U12,Q12,M12,I12) -> 655 | AQ12: =BJ12/$AP$8 -> 6.3181818 | AR12: =AQ12 -> 6.3181818 | AS12: =SUMIF(BA12:BI12,">0",$BA$10:$BI$10) -> 22 | AT12: =IF(OR(J12=$AX$19,N12=$AX$19,R12=$AX$19, V12=$AX$19, Z12=$AX$19, AD12=$AX$19, AG12=$AX$19, AK12=$AX$19, AO12=$AX$19), "CARRY OVER", "PASS") -> PASS | AU12: =IF(AT12="CARRY OVER",_xlfn.TEXTJOIN(" ", TRUE, "BACK IN:", IF(J12=$AX$19, $G$5, ""), IF(N12=$AX$19, $K$5, ""),IF(R12=$AX$19, $O$5, ""),IF(V12=$AX$19, $S$5, ""),IF(Z12=$AX$19, $W$5, ""), IF(AD12=$AX$19, $AA$5, ""),IF(AG12=$AX$19, $AE$5, ""),IF(AK12=$AX$19, $AH$5, ""),IF(AO12=$AX$19, $AL$5, "")), " ") | AV12: =AS12 -> 22 | AX12: Grade | AY12: Grade Point | BA12: =INDEX($AY$13:$AY$23,MATCH(INDIRECT(ADDRESS(ROW($J12),COLUMN($J12)+(COLUMN(J12)-10)*4,1)),$AX$13:$AX$23,0)) -> 5 | BB12: =INDEX($AY$13:$AY$23,MATCH(INDIRECT(ADDRESS(ROW($J12),COLUMN($J12)+(COLUMN(K12)-10)*4,1)),$AX$13:$AX$23,0)) -> 5 | BC12: =INDEX($AY$13:$AY$23,MATCH(INDIRECT(ADDRESS(ROW($J12),COLUMN($J12)+(COLUMN(L12)-10)*4,1)),$AX$13:$AX$23,0)) -> 6 | BD12: =INDEX($AY$13:$AY$23,MATCH(INDIRECT(ADDRESS(ROW($J12),COLUMN($J12)+(COLUMN(M12)-10)*4,1)),$AX$13:$AX$23,0)) -> 6 | BE12: =INDEX($AY$13:$AY$23,MATCH(INDIRECT(ADDRESS(ROW($J12),COLUMN($J12)+(COLUMN(N12)-10)*4,1)),$AX$13:$AX$23,0)) -> 7 | BF12: =INDEX($AY$13:$AY$23,MATCH(INDIRECT(ADDRESS(ROW($J12),COLUMN($J12)+(COLUMN(O12)-10)*4,1)),$AX$13:$AX$23,0)) -> 8 | BG12: =INDEX($AY$13:$AY$23,MATCH(INDIRECT(ADDRESS(ROW($J12),COLUMN($J12)+(COLUMN(P12)-10)*4-1,1)),$AX$13:$AX$23,0)) -> 7 | BH12: =INDEX($AY$13:$AY$23,MATCH(INDIRECT(ADDRESS(ROW($J12),COLUMN($J12)+(COLUMN(Q12)-10)*4-1,1)),$AX$13:$AX$23,0)) -> 10 | BI12: =INDEX($AY$13:$AY$23,MATCH(INDIRECT(ADDRESS(ROW($J12),COLUMN($J12)+(COLUMN(R12)-10)*4-1,1)),$AX$13:$AX$23,0)) -> 10 | BJ12: =SUMPRODUCT(BA12:BI12,$BA$10:$BI$10) -> 139
A13: 3 | B13: 250090705003 | C13: UTU/2507100022 | D13: 255303 | E13: Kalash Kundaliya | F13: Sanjay Prasad Kundaliya | G13: 65 | H13: 42 | I13: =SUM(G13:H13) -> 107 | J13: =IF(ISTEXT(G13),IF(G13="A","Ab",IF(G13="D","Dt",IF(G13="UFM","UFM",IF(G13="NA","")))),IF(AND(ISBLANK(G13),ISBLANK(I13)),"",IF(G13<0.4*G$10,"F",IF(ISBLANK(I13),"",IF(ISTEXT(I13),I13,IF(I13>=0.9*I$10,"O",IF(I13>=0.85*I$10,"A+",IF(I13>=0.8*I$10,"A",IF(I13>=0.7*I$10,"B",IF(I13>=0.6*I$10,"C",IF(I13>=0.5*I$10,"P",IF(I13<0.5*I$10,"F",I13)))))))))))) -> B | K13: 83 | L13: 24 | M13: =SUM(K13:L13) -> 107 | N13: =IF(ISTEXT(K13),IF(K13="A","Ab",IF(K13="D","Dt",IF(K13="UFM","UFM",IF(K13="NA","")))),IF(AND(ISBLANK(K13),ISBLANK(M13)),"",IF(K13<0.4*K$10,"F",IF(ISBLANK(M13),"",IF(ISTEXT(M13),M13,IF(M13>=0.9*M$10,"O",IF(M13>=0.85*M$10,"A+",IF(M13>=0.8*M$10,"A",IF(M13>=0.7*M$10,"B",IF(M13>=0.6*M$10,"C",IF(M13>=0.5*M$10,"P",IF(M13<0.5*M$10,"F",M13)))))))))))) -> B | O13: 81 | P13: 49 | Q13: =SUM(O13:P13) -> 130 | R13: =IF(ISTEXT(O13),IF(O13="A","Ab",IF(O13="D","Dt",IF(O13="UFM","UFM",IF(O13="NA","")))),IF(AND(ISBLANK(O13),ISBLANK(Q13)),"",IF(O13<0.4*O$10,"F",IF(ISBLANK(Q13),"",IF(ISTEXT(Q13),Q13,IF(Q13>=0.9*Q$10,"O",IF(Q13>=0.85*Q$10,"A+",IF(Q13>=0.8*Q$10,"A",IF(Q13>=0.7*Q$10,"B",IF(Q13>=0.6*Q$10,"C",IF(Q13>=0.5*Q$10,"P",IF(Q13<0.5*Q$10,"F",Q13)))))))))))) -> A+ | S13: 63 | T13: 41 | U13: =SUM(S13:T13) -> 104 | V13: =IF(ISTEXT(S13),IF(S13="A","Ab",IF(S13="D","Dt",IF(S13="UFM","UFM",IF(S13="NA","")))),IF(AND(ISBLANK(S13),ISBLANK(U13)),"",IF(S13<0.4*S$10,"F",IF(ISBLANK(U13),"",IF(ISTEXT(U13),U13,IF(U13>=0.9*U$10,"O",IF(U13>=0.85*U$10,"A+",IF(U13>=0.8*U$10,"A",IF(U13>=0.7*U$10,"B",IF(U13>=0.6*U$10,"C",IF(U13>=0.5*U$10,"P",IF(U13<0.5*U$10,"F",U13)))))))))))) -> C | W13: 69 | X13: 40 | Y13: =SUM(W13:X13) -> 109 | Z13: =IF(ISTEXT(W13),IF(W13="A","Ab",IF(W13="D","Dt",IF(W13="UFM","UFM",IF(W13="NA","")))),IF(AND(ISBLANK(W13),ISBLANK(Y13)),"",IF(W13<0.4*W$10,"F",IF(ISBLANK(Y13),"",IF(ISTEXT(Y13),Y13,IF(Y13>=0.9*Y$10,"O",IF(Y13>=0.85*Y$10,"A+",IF(Y13>=0.8*Y$10,"A",IF(Y13>=0.7*Y$10,"B",IF(Y13>=0.6*Y$10,"C",IF(Y13>=0.5*Y$10,"P",IF(Y13<0.5*Y$10,"F",Y13)))))))))))) -> B | AA13: 40 | AB13: 46 | AC13: =SUM(AA13:AB13) -> 86 | AD13: =IF(ISTEXT(AA13),IF(AA13="A","Ab",IF(AA13="D","Dt",IF(AA13="UFM","UFM",IF(AA13="NA","")))),IF(AND(ISBLANK(AA13),ISBLANK(AC13)),"",IF(AA13<0.4*AA$10,"F",IF(ISBLANK(AC13),"",IF(ISTEXT(AC13),AC13,IF(AC13>=0.9*AC$10,"O",IF(AC13>=0.85*AC$10,"A+",IF(AC13>=0.8*AC$10,"A",IF(AC13>=0.7*AC$10,"B",IF(AC13>=0.6*AC$10,"C",IF(AC13>=0.5*AC$10,"P",IF(AC13<0.5*AC$10,"F",AC13)))))))))))) -> A+ | AE13: 37 | AF13: =SUM(AE13) -> 37 | AG13: =IF(ISBLANK(AF13),"",IF(ISTEXT(AF13),AF13,IF(AF13>=0.9*AF$10,"O",IF(AF13>=0.85*AF$10,"A+",IF(AF13>=0.8*AF$10,"A",IF(AF13>=0.7*AF$10,"B",IF(AF13>=0.6*AF$10,"C",IF(AF13>=0.5*AF$10,"P",IF(AF13<0.5*AF$10,"F",AF13))))))))) -> B | AH13: 22 | AI13: 24 | AJ13: =SUM(AH13:AI13) -> 46 | AK13: =IF(ISTEXT(AH13),IF(AH13="A","Ab",IF(AH13="D","Dt",IF(AH13="UFM","UFM",IF(AH13="NA","")))),IF(AND(ISBLANK(AH13),ISBLANK(AJ13)),"",IF(AH13<0.4*AH$10,"F",IF(ISBLANK(AJ13),"",IF(ISTEXT(AJ13),AJ13,IF(AJ13>=0.9*AJ$10,"O",IF(AJ13>=0.85*AJ$10,"A+",IF(AJ13>=0.8*AJ$10,"A",IF(AJ13>=0.7*AJ$10,"B",IF(AJ13>=0.6*AJ$10,"C",IF(AJ13>=0.5*AJ$10,"P",IF(AJ13<0.5*AJ$10,"F",AJ13)))))))))))) -> O | AL13: 23 | AM13: 24 | AN13: =SUM(AL13:AM13) -> 47 | AO13: =IF(ISTEXT(AL13),IF(AL13="A","Ab",IF(AL13="D","Dt",IF(AL13="UFM","UFM",IF(AL13="NA","")))),IF(AND(ISBLANK(AL13),ISBLANK(AN13)),"",IF(AL13<0.4*AL$10,"F",IF(ISBLANK(AN13),"",IF(ISTEXT(AN13),AN13,IF(AN13>=0.9*AN$10,"O",IF(AN13>=0.85*AN$10,"A+",IF(AN13>=0.8*AN$10,"A",IF(AN13>=0.7*AN$10,"B",IF(AN13>=0.6*AN$10,"C",IF(AN13>=0.5*AN$10,"P",IF(AN13<0.5*AN$10,"F",AN13)))))))))))) -> O | AP13: =SUM(AN13,AJ13,AC13,Y13,U13,Q13,M13,I13) -> 736 | AQ13: =BJ13/$AP$8 -> 7.6818182 | AR13: =AQ13 -> 7.6818182 | AS13: =SUMIF(BA13:BI13,">0",$BA$10:$BI$10) -> 22 | AT13: =IF(OR(J13=$AX$19,N13=$AX$19,R13=$AX$19, V13=$AX$19, Z13=$AX$19, AD13=$AX$19, AG13=$AX$19, AK13=$AX$19, AO13=$AX$19), "CARRY OVER", "PASS") -> PASS | AU13: =IF(AT13="CARRY OVER",_xlfn.TEXTJOIN(" ", TRUE, "BACK IN:", IF(J13=$AX$19, $G$5, ""), IF(N13=$AX$19, $K$5, ""),IF(R13=$AX$19, $O$5, ""),IF(V13=$AX$19, $S$5, ""),IF(Z13=$AX$19, $W$5, ""), IF(AD13=$AX$19, $AA$5, ""),IF(AG13=$AX$19, $AE$5, ""),IF(AK13=$AX$19, $AH$5, ""),IF(AO13=$AX$19, $AL$5, "")), " ") | AV13: =AS13 -> 22 | AX13: O | AY13: 10 | BA13: =INDEX($AY$13:$AY$23,MATCH(INDIRECT(ADDRESS(ROW($J13),COLUMN($J13)+(COLUMN(J13)-10)*4,1)),$AX$13:$AX$23,0)) -> 7 | BB13: =INDEX($AY$13:$AY$23,MATCH(INDIRECT(ADDRESS(ROW($J13),COLUMN($J13)+(COLUMN(K13)-10)*4,1)),$AX$13:$AX$23,0)) -> 7 | BC13: =INDEX($AY$13:$AY$23,MATCH(INDIRECT(ADDRESS(ROW($J13),COLUMN($J13)+(COLUMN(L13)-10)*4,1)),$AX$13:$AX$23,0)) -> 9 | BD13: =INDEX($AY$13:$AY$23,MATCH(INDIRECT(ADDRESS(ROW($J13),COLUMN($J13)+(COLUMN(M13)-10)*4,1)),$AX$13:$AX$23,0)) -> 6 | BE13: =INDEX($AY$13:$AY$23,MATCH(INDIRECT(ADDRESS(ROW($J13),COLUMN($J13)+(COLUMN(N13)-10)*4,1)),$AX$13:$AX$23,0)) -> 7 | BF13: =INDEX($AY$13:$AY$23,MATCH(INDIRECT(ADDRESS(ROW($J13),COLUMN($J13)+(COLUMN(O13)-10)*4,1)),$AX$13:$AX$23,0)) -> 9 | BG13: =INDEX($AY$13:$AY$23,MATCH(INDIRECT(ADDRESS(ROW($J13),COLUMN($J13)+(COLUMN(P13)-10)*4-1,1)),$AX$13:$AX$23,0)) -> 7 | BH13: =INDEX($AY$13:$AY$23,MATCH(INDIRECT(ADDRESS(ROW($J13),COLUMN($J13)+(COLUMN(Q13)-10)*4-1,1)),$AX$13:$AX$23,0)) -> 10 | BI13: =INDEX($AY$13:$AY$23,MATCH(INDIRECT(ADDRESS(ROW($J13),COLUMN($J13)+(COLUMN(R13)-10)*4-1,1)),$AX$13:$AX$23,0)) -> 10 | BJ13: =SUMPRODUCT(BA13:BI13,$BA$10:$BI$10) -> 169
A14: 4 | B14: 250090705004 | C14: UTU/2507100037 | D14: 255304 | E14: Mayank Gaur | F14: Rakesh Gaur | G14: 65 | H14: 42 | I14: =SUM(G14:H14) -> 107 | J14: =IF(ISTEXT(G14),IF(G14="A","Ab",IF(G14="D","Dt",IF(G14="UFM","UFM",IF(G14="NA","")))),IF(AND(ISBLANK(G14),ISBLANK(I14)),"",IF(G14<0.4*G$10,"F",IF(ISBLANK(I14),"",IF(ISTEXT(I14),I14,IF(I14>=0.9*I$10,"O",IF(I14>=0.85*I$10,"A+",IF(I14>=0.8*I$10,"A",IF(I14>=0.7*I$10,"B",IF(I14>=0.6*I$10,"C",IF(I14>=0.5*I$10,"P",IF(I14<0.5*I$10,"F",I14)))))))))))) -> B | K14: 78 | L14: 23 | M14: =SUM(K14:L14) -> 101 | N14: =IF(ISTEXT(K14),IF(K14="A","Ab",IF(K14="D","Dt",IF(K14="UFM","UFM",IF(K14="NA","")))),IF(AND(ISBLANK(K14),ISBLANK(M14)),"",IF(K14<0.4*K$10,"F",IF(ISBLANK(M14),"",IF(ISTEXT(M14),M14,IF(M14>=0.9*M$10,"O",IF(M14>=0.85*M$10,"A+",IF(M14>=0.8*M$10,"A",IF(M14>=0.7*M$10,"B",IF(M14>=0.6*M$10,"C",IF(M14>=0.5*M$10,"P",IF(M14<0.5*M$10,"F",M14)))))))))))) -> C | O14: 66 | P14: 45 | Q14: =SUM(O14:P14) -> 111 | R14: =IF(ISTEXT(O14),IF(O14="A","Ab",IF(O14="D","Dt",IF(O14="UFM","UFM",IF(O14="NA","")))),IF(AND(ISBLANK(O14),ISBLANK(Q14)),"",IF(O14<0.4*O$10,"F",IF(ISBLANK(Q14),"",IF(ISTEXT(Q14),Q14,IF(Q14>=0.9*Q$10,"O",IF(Q14>=0.85*Q$10,"A+",IF(Q14>=0.8*Q$10,"A",IF(Q14>=0.7*Q$10,"B",IF(Q14>=0.6*Q$10,"C",IF(Q14>=0.5*Q$10,"P",IF(Q14<0.5*Q$10,"F",Q14)))))))))))) -> B | S14: 69 | T14: 39 | U14: =SUM(S14:T14) -> 108 | V14: =IF(ISTEXT(S14),IF(S14="A","Ab",IF(S14="D","Dt",IF(S14="UFM","UFM",IF(S14="NA","")))),IF(AND(ISBLANK(S14),ISBLANK(U14)),"",IF(S14<0.4*S$10,"F",IF(ISBLANK(U14),"",IF(ISTEXT(U14),U14,IF(U14>=0.9*U$10,"O",IF(U14>=0.85*U$10,"A+",IF(U14>=0.8*U$10,"A",IF(U14>=0.7*U$10,"B",IF(U14>=0.6*U$10,"C",IF(U14>=0.5*U$10,"P",IF(U14<0.5*U$10,"F",U14)))))))))))) -> B | W14: 69 | X14: 38 | Y14: =SUM(W14:X14) -> 107 | Z14: =IF(ISTEXT(W14),IF(W14="A","Ab",IF(W14="D","Dt",IF(W14="UFM","UFM",IF(W14="NA","")))),IF(AND(ISBLANK(W14),ISBLANK(Y14)),"",IF(W14<0.4*W$10,"F",IF(ISBLANK(Y14),"",IF(ISTEXT(Y14),Y14,IF(Y14>=0.9*Y$10,"O",IF(Y14>=0.85*Y$10,"A+",IF(Y14>=0.8*Y$10,"A",IF(Y14>=0.7*Y$10,"B",IF(Y14>=0.6*Y$10,"C",IF(Y14>=0.5*Y$10,"P",IF(Y14<0.5*Y$10,"F",Y14)))))))))))) -> B | AA14: 42 | AB14: 48 | AC14: =SUM(AA14:AB14) -> 90 | AD14: =IF(ISTEXT(AA14),IF(AA14="A","Ab",IF(AA14="D","Dt",IF(AA14="UFM","UFM",IF(AA14="NA","")))),IF(AND(ISBLANK(AA14),ISBLANK(AC14)),"",IF(AA14<0.4*AA$10,"F",IF(ISBLANK(AC14),"",IF(ISTEXT(AC14),AC14,IF(AC14>=0.9*AC$10,"O",IF(AC14>=0.85*AC$10,"A+",IF(AC14>=0.8*AC$10,"A",IF(AC14>=0.7*AC$10,"B",IF(AC14>=0.6*AC$10,"C",IF(AC14>=0.5*AC$10,"P",IF(AC14<0.5*AC$10,"F",AC14)))))))))))) -> O | AE14: 40 | AF14: =SUM(AE14) -> 40 | AG14: =IF(ISBLANK(AF14),"",IF(ISTEXT(AF14),AF14,IF(AF14>=0.9*AF$10,"O",IF(AF14>=0.85*AF$10,"A+",IF(AF14>=0.8*AF$10,"A",IF(AF14>=0.7*AF$10,"B",IF(AF14>=0.6*AF$10,"C",IF(AF14>=0.5*AF$10,"P",IF(AF14<0.5*AF$10,"F",AF14))))))))) -> A | AH14: 23 | AI14: 23 | AJ14: =SUM(AH14:AI14) -> 46 | AK14: =IF(ISTEXT(AH14),IF(AH14="A","Ab",IF(AH14="D","Dt",IF(AH14="UFM","UFM",IF(AH14="NA","")))),IF(AND(ISBLANK(AH14),ISBLANK(AJ14)),"",IF(AH14<0.4*AH$10,"F",IF(ISBLANK(AJ14),"",IF(ISTEXT(AJ14),AJ14,IF(AJ14>=0.9*AJ$10,"O",IF(AJ14>=0.85*AJ$10,"A+",IF(AJ14>=0.8*AJ$10,"A",IF(AJ14>=0.7*AJ$10,"B",IF(AJ14>=0.6*AJ$10,"C",IF(AJ14>=0.5*AJ$10,"P",IF(AJ14<0.5*AJ$10,"F",AJ14)))))))))))) -> O | AL14: 22 | AM14: 24 | AN14: =SUM(AL14:AM14) -> 46 | AO14: =IF(ISTEXT(AL14),IF(AL14="A","Ab",IF(AL14="D","Dt",IF(AL14="UFM","UFM",IF(AL14="NA","")))),IF(AND(ISBLANK(AL14),ISBLANK(AN14)),"",IF(AL14<0.4*AL$10,"F",IF(ISBLANK(AN14),"",IF(ISTEXT(AN14),AN14,IF(AN14>=0.9*AN$10,"O",IF(AN14>=0.85*AN$10,"A+",IF(AN14>=0.8*AN$10,"A",IF(AN14>=0.7*AN$10,"B",IF(AN14>=0.6*AN$10,"C",IF(AN14>=0.5*AN$10,"P",IF(AN14<0.5*AN$10,"F",AN14)))))))))))) -> O | AP14: =SUM(AN14,AJ14,AC14,Y14,U14,Q14,M14,I14) -> 716 | AQ14: =BJ14/$AP$8 -> 7.3636364 | AR14: =AQ14 -> 7.3636364 | AS14: =SUMIF(BA14:BI14,">0",$BA$10:$BI$10) -> 22 | AT14: =IF(OR(J14=$AX$19,N14=$AX$19,R14=$AX$19, V14=$AX$19, Z14=$AX$19, AD14=$AX$19, AG14=$AX$19, AK14=$AX$19, AO14=$AX$19), "CARRY OVER", "PASS") -> PASS | AU14: =IF(AT14="CARRY OVER",_xlfn.TEXTJOIN(" ", TRUE, "BACK IN:", IF(J14=$AX$19, $G$5, ""), IF(N14=$AX$19, $K$5, ""),IF(R14=$AX$19, $O$5, ""),IF(V14=$AX$19, $S$5, ""),IF(Z14=$AX$19, $W$5, ""), IF(AD14=$AX$19, $AA$5, ""),IF(AG14=$AX$19, $AE$5, ""),IF(AK14=$AX$19, $AH$5, ""),IF(AO14=$AX$19, $AL$5, "")), " ") | AV14: =AS14 -> 22 | AX14: A+ | AY14: 9 | BA14: =INDEX($AY$13:$AY$23,MATCH(INDIRECT(ADDRESS(ROW($J14),COLUMN($J14)+(COLUMN(J14)-10)*4,1)),$AX$13:$AX$23,0)) -> 7 | BB14: =INDEX($AY$13:$AY$23,MATCH(INDIRECT(ADDRESS(ROW($J14),COLUMN($J14)+(COLUMN(K14)-10)*4,1)),$AX$13:$AX$23,0)) -> 6 | BC14: =INDEX($AY$13:$AY$23,MATCH(INDIRECT(ADDRESS(ROW($J14),COLUMN($J14)+(COLUMN(L14)-10)*4,1)),$AX$13:$AX$23,0)) -> 7 | BD14: =INDEX($AY$13:$AY$23,MATCH(INDIRECT(ADDRESS(ROW($J14),COLUMN($J14)+(COLUMN(M14)-10)*4,1)),$AX$13:$AX$23,0)) -> 7 | BE14: =INDEX($AY$13:$AY$23,MATCH(INDIRECT(ADDRESS(ROW($J14),COLUMN($J14)+(COLUMN(N14)-10)*4,1)),$AX$13:$AX$23,0)) -> 7 | BF14: =INDEX($AY$13:$AY$23,MATCH(INDIRECT(ADDRESS(ROW($J14),COLUMN($J14)+(COLUMN(O14)-10)*4,1)),$AX$13:$AX$23,0)) -> 10 | BG14: =INDEX($AY$13:$AY$23,MATCH(INDIRECT(ADDRESS(ROW($J14),COLUMN($J14)+(COLUMN(P14)-10)*4-1,1)),$AX$13:$AX$23,0)) -> 8 | BH14: =INDEX($AY$13:$AY$23,MATCH(INDIRECT(ADDRESS(ROW($J14),COLUMN($J14)+(COLUMN(Q14)-10)*4-1,1)),$AX$13:$AX$23,0)) -> 10 | BI14: =INDEX($AY$13:$AY$23,MATCH(INDIRECT(ADDRESS(ROW($J14),COLUMN($J14)+(COLUMN(R14)-10)*4-1,1)),$AX$13:$AX$23,0)) -> 10 | BJ14: =SUMPRODUCT(BA14:BI14,$BA$10:$BI$10) -> 162
A15: 5 | B15: 250090705005 | C15: PUTU/2507100070 | D15: 255305 | E15: Rajesh Kumar | F15: Ranjeet Singh | G15: D | H15: 41 | I15: =SUM(G15:H15) -> 41 | J15: =IF(ISTEXT(G15),IF(G15="A","Ab",IF(G15="D","Dt",IF(G15="UFM","UFM",IF(G15="NA","")))),IF(AND(ISBLANK(G15),ISBLANK(I15)),"",IF(G15<0.4*G$10,"F",IF(ISBLANK(I15),"",IF(ISTEXT(I15),I15,IF(I15>=0.9*I$10,"O",IF(I15>=0.85*I$10,"A+",IF(I15>=0.8*I$10,"A",IF(I15>=0.7*I$10,"B",IF(I15>=0.6*I$10,"C",IF(I15>=0.5*I$10,"P",IF(I15<0.5*I$10,"F",I15)))))))))))) -> Dt | K15: D | L15: D | M15: =SUM(K15:L15) -> 0 | N15: =IF(ISTEXT(K15),IF(K15="A","Ab",IF(K15="D","Dt",IF(K15="UFM","UFM",IF(K15="NA","")))),IF(AND(ISBLANK(K15),ISBLANK(M15)),"",IF(K15<0.4*K$10,"F",IF(ISBLANK(M15),"",IF(ISTEXT(M15),M15,IF(M15>=0.9*M$10,"O",IF(M15>=0.85*M$10,"A+",IF(M15>=0.8*M$10,"A",IF(M15>=0.7*M$10,"B",IF(M15>=0.6*M$10,"C",IF(M15>=0.5*M$10,"P",IF(M15<0.5*M$10,"F",M15)))))))))))) -> Dt | O15: D | P15: D | Q15: =SUM(O15:P15) -> 0 | R15: =IF(ISTEXT(O15),IF(O15="A","Ab",IF(O15="D","Dt",IF(O15="UFM","UFM",IF(O15="NA","")))),IF(AND(ISBLANK(O15),ISBLANK(Q15)),"",IF(O15<0.4*O$10,"F",IF(ISBLANK(Q15),"",IF(ISTEXT(Q15),Q15,IF(Q15>=0.9*Q$10,"O",IF(Q15>=0.85*Q$10,"A+",IF(Q15>=0.8*Q$10,"A",IF(Q15>=0.7*Q$10,"B",IF(Q15>=0.6*Q$10,"C",IF(Q15>=0.5*Q$10,"P",IF(Q15<0.5*Q$10,"F",Q15)))))))))))) -> Dt | S15: D | T15: D | U15: =SUM(S15:T15) -> 0 | V15: =IF(ISTEXT(S15),IF(S15="A","Ab",IF(S15="D","Dt",IF(S15="UFM","UFM",IF(S15="NA","")))),IF(AND(ISBLANK(S15),ISBLANK(U15)),"",IF(S15<0.4*S$10,"F",IF(ISBLANK(U15),"",IF(ISTEXT(U15),U15,IF(U15>=0.9*U$10,"O",IF(U15>=0.85*U$10,"A+",IF(U15>=0.8*U$10,"A",IF(U15>=0.7*U$10,"B",IF(U15>=0.6*U$10,"C",IF(U15>=0.5*U$10,"P",IF(U15<0.5*U$10,"F",U15)))))))))))) -> Dt | W15: D | X15: D | Y15: =SUM(W15:X15) -> 0 | Z15: =IF(ISTEXT(W15),IF(W15="A","Ab",IF(W15="D","Dt",IF(W15="UFM","UFM",IF(W15="NA","")))),IF(AND(ISBLANK(W15),ISBLANK(Y15)),"",IF(W15<0.4*W$10,"F",IF(ISBLANK(Y15),"",IF(ISTEXT(Y15),Y15,IF(Y15>=0.9*Y$10,"O",IF(Y15>=0.85*Y$10,"A+",IF(Y15>=0.8*Y$10,"A",IF(Y15>=0.7*Y$10,"B",IF(Y15>=0.6*Y$10,"C",IF(Y15>=0.5*Y$10,"P",IF(Y15<0.5*Y$10,"F",Y15)))))))))))) -> Dt | AA15: D | AB15: 32 | AC15: =SUM(AA15:AB15) -> 32 | AD15: =IF(ISTEXT(AA15),IF(AA15="A","Ab",IF(AA15="D","Dt",IF(AA15="UFM","UFM",IF(AA15="NA","")))),IF(AND(ISBLANK(AA15),ISBLANK(AC15)),"",IF(AA15<0.4*AA$10,"F",IF(ISBLANK(AC15),"",IF(ISTEXT(AC15),AC15,IF(AC15>=0.9*AC$10,"O",IF(AC15>=0.85*AC$10,"A+",IF(AC15>=0.8*AC$10,"A",IF(AC15>=0.7*AC$10,"B",IF(AC15>=0.6*AC$10,"C",IF(AC15>=0.5*AC$10,"P",IF(AC15<0.5*AC$10,"F",AC15)))))))))))) -> Dt | AE15: 26 | AF15: =SUM(AE15) -> 26 | AG15: =IF(ISBLANK(AF15),"",IF(ISTEXT(AF15),AF15,IF(AF15>=0.9*AF$10,"O",IF(AF15>=0.85*AF$10,"A+",IF(AF15>=0.8*AF$10,"A",IF(AF15>=0.7*AF$10,"B",IF(AF15>=0.6*AF$10,"C",IF(AF15>=0.5*AF$10,"P",IF(AF15<0.5*AF$10,"F",AF15))))))))) -> P | AH15: D | AI15: 24 | AJ15: =SUM(AH15:AI15) -> 24 | AK15: =IF(ISTEXT(AH15),IF(AH15="A","Ab",IF(AH15="D","Dt",IF(AH15="UFM","UFM",IF(AH15="NA","")))),IF(AND(ISBLANK(AH15),ISBLANK(AJ15)),"",IF(AH15<0.4*AH$10,"F",IF(ISBLANK(AJ15),"",IF(ISTEXT(AJ15),AJ15,IF(AJ15>=0.9*AJ$10,"O",IF(AJ15>=0.85*AJ$10,"A+",IF(AJ15>=0.8*AJ$10,"A",IF(AJ15>=0.7*AJ$10,"B",IF(AJ15>=0.6*AJ$10,"C",IF(AJ15>=0.5*AJ$10,"P",IF(AJ15<0.5*AJ$10,"F",AJ15)))))))))))) -> Dt | AL15: D | AM15: D | AN15: =SUM(AL15:AM15) -> 0 | AO15: =IF(ISTEXT(AL15),IF(AL15="A","Ab",IF(AL15="D","Dt",IF(AL15="UFM","UFM",IF(AL15="NA","")))),IF(AND(ISBLANK(AL15),ISBLANK(AN15)),"",IF(AL15<0.4*AL$10,"F",IF(ISBLANK(AN15),"",IF(ISTEXT(AN15),AN15,IF(AN15>=0.9*AN$10,"O",IF(AN15>=0.85*AN$10,"A+",IF(AN15>=0.8*AN$10,"A",IF(AN15>=0.7*AN$10,"B",IF(AN15>=0.6*AN$10,"C",IF(AN15>=0.5*AN$10,"P",IF(AN15<0.5*AN$10,"F",AN15)))))))))))) -> Dt | AP15: =SUM(AN15,AJ15,AC15,Y15,U15,Q15,M15,I15) -> 97 | AQ15: =BJ15/$AP$8 -> 0 | AR15: =AQ15 -> 0 | AS15: =SUMIF(BA15:BI15,">0",$BA$10:$BI$10) -> 0 | AT15: =IF(OR(J15=$AX$22,N15=$AX$22,R15=$AX$22, V15=$AX$22, Z15=$AX$22, AD15=$AX$22, AG15=$AX$22, AK15=$AX$22, AO15=$AX$22), "CARRY OVER", "PASS") -> CARRY OVER | AU15: =IF(AT15="CARRY OVER",_xlfn.TEXTJOIN(" ", TRUE, "BACK IN:", IF(J15=$AX$22, $G$5, ""), IF(N15=$AX$22, $K$5, ""),IF(R15=$AX$22, $O$5, ""),IF(V15=$AX$22, $S$5, ""),IF(Z15=$AX$22, $W$5, ""), IF(AD15=$AX$22, $AA$5, ""),IF(AG15=$AX$22, $AE$5, ""),IF(AK15=$AX$22, $AH$5, ""),IF(AO15=$AX$22, $AL$5, "")), " ") -> BACK IN: AHT 301 CST 301 CST 302 CST 304 CST 307 AHT 302 CSP 301 CSP 302 | AV15: =AS15 -> 0 | AX15: A | AY15: 8 | BA15: =INDEX($AY$13:$AY$23,MATCH(INDIRECT(ADDRESS(ROW($J15),COLUMN($J15)+(COLUMN(J15)-10)*4,1)),$AX$13:$AX$23,0)) -> 0 | BB15: =INDEX($AY$13:$AY$23,MATCH(INDIRECT(ADDRESS(ROW($J15),COLUMN($J15)+(COLUMN(K15)-10)*4,1)),$AX$13:$AX$23,0)) -> 0 | BC15: =INDEX($AY$13:$AY$23,MATCH(INDIRECT(ADDRESS(ROW($J15),COLUMN($J15)+(COLUMN(L15)-10)*4,1)),$AX$13:$AX$23,0)) -> 0 | BD15: =INDEX($AY$13:$AY$23,MATCH(INDIRECT(ADDRESS(ROW($J15),COLUMN($J15)+(COLUMN(M15)-10)*4,1)),$AX$13:$AX$23,0)) -> 0 | BE15: =INDEX($AY$13:$AY$23,MATCH(INDIRECT(ADDRESS(ROW($J15),COLUMN($J15)+(COLUMN(N15)-10)*4,1)),$AX$13:$AX$23,0)) -> 0 | BF15: =INDEX($AY$13:$AY$23,MATCH(INDIRECT(ADDRESS(ROW($J15),COLUMN($J15)+(COLUMN(O15)-10)*4,1)),$AX$13:$AX$23,0)) -> 0 | BG15: =INDEX($AY$13:$AY$23,MATCH(INDIRECT(ADDRESS(ROW($J15),COLUMN($J15)+(COLUMN(P15)-10)*4-1,1)),$AX$13:$AX$23,0)) -> 5 | BH15: =INDEX($AY$13:$AY$23,MATCH(INDIRECT(ADDRESS(ROW($J15),COLUMN($J15)+(COLUMN(Q15)-10)*4-1,1)),$AX$13:$AX$23,0)) -> 0 | BI15: =INDEX($AY$13:$AY$23,MATCH(INDIRECT(ADDRESS(ROW($J15),COLUMN($J15)+(COLUMN(R15)-10)*4-1,1)),$AX$13:$AX$23,0)) -> 0 | BJ15: =SUMPRODUCT(BA15:BI15,$BA$10:$BI$10) -> 0
AX16: B | AY16: 7
AX17: C | AY17: 6
AX18: P | AY18: 5
AX19: F | AY19: 0
AX20: Ab | AY20: 0
AX21: UFM | AY21: 0
AX22: Dt | AY22: 0
AX23: ="" | AY23: =""

Sheet Production
A1: UTTARAKHAND TECHNICAL UNIVERSITY, DEHRADUN
A2: G.B. PANT INSTITUTE OF ENGINEERING & TECHNOLOGY, PAURI GARHWAL
A3: TABULATION CHART FOR M.TECH. PRODUCTION ENGINEERING FIRST YEAR ( I SEMESTER) EXAMINATION DECEMBER 2025
B4: Roll No. | C4: Enrollment No. | D4: Institute ID | E4: Student Name | F4: Father Name | G4: Subject and Subject Code | AQ4: SGPA | AR4: CGPA | AS4: Credits Earned | AT4: Result | AU4: Remarks | AV4: Cumilative Earned Credits I
A5: SC | G5: AHT 301 | K5: PET 301 | O5: PET 302 | S5: PET 308 | W5: PET 312 | AA5: AHT 302 | AE5: AHT 303 | AH5: PEP 301 | AL5: PEP 302 | AP5: Grand Total
A6: SN | G6: Advanced Mathematics | K6: Machining Science | O6: Industrial Tribology | S6: Automated Material Handeling System | W6: Total Quality Management | AA6: Research Methodology and IPR | AE6: Technical Writing and Presentation Skill ($) | AH6: Machining Science Lab | AL6: Industrial Tribology Lab
G7: Credits
A8: C | G8: 4 | J8: Grade | K8: 4 | N8: Grade | O8: 4 | R8: Grade | S8: 3 | V8: Grade | W8: 3 | Z8: Grade | AA8: 2 | AD8: Grade | AE8: 0 | AG8: Grade | AH8: 1 | AK8: Grade | AL8: 1 | AO8: Grade | AP8: =SUM(AL8,AH8,AE8,AA8,W8,S8,O8,K8,G8) -> 22
G9: Th. Ex. | H9: Ses. | I9: Total | K9: Th. Ex. | L9: Ses. | M9: Total | O9: Th. Ex. | P9: Ses. | Q9: Total | S9: Th. Ex. | T9: Ses. | U9: Total | W9: Th. Ex. | X9: Ses. | Y9: Total | AA9: Th. Ex. | AB9: Ses. | AC9: Total | AE9: Ses. | AF9: Total | AH9: Th. Ex. | AI9: Ses. | AJ9: Total | AL9: Th. Ex. | AM9: Ses. | AN9: Total | AP9: =SUM(AN10,AJ10,AC10,Y10,U10,Q10,M10,I10) -> 950 | BA9: Grade Point Summary | BJ9: TGP I
A10: M.M. | G10: 100 | H10: 50 | I10: 150 | K10: 100 | L10: 50 | M10: 150 | O10: 100 | P10: 50 | Q10: 150 | S10: 100 | T10: 50 | U10: 150 | W10: 100 | X10: 50 | Y10: 150 | AA10: 50 | AB10: 50 | AC10: 100 | AE10: 50 | AF10: 50 | AH10: 25 | AI10: 25 | AJ10: 50 | AL10: 25 | AM10: 25 | AN10: 50 | BA10: =OFFSET($G$8,0,(COLUMN(G8)-7)*4) -> 4 | BB10: =OFFSET($G$8,0,(COLUMN(H8)-7)*4) -> 4 | BC10: =OFFSET($G$8,0,(COLUMN(I8)-7)*4) -> 4 | BD10: =OFFSET($G$8,0,(COLUMN(J8)-7)*4) -> 3 | BE10: =OFFSET($G$8,0,(COLUMN(K8)-7)*4) -> 3 | BF10: =OFFSET($G$8,0,(COLUMN(L8)-7)*4) -> 2 | BG10: =OFFSET($G$8,0,(COLUMN(M8)-7)*4) -> 0 | BH10: =OFFSET($G$8,0,(COLUMN(N8)-7)*4-1) -> 1 | BI10: =OFFSET($G$8,0,(COLUMN(O8)-7)*4-1) -> 1
A11: 1 | B11: 250090707001 | C11: PUTU/2507100044 | D11: 255401 | E11: Amandeep | F11: Kripa Ram | G11: 41 | H11: 40 | I11: =SUM(G11:H11) -> 81 | J11: =IF(ISTEXT(G11),IF(G11="A","Ab",IF(G11="D","Dt",IF(G11="UFM","UFM",IF(G11="NA","")))),IF(AND(ISBLANK(G11),ISBLANK(I11)),"",IF(G11<0.4*G$10,"F",IF(ISBLANK(I11),"",IF(ISTEXT(I11),I11,IF(I11>=0.9*I$10,"O",IF(I11>=0.85*I$10,"A+",IF(I11>=0.8*I$10,"A",IF(I11>=0.7*I$10,"B",IF(I11>=0.6*I$10,"C",IF(I11>=0.5*I$10,"P",IF(I11<0.5*I$10,"F",I11)))))))))))) -> P | K11: 69 | L11: 47 | M11: =SUM(K11:L11) -> 116 | N11: =IF(ISTEXT(K11),IF(K11="A","Ab",IF(K11="D","Dt",IF(K11="UFM","UFM",IF(K11="NA","")))),IF(AND(ISBLANK(K11),ISBLANK(M11)),"",IF(K11<0.4*K$10,"F",IF(ISBLANK(M11),"",IF(ISTEXT(M11),M11,IF(M11>=0.9*M$10,"O",IF(M11>=0.85*M$10,"A+",IF(M11>=0.8*M$10,"A",IF(M11>=0.7*M$10,"B",IF(M11>=0.6*M$10,"C",IF(M11>=0.5*M$10,"P",IF(M11<0.5*M$10,"F",M11)))))))))))) -> B | O11: 86 | P11: 48 | Q11: =SUM(O11:P11) -> 134 | R11: =IF(ISTEXT(O11),IF(O11="A","Ab",IF(O11="D","Dt",IF(O11="UFM","UFM",IF(O11="NA","")))),IF(AND(ISBLANK(O11),ISBLANK(Q11)),"",IF(O11<0.4*O$10,"F",IF(ISBLANK(Q11),"",IF(ISTEXT(Q11),Q11,IF(Q11>=0.9*Q$10,"O",IF(Q11>=0.85*Q$10,"A+",IF(Q11>=0.8*Q$10,"A",IF(Q11>=0.7*Q$10,"B",IF(Q11>=0.6*Q$10,"C",IF(Q11>=0.5*Q$10,"P",IF(Q11<0.5*Q$10,"F",Q11)))))))))))) -> A+ | S11: 66 | T11: 44 | U11: =SUM(S11:T11) -> 110 | V11: =IF(ISTEXT(S11),IF(S11="A","Ab",IF(S11="D","Dt",IF(S11="UFM","UFM",IF(S11="NA","")))),IF(AND(ISBLANK(S11),ISBLANK(U11)),"",IF(S11<0.4*S$10,"F",IF(ISBLANK(U11),"",IF(ISTEXT(U11),U11,IF(U11>=0.9*U$10,"O",IF(U11>=0.85*U$10,"A+",IF(U11>=0.8*U$10,"A",IF(U11>=0.7*U$10,"B",IF(U11>=0.6*U$10,"C",IF(U11>=0.5*U$10,"P",IF(U11<0.5*U$10,"F",U11)))))))))))) -> B | W11: 79 | X11: 47 | Y11: =SUM(W11:X11) -> 126 | Z11: =IF(ISTEXT(W11),IF(W11="A","Ab",IF(W11="D","Dt",IF(W11="UFM","UFM",IF(W11="NA","")))),IF(AND(ISBLANK(W11),ISBLANK(Y11)),"",IF(W11<0.4*W$10,"F",IF(ISBLANK(Y11),"",IF(ISTEXT(Y11),Y11,IF(Y11>=0.9*Y$10,"O",IF(Y11>=0.85*Y$10,"A+",IF(Y11>=0.8*Y$10,"A",IF(Y11>=0.7*Y$10,"B",IF(Y11>=0.6*Y$10,"C",IF(Y11>=0.5*Y$10,"P",IF(Y11<0.5*Y$10,"F",Y11)))))))))))) -> A | AA11: 43 | AB11: 42 | AC11: =SUM(AA11:AB11) -> 85 | AD11: =IF(ISTEXT(AA11),IF(AA11="A","Ab",IF(AA11="D","Dt",IF(AA11="UFM","UFM",IF(AA11="NA","")))),IF(AND(ISBLANK(AA11),ISBLANK(AC11)),"",IF(AA11<0.4*AA$10,"F",IF(ISBLANK(AC11),"",IF(ISTEXT(AC11),AC11,IF(AC11>=0.9*AC$10,"O",IF(AC11>=0.85*AC$10,"A+",IF(AC11>=0.8*AC$10,"A",IF(AC11>=0.7*AC$10,"B",IF(AC11>=0.6*AC$10,"C",IF(AC11>=0.5*AC$10,"P",IF(AC11<0.5*AC$10,"F",AC11)))))))))))) -> A+ | AE11: 34 | AF11: =SUM(AE11) -> 34 | AG11: =IF(ISBLANK(AF11),"",IF(ISTEXT(AF11),AF11,IF(AF11>=0.9*AF$10,"O",IF(AF11>=0.85*AF$10,"A+",IF(AF11>=0.8*AF$10,"A",IF(AF11>=0.7*AF$10,"B",IF(AF11>=0.6*AF$10,"C",IF(AF11>=0.5*AF$10,"P",IF(AF11<0.5*AF$10,"F",AF11))))))))) -> C | AH11: 23 | AI11: 24 | AJ11: =SUM(AH11:AI11) -> 47 | AK11: =IF(ISTEXT(AH11),IF(AH11="A","Ab",IF(AH11="D","Dt",IF(AH11="UFM","UFM",IF(AH11="NA","")))),IF(AND(ISBLANK(AH11),ISBLANK(AJ11)),"",IF(AH11<0.4*AH$10,"F",IF(ISBLANK(AJ11),"",IF(ISTEXT(AJ11),AJ11,IF(AJ11>=0.9*AJ$10,"O",IF(AJ11>=0.85*AJ$10,"A+",IF(AJ11>=0.8*AJ$10,"A",IF(AJ11>=0.7*AJ$10,"B",IF(AJ11>=0.6*AJ$10,"C",IF(AJ11>=0.5*AJ$10,"P",IF(AJ11<0.5*AJ$10,"F",AJ11)))))))))))) -> O | AL11: 23 | AM11: 23 | AN11: =SUM(AL11:AM11) -> 46 | AO11: =IF(ISTEXT(AL11),IF(AL11="A","Ab",IF(AL11="D","Dt",IF(AL11="UFM","UFM",IF(AL11="NA","")))),IF(AND(ISBLANK(AL11),ISBLANK(AN11)),"",IF(AL11<0.4*AL$10,"F",IF(ISBLANK(AN11),"",IF(ISTEXT(AN11),AN11,IF(AN11>=0.9*AN$10,"O",IF(AN11>=0.85*AN$10,"A+",IF(AN11>=0.8*AN$10,"A",IF(AN11>=0.7*AN$10,"B",IF(AN11>=0.6*AN$10,"C",IF(AN11>=0.5*AN$10,"P",IF(AN11<0.5*AN$10,"F",AN11)))))))))))) -> O | AP11: =SUM(AN11,AJ11,AC11,Y11,U11,Q11,M11,I11) -> 745 | AQ11: =BJ11/$AP$8 -> 7.5909091 | AR11: =AQ11 -> 7.5909091 | AS11: =SUMIF(BA11:BI11,">0",$BA$10:$BI$10) -> 22 | AT11: =IF(OR(J11=$AX$19,N11=$AX$19,R11=$AX$19, V11=$AX$19, Z11=$AX$19, AD11=$AX$19, AG11=$AX$19, AK11=$AX$19, AO11=$AX$19), "CARRY OVER", "PASS") -> PASS | AU11: =IF(AT11="CARRY OVER",_xlfn.TEXTJOIN(" ", TRUE, "BACK IN:", IF(J11=$AX$19, $G$5, ""), IF(N11=$AX$19, $K$5, ""),IF(R11=$AX$19, $O$5, ""),IF(V11=$AX$19, $S$5, ""),IF(Z11=$AX$19, $W$5, ""), IF(AD11=$AX$19, $AA$5, ""),IF(AG11=$AX$19, $AE$5, ""),IF(AK11=$AX$19, $AH$5, ""),IF(AO11=$AX$19, $AL$5, "")), " ") | AV11: =AS11 -> 22 | BA11: =INDEX($AY$13:$AY$23,MATCH(INDIRECT(ADDRESS(ROW($J11),COLUMN($J11)+(COLUMN(J11)-10)*4,1)),$AX$13:$AX$23,0)) -> 5 | BB11: =INDEX($AY$13:$AY$23,MATCH(INDIRECT(ADDRESS(ROW($J11),COLUMN($J11)+(COLUMN(K11)-10)*4,1)),$AX$13:$AX$23,0)) -> 7 | BC11: =INDEX($AY$13:$AY$23,MATCH(INDIRECT(ADDRESS(ROW($J11),COLUMN($J11)+(COLUMN(L11)-10)*4,1)),$AX$13:$AX$23,0)) -> 9 | BD11: =INDEX($AY$13:$AY$23,MATCH(INDIRECT(ADDRESS(ROW($J11),COLUMN($J11)+(COLUMN(M11)-10)*4,1)),$AX$13:$AX$23,0)) -> 7 | BE11: =INDEX($AY$13:$AY$23,MATCH(INDIRECT(ADDRESS(ROW($J11),COLUMN($J11)+(COLUMN(N11)-10)*4,1)),$AX$13:$AX$23,0)) -> 8 | BF11: =INDEX($AY$13:$AY$23,MATCH(INDIRECT(ADDRESS(ROW($J11),COLUMN($J11)+(COLUMN(O11)-10)*4,1)),$AX$13:$AX$23,0)) -> 9 | BG11: =INDEX($AY$13:$AY$23,MATCH(INDIRECT(ADDRESS(ROW($J11),COLUMN($J11)+(COLUMN(P11)-10)*4-1,1)),$AX$13:$AX$23,0)) -> 6 | BH11: =INDEX($AY$13:$AY$23,MATCH(INDIRECT(ADDRESS(ROW($J11),COLUMN($J11)+(COLUMN(Q11)-10)*4-1,1)),$AX$13:$AX$23,0)) -> 10 | BI11: =INDEX($AY$13:$AY$23,MATCH(INDIRECT(ADDRESS(ROW($J11),COLUMN($J11)+(COLUMN(R11)-10)*4-1,1)),$AX$13:$AX$23,0)) -> 10 | BJ11: =SUMPRODUCT(BA11:BI11,$BA$10:$BI$10) -> 167
A12: 2 | B12: 250090707002 | C12: PUTU/2507100051 | D12: 255402 | E12: Yukti Dinkar | F12: Hemant Kumar | G12: 44 | H12: 46 | I12: =SUM(G12:H12) -> 90 | J12: =IF(ISTEXT(G12),IF(G12="A","Ab",IF(G12="D","Dt",IF(G12="UFM","UFM",IF(G12="NA","")))),IF(AND(ISBLANK(G12),ISBLANK(I12)),"",IF(G12<0.4*G$10,"F",IF(ISBLANK(I12),"",IF(ISTEXT(I12),I12,IF(I12>=0.9*I$10,"O",IF(I12>=0.85*I$10,"A+",IF(I12>=0.8*I$10,"A",IF(I12>=0.7*I$10,"B",IF(I12>=0.6*I$10,"C",IF(I12>=0.5*I$10,"P",IF(I12<0.5*I$10,"F",I12)))))))))))) -> C | K12: 63 | L12: 48 | M12: =SUM(K12:L12) -> 111 | N12: =IF(ISTEXT(K12),IF(K12="A","Ab",IF(K12="D","Dt",IF(K12="UFM","UFM",IF(K12="NA","")))),IF(AND(ISBLANK(K12),ISBLANK(M12)),"",IF(K12<0.4*K$10,"F",IF(ISBLANK(M12),"",IF(ISTEXT(M12),M12,IF(M12>=0.9*M$10,"O",IF(M12>=0.85*M$10,"A+",IF(M12>=0.8*M$10,"A",IF(M12>=0.7*M$10,"B",IF(M12>=0.6*M$10,"C",IF(M12>=0.5*M$10,"P",IF(M12<0.5*M$10,"F",M12)))))))))))) -> B | O12: 70 | P12: 41 | Q12: =SUM(O12:P12) -> 111 | R12: =IF(ISTEXT(O12),IF(O12="A","Ab",IF(O12="D","Dt",IF(O12="UFM","UFM",IF(O12="NA","")))),IF(AND(ISBLANK(O12),ISBLANK(Q12)),"",IF(O12<0.4*O$10,"F",IF(ISBLANK(Q12),"",IF(ISTEXT(Q12),Q12,IF(Q12>=0.9*Q$10,"O",IF(Q12>=0.85*Q$10,"A+",IF(Q12>=0.8*Q$10,"A",IF(Q12>=0.7*Q$10,"B",IF(Q12>=0.6*Q$10,"C",IF(Q12>=0.5*Q$10,"P",IF(Q12<0.5*Q$10,"F",Q12)))))))))))) -> B | S12: 61 | T12: 41 | U12: =SUM(S12:T12) -> 102 | V12: =IF(ISTEXT(S12),IF(S12="A","Ab",IF(S12="D","Dt",IF(S12="UFM","UFM",IF(S12="NA","")))),IF(AND(ISBLANK(S12),ISBLANK(U12)),"",IF(S12<0.4*S$10,"F",IF(ISBLANK(U12),"",IF(ISTEXT(U12),U12,IF(U12>=0.9*U$10,"O",IF(U12>=0.85*U$10,"A+",IF(U12>=0.8*U$10,"A",IF(U12>=0.7*U$10,"B",IF(U12>=0.6*U$10,"C",IF(U12>=0.5*U$10,"P",IF(U12<0.5*U$10,"F",U12)))))))))))) -> C | W12: 77 | X12: 45 | Y12: =SUM(W12:X12) -> 122 | Z12: =IF(ISTEXT(W12),IF(W12="A","Ab",IF(W12="D","Dt",IF(W12="UFM","UFM",IF(W12="NA","")))),IF(AND(ISBLANK(W12),ISBLANK(Y12)),"",IF(W12<0.4*W$10,"F",IF(ISBLANK(Y12),"",IF(ISTEXT(Y12),Y12,IF(Y12>=0.9*Y$10,"O",IF(Y12>=0.85*Y$10,"A+",IF(Y12>=0.8*Y$10,"A",IF(Y12>=0.7*Y$10,"B",IF(Y12>=0.6*Y$10,"C",IF(Y12>=0.5*Y$10,"P",IF(Y12<0.5*Y$10,"F",Y12)))))))))))) -> A | AA12: 40 | AB12: 43 | AC12: =SUM(AA12:AB12) -> 83 | AD12: =IF(ISTEXT(AA12),IF(AA12="A","Ab",IF(AA12="D","Dt",IF(AA12="UFM","UFM",IF(AA12="NA","")))),IF(AND(ISBLANK(AA12),ISBLANK(AC12)),"",IF(AA12<0.4*AA$10,"F",IF(ISBLANK(AC12),"",IF(ISTEXT(AC12),AC12,IF(AC12>=0.9*AC$10,"O",IF(AC12>=0.85*AC$10,"A+",IF(AC12>=0.8*AC$10,"A",IF(AC12>=0.7*AC$10,"B",IF(AC12>=0.6*AC$10,"C",IF(AC12>=0.5*AC$10,"P",IF(AC12<0.5*AC$10,"F",AC12)))))))))))) -> A | AE12: 38 | AF12: =SUM(AE12) -> 38 | AG12: =IF(ISBLANK(AF12),"",IF(ISTEXT(AF12),AF12,IF(AF12>=0.9*AF$10,"O",IF(AF12>=0.85*AF$10,"A+",IF(AF12>=0.8*AF$10,"A",IF(AF12>=0.7*AF$10,"B",IF(AF12>=0.6*AF$10,"C",IF(AF12>=0.5*AF$10,"P",IF(AF12<0.5*AF$10,"F",AF12))))))))) -> B | AH12: 22 | AI12: 24 | AJ12: =SUM(AH12:AI12) -> 46 | AK12: =IF(ISTEXT(AH12),IF(AH12="A","Ab",IF(AH12="D","Dt",IF(AH12="UFM","UFM",IF(AH12="NA","")))),IF(AND(ISBLANK(AH12),ISBLANK(AJ12)),"",IF(AH12<0.4*AH$10,"F",IF(ISBLANK(AJ12),"",IF(ISTEXT(AJ12),AJ12,IF(AJ12>=0.9*AJ$10,"O",IF(AJ12>=0.85*AJ$10,"A+",IF(AJ12>=0.8*AJ$10,"A",IF(AJ12>=0.7*AJ$10,"B",IF(AJ12>=0.6*AJ$10,"C",IF(AJ12>=0.5*AJ$10,"P",IF(AJ12<0.5*AJ$10,"F",AJ12)))))))))))) -> O | AL12: 21 | AM12: 22 | AN12: =SUM(AL12:AM12) -> 43 | AO12: =IF(ISTEXT(AL12),IF(AL12="A","Ab",IF(AL12="D","Dt",IF(AL12="UFM","UFM",IF(AL12="NA","")))),IF(AND(ISBLANK(AL12),ISBLANK(AN12)),"",IF(AL12<0.4*AL$10,"F",IF(ISBLANK(AN12),"",IF(ISTEXT(AN12),AN12,IF(AN12>=0.9*AN$10,"O",IF(AN12>=0.85*AN$10,"A+",IF(AN12>=0.8*AN$10,"A",IF(AN12>=0.7*AN$10,"B",IF(AN12>=0.6*AN$10,"C",IF(AN12>=0.5*AN$10,"P",IF(AN12<0.5*AN$10,"F",AN12)))))))))))) -> A+ | AP12: =SUM(AN12,AJ12,AC12,Y12,U12,Q12,M12,I12) -> 708 | AQ12: =BJ12/$AP$8 -> 7.1363636 | AR12: =AQ12 -> 7.1363636 | AS12: =SUMIF(BA12:BI12,">0",$BA$10:$BI$10) -> 22 | AT12: =IF(OR(J12=$AX$19,N12=$AX$19,R12=$AX$19, V12=$AX$19, Z12=$AX$19, AD12=$AX$19, AG12=$AX$19, AK12=$AX$19, AO12=$AX$19), "CARRY OVER", "PASS") -> PASS | AU12: =IF(AT12="CARRY OVER",_xlfn.TEXTJOIN(" ", TRUE, "BACK IN:", IF(J12=$AX$19, $G$5, ""), IF(N12=$AX$19, $K$5, ""),IF(R12=$AX$19, $O$5, ""),IF(V12=$AX$19, $S$5, ""),IF(Z12=$AX$19, $W$5, ""), IF(AD12=$AX$19, $AA$5, ""),IF(AG12=$AX$19, $AE$5, ""),IF(AK12=$AX$19, $AH$5, ""),IF(AO12=$AX$19, $AL$5, "")), " ") | AV12: =AS12 -> 22 | AX12: Grade | AY12: Grade Point | BA12: =INDEX($AY$13:$AY$23,MATCH(INDIRECT(ADDRESS(ROW($J12),COLUMN($J12)+(COLUMN(J12)-10)*4,1)),$AX$13:$AX$23,0)) -> 6 | BB12: =INDEX($AY$13:$AY$23,MATCH(INDIRECT(ADDRESS(ROW($J12),COLUMN($J12)+(COLUMN(K12)-10)*4,1)),$AX$13:$AX$23,0)) -> 7 | BC12: =INDEX($AY$13:$AY$23,MATCH(INDIRECT(ADDRESS(ROW($J12),COLUMN($J12)+(COLUMN(L12)-10)*4,1)),$AX$13:$AX$23,0)) -> 7 | BD12: =INDEX($AY$13:$AY$23,MATCH(INDIRECT(ADDRESS(ROW($J12),COLUMN($J12)+(COLUMN(M12)-10)*4,1)),$AX$13:$AX$23,0)) -> 6 | BE12: =INDEX($AY$13:$AY$23,MATCH(INDIRECT(ADDRESS(ROW($J12),COLUMN($J12)+(COLUMN(N12)-10)*4,1)),$AX$13:$AX$23,0)) -> 8 | BF12: =INDEX($AY$13:$AY$23,MATCH(INDIRECT(ADDRESS(ROW($J12),COLUMN($J12)+(COLUMN(O12)-10)*4,1)),$AX$13:$AX$23,0)) -> 8 | BG12: =INDEX($AY$13:$AY$23,MATCH(INDIRECT(ADDRESS(ROW($J12),COLUMN($J12)+(COLUMN(P12)-10)*4-1,1)),$AX$13:$AX$23,0)) -> 7 | BH12: =INDEX($AY$13:$AY$23,MATCH(INDIRECT(ADDRESS(ROW($J12),COLUMN($J12)+(COLUMN(Q12)-10)*4-1,1)),$AX$13:$AX$23,0)) -> 10 | BI12: =INDEX($AY$13:$AY$23,MATCH(INDIRECT(ADDRESS(ROW($J12),COLUMN($J12)+(COLUMN(R12)-10)*4-1,1)),$AX$13:$AX$23,0)) -> 9 | BJ12: =SUMPRODUCT(BA12:BI12,$BA$10:$BI$10) -> 157
A13: 3 | AX13: O | AY13: 10
AX14: A+ | AY14: 9
AX15: A | AY15: 8
AX16: B | AY16: 7
AX17: C | AY17: 6
AX18: P | AY18: 5
AX19: F | AY19: 0
AX20: Ab | AY20: 0
AX21: UFM | AY21: 0
AX22: Dt | AY22: 0
AX23: ="" | AY23: =""

Sheet Geotechnology
A1: UTTARAKHAND TECHNICAL UNIVERSITY, DEHRADUN
A2: G.B. PANT INSTITUTE OF ENGINEERING & TECHNOLOGY, PAURI GARHWAL
A3: TABULATION CHART FOR M.TECH. ( GEOTECHNOLOGY ) FIRST YEAR ( I SEMESTER) EXAMINATION DECEMBER 2025
B4: Roll No. | C4: Enrollment No. | D4: Institute ID | E4: Student Name | F4: Father Name | G4: Subject and Subject Code | AP4: Grand Total | AQ4: SGPA | AR4: CGPA | AS4: Credits Earned | AT4: Result | AU4: Remarks | AV4: Cumilative Earned Credits I
A5: SC | G5: AHT 301 | K5: CET 601 | O5: CET 602 | S5: CET 604 | W5: CET 607 | AA5: AHT 302 | AE5: AHT 303 | AH5: CEP 601 | AL5: CEP 602
A6: SN | G6: Advanced Mathematics | K6: Advanced Soil Mechanics | O6: Soil Dynamics | S6: Pavement Analysis and Design | W6: Soil Structure Interaction | AA6: Research Methodology and IPR | AE6: Technical Writing and Presentation Skill ($) | AH6: Advanced Soil Mechanics Lab | AL6: Soil Dynamics Lab
G7: Credits
A8: C | G8: 4 | J8: Grade | K8: 4 | N8: Grade | O8: 4 | R8: Grade | S8: 3 | V8: Grade | W8: 3 | Z8: Grade | AA8: 2 | AD8: Grade | AE8: 0 | AG8: Grade | AH8: 1 | AK8: Grade | AL8: 1 | AO8: Grade | AP8: =SUM(AL8,AH8,AE8,AA8,W8,S8,O8,K8,G8) -> 22
G9: Th. Ex. | H9: Ses. | I9: Total | K9: Th. Ex. | L9: Ses. | M9: Total | O9: Th. Ex. | P9: Ses. | Q9: Total | S9: Th. Ex. | T9: Ses. | U9: Total | W9: Th. Ex. | X9: Ses. | Y9: Total | AA9: Th. Ex. | AB9: Ses. | AC9: Total | AE9: Ses. | AF9: Total | AH9: Pr. Ex. | AI9: Ses. | AJ9: Total | AL9: Pr. Ex. | AM9: Ses. | AN9: Total | AP9: =SUM(AN10,AJ10,AC10,Y10,U10,Q10,M10,I10) -> 950 | BA9: Grade Point Summary | BJ9: TGP I
A10: M.M. | G10: 100 | H10: 50 | I10: 150 | K10: 100 | L10: 50 | M10: 150 | O10: 100 | P10: 50 | Q10: 150 | S10: 100 | T10: 50 | U10: 150 | W10: 100 | X10: 50 | Y10: 150 | AA10: 50 | AB10: 50 | AC10: 100 | AE10: 50 | AF10: 50 | AH10: 25 | AI10: 25 | AJ10: 50 | AL10: 25 | AM10: 25 | AN10: 50 | BA10: =OFFSET($G$8,0,(COLUMN(G8)-7)*4) -> 4 | BB10: =OFFSET($G$8,0,(COLUMN(H8)-7)*4) -> 4 | BC10: =OFFSET($G$8,0,(COLUMN(I8)-7)*4) -> 4 | BD10: =OFFSET($G$8,0,(COLUMN(J8)-7)*4) -> 3 | BE10: =OFFSET($G$8,0,(COLUMN(K8)-7)*4) -> 3 | BF10: =OFFSET($G$8,0,(COLUMN(L8)-7)*4) -> 2 | BG10: =OFFSET($G$8,0,(COLUMN(M8)-7)*4) -> 0 | BH10: =OFFSET($G$8,0,(COLUMN(N8)-7)*4-1) -> 1 | BI10: =OFFSET($G$8,0,(COLUMN(O8)-7)*4-1) -> 1
A11: 1 | B11: 250090725001 | C11: PUTU/2507100063 | D11: 255601 | E11: Jatin Dhapola | F11: Vijay Kumar Dhapola | G11: 60 | H11: 44 | I11: =SUM(G11:H11) -> 104 | J11: =IF(ISTEXT(G11),IF(G11="A","Ab",IF(G11="D","Dt",IF(G11="UFM","UFM",IF(G11="NA","")))),IF(AND(ISBLANK(G11),ISBLANK(I11)),"",IF(G11<0.4*G$10,"F",IF(ISBLANK(I11),"",IF(ISTEXT(I11),I11,IF(I11>=0.9*I$10,"O",IF(I11>=0.85*I$10,"A+",IF(I11>=0.8*I$10,"A",IF(I11>=0.7*I$10,"B",IF(I11>=0.6*I$10,"C",IF(I11>=0.5*I$10,"P",IF(I11<0.5*I$10,"F",I11)))))))))))) -> C | K11: 72 | L11: 42 | M11: =SUM(K11:L11) -> 114 | N11: =IF(ISTEXT(K11),IF(K11="A","Ab",IF(K11="D","Dt",IF(K11="UFM","UFM",IF(K11="NA","")))),IF(AND(ISBLANK(K11),ISBLANK(M11)),"",IF(K11<0.4*K$10,"F",IF(ISBLANK(M11),"",IF(ISTEXT(M11),M11,IF(M11>=0.9*M$10,"O",IF(M11>=0.85*M$10,"A+",IF(M11>=0.8*M$10,"A",IF(M11>=0.7*M$10,"B",IF(M11>=0.6*M$10,"C",IF(M11>=0.5*M$10,"P",IF(M11<0.5*M$10,"F",M11)))))))))))) -> B | O11: 65 | P11: 40 | Q11: =SUM(O11:P11) -> 105 | R11: =IF(ISTEXT(O11),IF(O11="A","Ab",IF(O11="D","Dt",IF(O11="UFM","UFM",IF(O11="NA","")))),IF(AND(ISBLANK(O11),ISBLANK(Q11)),"",IF(O11<0.4*O$10,"F",IF(ISBLANK(Q11),"",IF(ISTEXT(Q11),Q11,IF(Q11>=0.9*Q$10,"O",IF(Q11>=0.85*Q$10,"A+",IF(Q11>=0.8*Q$10,"A",IF(Q11>=0.7*Q$10,"B",IF(Q11>=0.6*Q$10,"C",IF(Q11>=0.5*Q$10,"P",IF(Q11<0.5*Q$10,"F",Q11)))))))))))) -> B | S11: 77 | T11: 47 | U11: =SUM(S11:T11) -> 124 | V11: =IF(ISTEXT(S11),IF(S11="A","Ab",IF(S11="D","Dt",IF(S11="UFM","UFM",IF(S11="NA","")))),IF(AND(ISBLANK(S11),ISBLANK(U11)),"",IF(S11<0.4*S$10,"F",IF(ISBLANK(U11),"",IF(ISTEXT(U11),U11,IF(U11>=0.9*U$10,"O",IF(U11>=0.85*U$10,"A+",IF(U11>=0.8*U$10,"A",IF(U11>=0.7*U$10,"B",IF(U11>=0.6*U$10,"C",IF(U11>=0.5*U$10,"P",IF(U11<0.5*U$10,"F",U11)))))))))))) -> A | W11: 84 | X11: 43 | Y11: =SUM(W11:X11) -> 127 | Z11: =IF(ISTEXT(W11),IF(W11="A","Ab",IF(W11="D","Dt",IF(W11="UFM","UFM",IF(W11="NA","")))),IF(AND(ISBLANK(W11),ISBLANK(Y11)),"",IF(W11<0.4*W$10,"F",IF(ISBLANK(Y11),"",IF(ISTEXT(Y11),Y11,IF(Y11>=0.9*Y$10,"O",IF(Y11>=0.85*Y$10,"A+",IF(Y11>=0.8*Y$10,"A",IF(Y11>=0.7*Y$10,"B",IF(Y11>=0.6*Y$10,"C",IF(Y11>=0.5*Y$10,"P",IF(Y11<0.5*Y$10,"F",Y11)))))))))))) -> A | AA11: 44 | AB11: 48 | AC11: =SUM(AA11:AB11) -> 92 | AD11: =IF(ISTEXT(AA11),IF(AA11="A","Ab",IF(AA11="D","Dt",IF(AA11="UFM","UFM",IF(AA11="NA","")))),IF(AND(ISBLANK(AA11),ISBLANK(AC11)),"",IF(AA11<0.4*AA$10,"F",IF(ISBLANK(AC11),"",IF(ISTEXT(AC11),AC11,IF(AC11>=0.9*AC$10,"O",IF(AC11>=0.85*AC$10,"A+",IF(AC11>=0.8*AC$10,"A",IF(AC11>=0.7*AC$10,"B",IF(AC11>=0.6*AC$10,"C",IF(AC11>=0.5*AC$10,"P",IF(AC11<0.5*AC$10,"F",AC11)))))))))))) -> O | AE11: 37 | AF11: =SUM(AE11) -> 37 | AG11: =IF(ISBLANK(AF11),"",IF(ISTEXT(AF11),AF11,IF(AF11>=0.9*AF$10,"O",IF(AF11>=0.85*AF$10,"A+",IF(AF11>=0.8*AF$10,"A",IF(AF11>=0.7*AF$10,"B",IF(AF11>=0.6*AF$10,"C",IF(AF11>=0.5*AF$10,"P",IF(AF11<0.5*AF$10,"F",AF11))))))))) -> B | AH11: 22 | AI11: 23 | AJ11: =SUM(AH11:AI11) -> 45 | AK11: =IF(ISTEXT(AH11),IF(AH11="A","Ab",IF(AH11="D","Dt",IF(AH11="UFM","UFM",IF(AH11="NA","")))),IF(AND(ISBLANK(AH11),ISBLANK(AJ11)),"",IF(AH11<0.4*AH$10,"F",IF(ISBLANK(AJ11),"",IF(ISTEXT(AJ11),AJ11,IF(AJ11>=0.9*AJ$10,"O",IF(AJ11>=0.85*AJ$10,"A+",IF(AJ11>=0.8*AJ$10,"A",IF(AJ11>=0.7*AJ$10,"B",IF(AJ11>=0.6*AJ$10,"C",IF(AJ11>=0.5*AJ$10,"P",IF(AJ11<0.5*AJ$10,"F",AJ11)))))))))))) -> O | AL11: 24 | AM11: 24 | AN11: =SUM(AL11:AM11) -> 48 | AO11: =IF(ISTEXT(AL11),IF(AL11="A","Ab",IF(AL11="D","Dt",IF(AL11="UFM","UFM",IF(AL11="NA","")))),IF(AND(ISBLANK(AL11),ISBLANK(AN11)),"",IF(AL11<0.4*AL$10,"F",IF(ISBLANK(AN11),"",IF(ISTEXT(AN11),AN11,IF(AN11>=0.9*AN$10,"O",IF(AN11>=0.85*AN$10,"A+",IF(AN11>=0.8*AN$10,"A",IF(AN11>=0.7*AN$10,"B",IF(AN11>=0.6*AN$10,"C",IF(AN11>=0.5*AN$10,"P",IF(AN11<0.5*AN$10,"F",AN11)))))))))))) -> O | AP11: =SUM(AN11,AJ11,AC11,Y11,U11,Q11,M11,I11) -> 759 | AQ11: =BJ11/$AP$8 -> 7.6363636 | AR11: =AQ11 -> 7.6363636 | AS11: =SUMIF(BA11:BI11,">0",$BA$10:$BI$10) -> 22 | AT11: =IF(OR(J11=$AX$19,N11=$AX$19,R11=$AX$19, V11=$AX$19, Z11=$AX$19, AD11=$AX$19, AG11=$AX$19, AK11=$AX$19, AO11=$AX$19), "CARRY OVER", "PASS") -> PASS | AU11: =IF(AT11="CARRY OVER",_xlfn.TEXTJOIN(" ", TRUE, "BACK IN:", IF(J11=$AX$19, $G$5, ""), IF(N11=$AX$19, $K$5, ""),IF(R11=$AX$19, $O$5, ""),IF(V11=$AX$19, $S$5, ""),IF(Z11=$AX$19, $W$5, ""), IF(AD11=$AX$19, $AA$5, ""),IF(AG11=$AX$19, $AE$5, ""),IF(AK11=$AX$19, $AH$5, ""),IF(AO11=$AX$19, $AL$5, "")), " ") | AV11: =AS11 -> 22 | BA11: =INDEX($AY$13:$AY$23,MATCH(INDIRECT(ADDRESS(ROW($J11),COLUMN($J11)+(COLUMN(J11)-10)*4,1)),$AX$13:$AX$23,0)) -> 6 | BB11: =INDEX($AY$13:$AY$23,MATCH(INDIRECT(ADDRESS(ROW($J11),COLUMN($J11)+(COLUMN(K11)-10)*4,1)),$AX$13:$AX$23,0)) -> 7 | BC11: =INDEX($AY$13:$AY$23,MATCH(INDIRECT(ADDRESS(ROW($J11),COLUMN($J11)+(COLUMN(L11)-10)*4,1)),$AX$13:$AX$23,0)) -> 7 | BD11: =INDEX($AY$13:$AY$23,MATCH(INDIRECT(ADDRESS(ROW($J11),COLUMN($J11)+(COLUMN(M11)-10)*4,1)),$AX$13:$AX$23,0)) -> 8 | BE11: =INDEX($AY$13:$AY$23,MATCH(INDIRECT(ADDRESS(ROW($J11),COLUMN($J11)+(COLUMN(N11)-10)*4,1)),$AX$13:$AX$23,0)) -> 8 | BF11: =INDEX($AY$13:$AY$23,MATCH(INDIRECT(ADDRESS(ROW($J11),COLUMN($J11)+(COLUMN(O11)-10)*4,1)),$AX$13:$AX$23,0)) -> 10 | BG11: =INDEX($AY$13:$AY$23,MATCH(INDIRECT(ADDRESS(ROW($J11),COLUMN($J11)+(COLUMN(P11)-10)*4-1,1)),$AX$13:$AX$23,0)) -> 7 | BH11: =INDEX($AY$13:$AY$23,MATCH(INDIRECT(ADDRESS(ROW($J11),COLUMN($J11)+(COLUMN(Q11)-10)*4-1,1)),$AX$13:$AX$23,0)) -> 10 | BI11: =INDEX($AY$13:$AY$23,MATCH(INDIRECT(ADDRESS(ROW($J11),COLUMN($J11)+(COLUMN(R11)-10)*4-1,1)),$AX$13:$AX$23,0)) -> 10 | BJ11: =SUMPRODUCT(BA11:BI11,$BA$10:$BI$10) -> 168
AX12: Grade | AY12: Grade Point
AX13: O | AY13: 10
AX14: A+ | AY14: 9
AX15: A | AY15: 8
AX16: B | AY16: 7
AX17: C | AY17: 6
AX18: P | AY18: 5
AX19: F | AY19: 0
AX20: Ab | AY20: 0
AX21: UFM | AY21: 0
AX22: Dt | AY22: 0
AX23: ="" | AY23: =""

Sheet PowerSystems
A1: UTTARAKHAND TECHNICAL UNIVERSITY, DEHRADUN
A2: G.B. PANT INSTITUTE OF ENGINEERING & TECHNOLOGY, PAURI GARHWAL
A3: TABULATION CHART FOR M.TECH. (POWER SYSTEMS) FIRST YEAR ( I SEMESTER) EXAMINATION DECEMBER 2025
B4: Roll No. | C4: Enrollment No. | D4: Institute ID | E4: Student Name | F4: Father Name | G4: Subject and Subject Code | AP4: Grand Total | AQ4: SGPA | AR4: CGPA | AS4: Credits Earned | AT4: Result | AU4: Remarks | AV4: Cumilative Earned Credits I
A5: SC | G5: AHT 301 | K5: MPST 101 | O5: MPST 102 | S5: MPST 111 | W5: MPST 121 | AA5: AHT 302 | AE5: AHT 303 | AH5: MPSP 101 | AL5: MPSP 102
A6: SN | G6: Advanced Mathematics | K6: Power System Analysis | O6: Power System Stability and Control | S6: Renewable Energy System | W6: Electrical Power Distribution System | AA6: Research Methodology and IPR | AE6: Technical Writing and Presentation Skill ($) | AH6: Power System Analysis Lab | AL6: Power System Stability & Control Lab
G7: Credits
A8: C | G8: 4 | J8: Grade | K8: 4 | N8: Grade | O8: 4 | R8: Grade | S8: 3 | V8: Grade | W8: 3 | Z8: Grade | AA8: 2 | AD8: Grade | AE8: 0 | AG8: Grade | AH8: 1 | AK8: Grade | AL8: 1 | AO8: Grade | AP8: =SUM(AL8,AH8,AE8,AA8,W8,S8,O8,K8,G8) -> 22
G9: Th. Ex. | H9: Ses. | I9: Total | K9: Th. Ex. | L9: Ses. | M9: Total | O9: Th. Ex. | P9: Ses. | Q9: Total | S9: Th. Ex. | T9: Ses. | U9: Total | W9: Th. Ex. | X9: Ses. | Y9: Total | AA9: Th. Ex. | AB9: Ses. | AC9: Total | AE9: Ses. | AF9: Total | AH9: Pr. Ex. | AI9: Ses. | AJ9: Total | AL9: Pr. Ex. | AM9: Ses. | AN9: Total | AP9: =SUM(AN10,AJ10,AC10,Y10,U10,Q10,M10,I10) -> 950 | BA9: Grade Point Summary | BJ9: TGP I
A10: M.M. | G10: 100 | H10: 50 | I10: 150 | K10: 100 | L10: 50 | M10: 150 | O10: 100 | P10: 50 | Q10: 150 | S10: 100 | T10: 50 | U10: 150 | W10: 100 | X10: 50 | Y10: 150 | AA10: 50 | AB10: 50 | AC10: 100 | AE10: 50 | AF10: 50 | AH10: 25 | AI10: 25 | AJ10: 50 | AL10: 25 | AM10: 25 | AN10: 50 | BA10: =OFFSET($G$8,0,(COLUMN(G8)-7)*4) -> 4 | BB10: =OFFSET($G$8,0,(COLUMN(H8)-7)*4) -> 4 | BC10: =OFFSET($G$8,0,(COLUMN(I8)-7)*4) -> 4 | BD10: =OFFSET($G$8,0,(COLUMN(J8)-7)*4) -> 3 | BE10: =OFFSET($G$8,0,(COLUMN(K8)-7)*4) -> 3 | BF10: =OFFSET($G$8,0,(COLUMN(L8)-7)*4) -> 2 | BG10: =OFFSET($G$8,0,(COLUMN(M8)-7)*4) -> 0 | BH10: =OFFSET($G$8,0,(COLUMN(N8)-7)*4-1) -> 1 | BI10: =OFFSET($G$8,0,(COLUMN(O8)-7)*4-1) -> 1
A11: 1 | B11: 250090713001 | C11: PUTU/2507100066 | D11: 255601 | E11: Deepansha Arya | F11: Nand Kishor | G11: 64 | H11: 46 | I11: =SUM(G11:H11) -> 110 | J11: =IF(ISTEXT(G11),IF(G11="A","Ab",IF(G11="D","Dt",IF(G11="UFM","UFM",IF(G11="NA","")))),IF(AND(ISBLANK(G11),ISBLANK(I11)),"",IF(G11<0.4*G$10,"F",IF(ISBLANK(I11),"",IF(ISTEXT(I11),I11,IF(I11>=0.9*I$10,"O",IF(I11>=0.85*I$10,"A+",IF(I11>=0.8*I$10,"A",IF(I11>=0.7*I$10,"B",IF(I11>=0.6*I$10,"C",IF(I11>=0.5*I$10,"P",IF(I11<0.5*I$10,"F",I11)))))))))))) -> B | K11: 52 | L11: 40 | M11: =SUM(K11:L11) -> 92 | N11: =IF(ISTEXT(K11),IF(K11="A","Ab",IF(K11="D","Dt",IF(K11="UFM","UFM",IF(K11="NA","")))),IF(AND(ISBLANK(K11),ISBLANK(M11)),"",IF(K11<0.4*K$10,"F",IF(ISBLANK(M11),"",IF(ISTEXT(M11),M11,IF(M11>=0.9*M$10,"O",IF(M11>=0.85*M$10,"A+",IF(M11>=0.8*M$10,"A",IF(M11>=0.7*M$10,"B",IF(M11>=0.6*M$10,"C",IF(M11>=0.5*M$10,"P",IF(M11<0.5*M$10,"F",M11)))))))))))) -> C | O11: 43 | P11: 43 | Q11: =SUM(O11:P11) -> 86 | R11: =IF(ISTEXT(O11),IF(O11="A","Ab",IF(O11="D","Dt",IF(O11="UFM","UFM",IF(O11="NA","")))),IF(AND(ISBLANK(O11),ISBLANK(Q11)),"",IF(O11<0.4*O$10,"F",IF(ISBLANK(Q11),"",IF(ISTEXT(Q11),Q11,IF(Q11>=0.9*Q$10,"O",IF(Q11>=0.85*Q$10,"A+",IF(Q11>=0.8*Q$10,"A",IF(Q11>=0.7*Q$10,"B",IF(Q11>=0.6*Q$10,"C",IF(Q11>=0.5*Q$10,"P",IF(Q11<0.5*Q$10,"F",Q11)))))))))))) -> P | S11: 60 | T11: 41 | U11: =SUM(S11:T11) -> 101 | V11: =IF(ISTEXT(S11),IF(S11="A","Ab",IF(S11="D","Dt",IF(S11="UFM","UFM",IF(S11="NA","")))),IF(AND(ISBLANK(S11),ISBLANK(U11)),"",IF(S11<0.4*S$10,"F",IF(ISBLANK(U11),"",IF(ISTEXT(U11),U11,IF(U11>=0.9*U$10,"O",IF(U11>=0.85*U$10,"A+",IF(U11>=0.8*U$10,"A",IF(U11>=0.7*U$10,"B",IF(U11>=0.6*U$10,"C",IF(U11>=0.5*U$10,"P",IF(U11<0.5*U$10,"F",U11)))))))))))) -> C | W11: 69 | X11: 40 | Y11: =SUM(W11:X11) -> 109 | Z11: =IF(ISTEXT(W11),IF(W11="A","Ab",IF(W11="D","Dt",IF(W11="UFM","UFM",IF(W11="NA","")))),IF(AND(ISBLANK(W11),ISBLANK(Y11)),"",IF(W11<0.4*W$10,"F",IF(ISBLANK(Y11),"",IF(ISTEXT(Y11),Y11,IF(Y11>=0.9*Y$10,"O",IF(Y11>=0.85*Y$10,"A+",IF(Y11>=0.8*Y$10,"A",IF(Y11>=0.7*Y$10,"B",IF(Y11>=0.6*Y$10,"C",IF(Y11>=0.5*Y$10,"P",IF(Y11<0.5*Y$10,"F",Y11)))))))))))) -> B | AA11: 34 | AB11: 47 | AC11: =SUM(AA11:AB11) -> 81 | AD11: =IF(ISTEXT(AA11),IF(AA11="A","Ab",IF(AA11="D","Dt",IF(AA11="UFM","UFM",IF(AA11="NA","")))),IF(AND(ISBLANK(AA11),ISBLANK(AC11)),"",IF(AA11<0.4*AA$10,"F",IF(ISBLANK(AC11),"",IF(ISTEXT(AC11),AC11,IF(AC11>=0.9*AC$10,"O",IF(AC11>=0.85*AC$10,"A+",IF(AC11>=0.8*AC$10,"A",IF(AC11>=0.7*AC$10,"B",IF(AC11>=0.6*AC$10,"C",IF(AC11>=0.5*AC$10,"P",IF(AC11<0.5*AC$10,"F",AC11)))))))))))) -> A | AE11: 42 | AF11: =SUM(AE11) -> 42 | AG11: =IF(ISBLANK(AF11),"",IF(ISTEXT(AF11),AF11,IF(AF11>=0.9*AF$10,"O",IF(AF11>=0.85*AF$10,"A+",IF(AF11>=0.8*AF$10,"A",IF(AF11>=0.7*AF$10,"B",IF(AF11>=0.6*AF$10,"C",IF(AF11>=0.5*AF$10,"P",IF(AF11<0.5*AF$10,"F",AF11))))))))) -> A | AH11: 22 | AI11: 23 | AJ11: =SUM(AH11:AI11) -> 45 | AK11: =IF(ISTEXT(AH11),IF(AH11="A","Ab",IF(AH11="D","Dt",IF(AH11="UFM","UFM",IF(AH11="NA","")))),IF(AND(ISBLANK(AH11),ISBLANK(AJ11)),"",IF(AH11<0.4*AH$10,"F",IF(ISBLANK(AJ11),"",IF(ISTEXT(AJ11),AJ11,IF(AJ11>=0.9*AJ$10,"O",IF(AJ11>=0.85*AJ$10,"A+",IF(AJ11>=0.8*AJ$10,"A",IF(AJ11>=0.7*AJ$10,"B",IF(AJ11>=0.6*AJ$10,"C",IF(AJ11>=0.5*AJ$10,"P",IF(AJ11<0.5*AJ$10,"F",AJ11)))))))))))) -> O | AL11: 22 | AM11: 23 | AN11: =SUM(AL11:AM11) -> 45 | AO11: =IF(ISTEXT(AL11),IF(AL11="A","Ab",IF(AL11="D","Dt",IF(AL11="UFM","UFM",IF(AL11="NA","")))),IF(AND(ISBLANK(AL11),ISBLANK(AN11)),"",IF(AL11<0.4*AL$10,"F",IF(ISBLANK(AN11),"",IF(ISTEXT(AN11),AN11,IF(AN11>=0.9*AN$10,"O",IF(AN11>=0.85*AN$10,"A+",IF(AN11>=0.8*AN$10,"A",IF(AN11>=0.7*AN$10,"B",IF(AN11>=0.6*AN$10,"C",IF(AN11>=0.5*AN$10,"P",IF(AN11<0.5*AN$10,"F",AN11)))))))))))) -> O | AP11: =SUM(AN11,AJ11,AC11,Y11,U11,Q11,M11,I11) -> 669 | AQ11: =BJ11/$AP$8 -> 6.6818182 | AR11: =AQ11 -> 6.6818182 | AS11: =SUMIF(BA11:BI11,">0",$BA$10:$BI$10) -> 22 | AT11: =IF(OR(J11=$AX$19,N11=$AX$19,R11=$AX$19, V11=$AX$19, Z11=$AX$19, AD11=$AX$19, AG11=$AX$19, AK11=$AX$19, AO11=$AX$19), "CARRY OVER", "PASS") -> PASS | AU11: =IF(AT11="CARRY OVER",_xlfn.TEXTJOIN(" ", TRUE, "BACK IN:", IF(J11=$AX$19, $G$5, ""), IF(N11=$AX$19, $K$5, ""),IF(R11=$AX$19, $O$5, ""),IF(V11=$AX$19, $S$5, ""),IF(Z11=$AX$19, $W$5, ""), IF(AD11=$AX$19, $AA$5, ""),IF(AG11=$AX$19, $AE$5, ""),IF(AK11=$AX$19, $AH$5, ""),IF(AO11=$AX$19, $AL$5, "")), " ") | AV11: =AS11 -> 22 | BA11: =INDEX($AY$13:$AY$23,MATCH(INDIRECT(ADDRESS(ROW($J11),COLUMN($J11)+(COLUMN(J11)-10)*4,1)),$AX$13:$AX$23,0)) -> 7 | BB11: =INDEX($AY$13:$AY$23,MATCH(INDIRECT(ADDRESS(ROW($J11),COLUMN($J11)+(COLUMN(K11)-10)*4,1)),$AX$13:$AX$23,0)) -> 6 | BC11: =INDEX($AY$13:$AY$23,MATCH(INDIRECT(ADDRESS(ROW($J11),COLUMN($J11)+(COLUMN(L11)-10)*4,1)),$AX$13:$AX$23,0)) -> 5 | BD11: =INDEX($AY$13:$AY$23,MATCH(INDIRECT(ADDRESS(ROW($J11),COLUMN($J11)+(COLUMN(M11)-10)*4,1)),$AX$13:$AX$23,0)) -> 6 | BE11: =INDEX($AY$13:$AY$23,MATCH(INDIRECT(ADDRESS(ROW($J11),COLUMN($J11)+(COLUMN(N11)-10)*4,1)),$AX$13:$AX$23,0)) -> 7 | BF11: =INDEX($AY$13:$AY$23,MATCH(INDIRECT(ADDRESS(ROW($J11),COLUMN($J11)+(COLUMN(O11)-10)*4,1)),$AX$13:$AX$23,0)) -> 8 | BG11: =INDEX($AY$13:$AY$23,MATCH(INDIRECT(ADDRESS(ROW($J11),COLUMN($J11)+(COLUMN(P11)-10)*4-1,1)),$AX$13:$AX$23,0)) -> 8 | BH11: =INDEX($AY$13:$AY$23,MATCH(INDIRECT(ADDRESS(ROW($J11),COLUMN($J11)+(COLUMN(Q11)-10)*4-1,1)),$AX$13:$AX$23,0)) -> 10 | BI11: =INDEX($AY$13:$AY$23,MATCH(INDIRECT(ADDRESS(ROW($J11),COLUMN($J11)+(COLUMN(R11)-10)*4-1,1)),$AX$13:$AX$23,0)) -> 10 | BJ11: =SUMPRODUCT(BA11:BI11,$BA$10:$BI$10) -> 147
