Workbook
Name I: SEM_I!$A$1:$AY$45
Name II: SEM_II!$A$1:$AM$45
Name III: SEM_III!$A$1:$AM$44
Name IV: SEM_IV!$A$1:$AM$44
Name V: #REF!

Sheet SEM_I
A1: SC | B1: Roll No. | C1: Enroll No. | D1: Student's Name | E1: Father's Name | F1: CAT 004 | I1: CAT 005 | L1: CAT 006 | O1: CAT 007 | R1: AHT 303 | U1: CAT 008 | X1: CAT 001 | AA1: CAT 002 | AD1: CAT 003 | AG1: CAP 001 | AJ1: CAP 002 | AM1: CAP 003 | AP1: AHP 303 | AV1: TGP | AW1: EC | AX1: Grace | AY1: CGPA
A2: SN | F2: Discrete Structure | I2: Database Management System | L2: Operating System | O2: Computer Organization | R2: Technical Communication Skills | U2: Python Programming ($) | X2: Introduction of Information Technology ($) | AA2: Programming Fundamentals with "C" ($) | AD2: Fundamental of Web Technology ($) | AG2: Database Management System Lab | AJ2: Operating System Lab | AM2: Computer Organization Lab | AP2: Technical Communication Skills
A3: C | F3: 4 | I3: 4 | L3: 4 | O3: 4 | R3: 4 | U3: 0 | X3: 0 | AA3: 0 | AD3: 0 | AG3: 1 | AJ3: 1 | AM3: 1 | AP3: 1 | AW3: =SUM(F3:AU3) -> 24
F4: Th. Ex. | G4: Ses. | H4: Total | I4: Th. Ex. | J4: Ses. | K4: Total | L4: Th. Ex. | M4: Ses. | N4: Total | O4: Th. Ex. | P4: Ses. | Q4: Total | R4: Th. Ex. | S4: Ses. | T4: Total | U4: Th. Ex. | V4: Ses. | W4: Total | X4: Pr. Ex. | Y4: Ses. | Z4: Total | AA4: Pr. Ex. | AB4: Ses. | AC4: Total | AD4: Pr. Ex. | AE4: Ses. | AF4: Total | AG4: Pr. Ex. | AH4: Ses. | AI4: Total | AJ4: Pr. Ex. | AK4: Ses. | AL4: Total | AM4: Pr. Ex. | AN4: Ses. | AO4: Total | AP4: Pr. Ex. | AQ4: Ses. | AR4: Total
A5: MM | F5: 100 | G5: 50 | H5: 150 | I5: 100 | J5: 50 | K5: 150 | L5: 100 | M5: 50 | N5: 150 | O5: 100 | P5: 50 | Q5: 150 | R5: 100 | S5: 50 | T5: 150 | U5: 30 | V5: 20 | W5: 50 | X5: 30 | Y5: 20 | Z5: 50 | AA5: 30 | AB5: 20 | AC5: 50 | AD5: 30 | AE5: 20 | AF5: 50 | AG5: 30 | AH5: 20 | AI5: 50 | AJ5: 30 | AK5: 20 | AL5: 50 | AM5: 30 | AN5: 20 | AO5: 50 | AP5: 30 | AQ5: 20 | AR5: 50
A6: 1 | B6: 250090600001 | C6: UTU/2506100119 | D6: ABHISHEK RAWAT | E6: RAMESH RAWAT | F6: 67 | G6: 42 | H6: =SUM(F6:G6) -> 109 | I6: 54 | J6: 40 | K6: =SUM(I6:J6) -> 94 | L6: 60 | M6: 42 | N6: =SUM(L6:M6) -> 102 | O6: 37 | P6: 40 | Q6: =SUM(O6:P6) -> 77 | R6: 67 | S6: 35 | T6: =SUM(R6:S6) -> 102 | U6: 16 | V6: 16 | W6: =SUM(U6:V6) -> 32 | X6: 27 | Y6: 19 | Z6: =SUM(X6:Y6) -> 46 | AA6: 24 | AB6: 18 | AC6: =SUM(AA6:AB6) -> 42 | AD6: 24 | AE6: 19 | AF6: =SUM(AD6:AE6) -> 43 | AG6: 26 | AH6: 16 | AI6: =SUM(AG6:AH6) -> 42 | AJ6: 26 | AK6: 17 | AL6: =SUM(AJ6:AK6) -> 43 | AM6: 25 | AN6: 19 | AO6: =SUM(AM6:AN6) -> 44 | AP6: 22 | AQ6: 16 | AR6: =SUM(AP6:AQ6) -> 38 | AV6: =INDIRECT(_xlfn.TEXTJOIN("",TRUE,"TC_",BC6,"!",ADDRESS(4+A6*(BD6+9),13))) -> 168.5 | AW6: =INDIRECT(_xlfn.TEXTJOIN("",TRUE,"TC_",BC6,"!",ADDRESS(5+A6*(BD6+9),12))) -> 24 | AX6: =IF(INDIRECT(_xlfn.TEXTJOIN("",TRUE,"TC_",BC6,"!",ADDRESS(4+A6*(BD6+9),23))),SUM(INDIRECT(_xlfn.TEXTJOIN("",TRUE,"TC_",BC6,"!",ADDRESS(4+A6*(BD6+9)-BD6,23),":",ADDRESS(3+A6*(BD6+9),23)))),0) -> 0 | AY6: =AV6/$AW$3 -> 7.0208333 | BC6: I | BD6: 14
A7: 2 | B7: 250090600002 | C7: UTU/2506100159 | D7: ABHISHEK SINGH NAYAL | E7: RAVENDRA SINGH NAYAL | F7: 61 | G7: 35 | H7: =SUM(F7:G7) -> 96 | I7: 46 | J7: 34 | K7: =SUM(I7:J7) -> 80 | L7: 56 | M7: 46 | N7: =SUM(L7:M7) -> 102 | O7: 51 | P7: 41 | Q7: =SUM(O7:P7) -> 92 | R7: 70 | S7: 37 | T7: =SUM(R7:S7) -> 107 | U7: 14 | V7: 12 | W7: =SUM(U7:V7) -> 26 | X7: NA | Y7: NA | Z7: NA | AA7: NA | AB7: NA | AC7: NA | AD7: NA | AE7: NA | AF7: NA | AG7: 24 | AH7: 14 | AI7: =SUM(AG7:AH7) -> 38 | AJ7: 27 | AK7: 18 | AL7: =SUM(AJ7:AK7) -> 45 | AM7: 27 | AN7: 18 | AO7: =SUM(AM7:AN7) -> 45 | AP7: 23 | AQ7: 17 | AR7: =SUM(AP7:AQ7) -> 40 | AV7: =INDIRECT(_xlfn.TEXTJOIN("",TRUE,"TC_",BC7,"!",ADDRESS(4+A7*(BD7+9),13))) -> 167.5 | AW7: =INDIRECT(_xlfn.TEXTJOIN("",TRUE,"TC_",BC7,"!",ADDRESS(5+A7*(BD7+9),12))) -> 24 | AX7: =IF(INDIRECT(_xlfn.TEXTJOIN("",TRUE,"TC_",BC7,"!",ADDRESS(4+A7*(BD7+9),23))),SUM(INDIRECT(_xlfn.TEXTJOIN("",TRUE,"TC_",BC7,"!",ADDRESS(4+A7*(BD7+9)-BD7,23),":",ADDRESS(3+A7*(BD7+9),23)))),0) -> 0 | AY7: =AV7/$AW$3 -> 6.9791667 | BC7: =BC6 -> I | BD7: =BD6 -> 14
A8: 3 | B8: 250090600003 | C8: UTU/2506100120 | D8: ASHOK CHANDRA UPRETI | E8: LALITA PRASAD UPRETI | F8: 69 | G8: 46 | H8: =SUM(F8:G8) -> 115 | I8: 85 | J8: 45 | K8: =SUM(I8:J8) -> 130 | L8: 88 | M8: 50 | N8: =SUM(L8:M8) -> 138 | O8: 81 | P8: 48 | Q8: =SUM(O8:P8) -> 129 | R8: 90 | S8: 48 | T8: =SUM(R8:S8) -> 138 | U8: 18 | V8: 13 | W8: =SUM(U8:V8) -> 31 | X8: 28 | Y8: 18 | Z8: =SUM(X8:Y8) -> 46 | AA8: 21 | AB8: 18 | AC8: =SUM(AA8:AB8) -> 39 | AD8: 22 | AE8: 19 | AF8: =SUM(AD8:AE8) -> 41 | AG8: 28 | AH8: 18 | AI8: =SUM(AG8:AH8) -> 46 | AJ8: 30 | AK8: 20 | AL8: =SUM(AJ8:AK8) -> 50 | AM8: 27 | AN8: 20 | AO8: =SUM(AM8:AN8) -> 47 | AP8: 30 | AQ8: 16 | AR8: =SUM(AP8:AQ8) -> 46 | AV8: =INDIRECT(_xlfn.TEXTJOIN("",TRUE,"TC_",BC8,"!",ADDRESS(4+A8*(BD8+9),13))) -> 218.5 | AW8: =INDIRECT(_xlfn.TEXTJOIN("",TRUE,"TC_",BC8,"!",ADDRESS(5+A8*(BD8+9),12))) -> 24 | AX8: =IF(INDIRECT(_xlfn.TEXTJOIN("",TRUE,"TC_",BC8,"!",ADDRESS(4+A8*(BD8+9),23))),SUM(INDIRECT(_xlfn.TEXTJOIN("",TRUE,"TC_",BC8,"!",ADDRESS(4+A8*(BD8+9)-BD8,23),":",ADDRESS(3+A8*(BD8+9),23)))),0) -> 0 | AY8: =AV8/$AW$3 -> 9.1041667 | BC8: =BC7 -> I | BD8: =BD7 -> 14
A9: 4 | B9: 250090600004 | C9: UTU/2506100116 | D9: AYUSH SINGH RAWAT | E9: RAJENDRA SINGH RAWAT | F9: 48 | G9: 42 | H9: =SUM(F9:G9) -> 90 | I9: 47 | J9: 31 | K9: =SUM(I9:J9) -> 78 | L9: 66 | M9: 36 | N9: =SUM(L9:M9) -> 102 | O9: 43 | P9: 33 | Q9: =SUM(O9:P9) -> 76 | R9: A | S9: 33 | T9: =SUM(R9:S9) -> 33 | U9: 13 | V9: 12 | W9: =SUM(U9:V9) -> 25 | X9: NA | Y9: NA | Z9: NA | AA9: NA | AB9: NA | AC9: NA | AD9: NA | AE9: NA | AF9: NA | AG9: 23 | AH9: 13 | AI9: =SUM(AG9:AH9) -> 36 | AJ9: 24 | AK9: 16 | AL9: =SUM(AJ9:AK9) -> 40 | AM9: 25 | AN9: 18 | AO9: =SUM(AM9:AN9) -> 43 | AP9: 25 | AQ9: 17 | AR9: =SUM(AP9:AQ9) -> 42 | AV9: =INDIRECT(_xlfn.TEXTJOIN("",TRUE,"TC_",BC9,"!",ADDRESS(4+A9*(BD9+9),13))) -> 131.5 | AW9: =INDIRECT(_xlfn.TEXTJOIN("",TRUE,"TC_",BC9,"!",ADDRESS(5+A9*(BD9+9),12))) -> 20 | AX9: =IF(INDIRECT(_xlfn.TEXTJOIN("",TRUE,"TC_",BC9,"!",ADDRESS(4+A9*(BD9+9),23))),SUM(INDIRECT(_xlfn.TEXTJOIN("",TRUE,"TC_",BC9,"!",ADDRESS(4+A9*(BD9+9)-BD9,23),":",ADDRESS(3+A9*(BD9+9),23)))),0) -> 0 | AY9: =AV9/$AW$3 -> 5.4791667 | BC9: =BC8 -> I | BD9: =BD8 -> 14
A10: 5 | B10: 250090600005 | C10: UTU/2506100147 | D10: DEEPAK BISHT | E10: DIWAN SINGH BISHT | F10: 58 | G10: 38 | H10: =SUM(F10:G10) -> 96 | I10: 49 | J10: 37 | K10: =SUM(I10:J10) -> 86 | L10: 77 | M10: 44 | N10: =SUM(L10:M10) -> 121 | O10: 40 | P10: 34 | Q10: =SUM(O10:P10) -> 74 | R10: 63 | S10: 32 | T10: =SUM(R10:S10) -> 95 | U10: 19 | V10: 15 | W10: =SUM(U10:V10) -> 34 | X10: NA | Y10: NA | Z10: NA | AA10: NA | AB10: NA | AC10: NA | AD10: NA | AE10: NA | AF10: NA | AG10: 25 | AH10: 15 | AI10: =SUM(AG10:AH10) -> 40 | AJ10: 27 | AK10: 18 | AL10: =SUM(AJ10:AK10) -> 45 | AM10: 23 | AN10: 17 | AO10: =SUM(AM10:AN10) -> 40 | AP10: 24 | AQ10: 16 | AR10: =SUM(AP10:AQ10) -> 40 | AV10: =INDIRECT(_xlfn.TEXTJOIN("",TRUE,"TC_",BC10,"!",ADDRESS(4+A10*(BD10+9),13))) -> 165 | AW10: =INDIRECT(_xlfn.TEXTJOIN("",TRUE,"TC_",BC10,"!",ADDRESS(5+A10*(BD10+9),12))) -> 24 | AX10: =IF(INDIRECT(_xlfn.TEXTJOIN("",TRUE,"TC_",BC10,"!",ADDRESS(4+A10*(BD10+9),23))),SUM(INDIRECT(_xlfn.TEXTJOIN("",TRUE,"TC_",BC10,"!",ADDRESS(4+A10*(BD10+9)-BD10,23),":",ADDRESS(3+A10*(BD10+9),23)))),0) -> 0 | AY10: =AV10/$AW$3 -> 6.875 | BC10: =BC9 -> I | BD10: =BD9 -> 14
A11: 6 | B11: 250090600006 | C11: UTU/2506100117 | D11: DEVASHISH TIWARI | E11: MAHESHWAR PRASAD TIWARI | F11: 47 | G11: 35 | H11: =SUM(F11:G11) -> 82 | I11: 64 | J11: 42 | K11: =SUM(I11:J11) -> 106 | L11: 69 | M11: 43 | N11: =SUM(L11:M11) -> 112 | O11: 46 | P11: 39 | Q11: =SUM(O11:P11) -> 85 | R11: 85 | S11: 35 | T11: =SUM(R11:S11) -> 120 | U11: 23 | V11: 11 | W11: =SUM(U11:V11) -> 34 | X11: NA | Y11: NA | Z11: NA | AA11: NA | AB11: NA | AC11: NA | AD11: NA | AE11: NA | AF11: NA | AG11: 27 | AH11: 17 | AI11: =SUM(AG11:AH11) -> 44 | AJ11: 27 | AK11: 18 | AL11: =SUM(AJ11:AK11) -> 45 | AM11: 25 | AN11: 18 | AO11: =SUM(AM11:AN11) -> 43 | AP11: 26 | AQ11: 18 | AR11: =SUM(AP11:AQ11) -> 44 | AV11: =INDIRECT(_xlfn.TEXTJOIN("",TRUE,"TC_",BC11,"!",ADDRESS(4+A11*(BD11+9),13))) -> 176.5 | AW11: =INDIRECT(_xlfn.TEXTJOIN("",TRUE,"TC_",BC11,"!",ADDRESS(5+A11*(BD11+9),12))) -> 24 | AX11: =IF(INDIRECT(_xlfn.TEXTJOIN("",TRUE,"TC_",BC11,"!",ADDRESS(4+A11*(BD11+9),23))),SUM(INDIRECT(_xlfn.TEXTJOIN("",TRUE,"TC_",BC11,"!",ADDRESS(4+A11*(BD11+9)-BD11,23),":",ADDRESS(3+A11*(BD11+9),23)))),0) -> 0 | AY11: =AV11/$AW$3 -> 7.3541667 | BC11: =BC10 -> I | BD11: =BD10 -> 14
A12: 7 | B12: 250090600007 | C12: UTU/2506100121 | D12: DIVESH PANT | E12: DINESH CHANDRA PANT | F12: 40 | G12: 44 | H12: =SUM(F12:G12) -> 84 | I12: 37 | J12: 37 | K12: =SUM(I12:J12) -> 74 | L12: 52 | M12: 36 | N12: =SUM(L12:M12) -> 88 | O12: 42 | P12: 43 | Q12: =SUM(O12:P12) -> 85 | R12: 62 | S12: 36 | T12: =SUM(R12:S12) -> 98 | U12: 14 | V12: 12 | W12: =SUM(U12:V12) -> 26 | X12: NA | Y12: NA | Z12: NA | AA12: NA | AB12: NA | AC12: NA | AD12: NA | AE12: NA | AF12: NA | AG12: 25 | AH12: 15 | AI12: =SUM(AG12:AH12) -> 40 | AJ12: 24 | AK12: 16 | AL12: =SUM(AJ12:AK12) -> 40 | AM12: 27 | AN12: 18 | AO12: =SUM(AM12:AN12) -> 45 | AP12: 25 | AQ12: 16 | AR12: =SUM(AP12:AQ12) -> 41 | AV12: =INDIRECT(_xlfn.TEXTJOIN("",TRUE,"TC_",BC12,"!",ADDRESS(4+A12*(BD12+9),13))) -> 155 | AW12: =INDIRECT(_xlfn.TEXTJOIN("",TRUE,"TC_",BC12,"!",ADDRESS(5+A12*(BD12+9),12))) -> 24 | AX12: =IF(INDIRECT(_xlfn.TEXTJOIN("",TRUE,"TC_",BC12,"!",ADDRESS(4+A12*(BD12+9),23))),SUM(INDIRECT(_xlfn.TEXTJOIN("",TRUE,"TC_",BC12,"!",ADDRESS(4+A12*(BD12+9)-BD12,23),":",ADDRESS(3+A12*(BD12+9),23)))),0) -> 0 | AY12: =AV12/$AW$3 -> 6.4583333 | BC12: =BC11 -> I | BD12: =BD11 -> 14
A13: 8 | B13: 250090600008 | C13: PUTU/2506100145 | D13: KHUSHI DWIVEDI | E13: CHANDI PRASAD DWIVEDI | F13: 81 | G13: 49 | H13: =SUM(F13:G13) -> 130 | I13: 88 | J13: 48 | K13: =SUM(I13:J13) -> 136 | L13: 98 | M13: 50 | N13: =SUM(L13:M13) -> 148 | O13: 89 | P13: 50 | Q13: =SUM(O13:P13) -> 139 | R13: 95 | S13: 35 | T13: =SUM(R13:S13) -> 130 | U13: 24 | V13: 19 | W13: =SUM(U13:V13) -> 43 | X13: NA | Y13: NA | Z13: NA | AA13: NA | AB13: NA | AC13: NA | AD13: NA | AE13: NA | AF13: NA | AG13: 29 | AH13: 19 | AI13: =SUM(AG13:AH13) -> 48 | AJ13: 30 | AK13: 20 | AL13: =SUM(AJ13:AK13) -> 50 | AM13: 30 | AN13: 20 | AO13: =SUM(AM13:AN13) -> 50 | AP13: 23 | AQ13: 17 | AR13: =SUM(AP13:AQ13) -> 40 | AV13: =INDIRECT(_xlfn.TEXTJOIN("",TRUE,"TC_",BC13,"!",ADDRESS(4+A13*(BD13+9),13))) -> 226.5 | AW13: =INDIRECT(_xlfn.TEXTJOIN("",TRUE,"TC_",BC13,"!",ADDRESS(5+A13*(BD13+9),12))) -> 24 | AX13: =IF(INDIRECT(_xlfn.TEXTJOIN("",TRUE,"TC_",BC13,"!",ADDRESS(4+A13*(BD13+9),23))),SUM(INDIRECT(_xlfn.TEXTJOIN("",TRUE,"TC_",BC13,"!",ADDRESS(4+A13*(BD13+9)-BD13,23),":",ADDRESS(3+A13*(BD13+9),23)))),0) -> 0 | AY13: =AV13/$AW$3 -> 9.4375 | BC13: =BC12 -> I | BD13: =BD12 -> 14
A14: 9 | B14: 250090600009 | C14: UTU/2506100160 | D14: KIRAN SAHANI | E14: VINOD SAHANI | F14: 65 | G14: 43 | H14: =SUM(F14:G14) -> 108 | I14: 59 | J14: 36 | K14: =SUM(I14:J14) -> 95 | L14: 71 | M14: 40 | N14: =SUM(L14:M14) -> 111 | O14: 46 | P14: 46 | Q14: =SUM(O14:P14) -> 92 | R14: 63 | S14: 33 | T14: =SUM(R14:S14) -> 96 | U14: 15 | V14: 12 | W14: =SUM(U14:V14) -> 27 | X14: 23 | Y14: 15 | Z14: =SUM(X14:Y14) -> 38 | AA14: 18 | AB14: 17 | AC14: =SUM(AA14:AB14) -> 35 | AD14: 24 | AE14: 16 | AF14: =SUM(AD14:AE14) -> 40 | AG14: 25 | AH14: 15 | AI14: =SUM(AG14:AH14) -> 40 | AJ14: 24 | AK14: 16 | AL14: =SUM(AJ14:AK14) -> 40 | AM14: 27 | AN14: 19 | AO14: =SUM(AM14:AN14) -> 46 | AP14: 22 | AQ14: 16 | AR14: =SUM(AP14:AQ14) -> 38 | AV14: =INDIRECT(_xlfn.TEXTJOIN("",TRUE,"TC_",BC14,"!",ADDRESS(4+A14*(BD14+9),13))) -> 172.5 | AW14: =INDIRECT(_xlfn.TEXTJOIN("",TRUE,"TC_",BC14,"!",ADDRESS(5+A14*(BD14+9),12))) -> 24 | AX14: =IF(INDIRECT(_xlfn.TEXTJOIN("",TRUE,"TC_",BC14,"!",ADDRESS(4+A14*(BD14+9),23))),SUM(INDIRECT(_xlfn.TEXTJOIN("",TRUE,"TC_",BC14,"!",ADDRESS(4+A14*(BD14+9)-BD14,23),":",ADDRESS(3+A14*(BD14+9),23)))),0) -> 0 | AY14: =AV14/$AW$3 -> 7.1875 | BC14: =BC13 -> I | BD14: =BD13 -> 14
A15: 10 | B15: 250090600010 | C15: UTU/2506100154 | D15: NIKITA BALODHI | E15: MR DHANJAY PRASAD BALODHI | F15: 53 | G15: 37 | H15: =SUM(F15:G15) -> 90 | I15: 64 | J15: 38 | K15: =SUM(I15:J15) -> 102 | L15: 76 | M15: 42 | N15: =SUM(L15:M15) -> 118 | O15: 52 | P15: 44 | Q15: =SUM(O15:P15) -> 96 | R15: 84 | S15: 37 | T15: =SUM(R15:S15) -> 121 | U15: 13 | V15: 14 | W15: =SUM(U15:V15) -> 27 | X15: NA | Y15: NA | Z15: NA | AA15: NA | AB15: NA | AC15: NA | AD15: NA | AE15: NA | AF15: NA | AG15: 24 | AH15: 15 | AI15: =SUM(AG15:AH15) -> 39 | AJ15: 26 | AK15: 17 | AL15: =SUM(AJ15:AK15) -> 43 | AM15: 25 | AN15: 19 | AO15: =SUM(AM15:AN15) -> 44 | AP15: 24 | AQ15: 18 | AR15: =SUM(AP15:AQ15) -> 42 | AV15: =INDIRECT(_xlfn.TEXTJOIN("",TRUE,"TC_",BC15,"!",ADDRESS(4+A15*(BD15+9),13))) -> 180.5 | AW15: =INDIRECT(_xlfn.TEXTJOIN("",TRUE,"TC_",BC15,"!",ADDRESS(5+A15*(BD15+9),12))) -> 24 | AX15: =IF(INDIRECT(_xlfn.TEXTJOIN("",TRUE,"TC_",BC15,"!",ADDRESS(4+A15*(BD15+9),23))),SUM(INDIRECT(_xlfn.TEXTJOIN("",TRUE,"TC_",BC15,"!",ADDRESS(4+A15*(BD15+9)-BD15,23),":",ADDRESS(3+A15*(BD15+9),23)))),0) -> 0 | AY15: =AV15/$AW$3 -> 7.5208333 | BC15: =BC14 -> I | BD15: =BD14 -> 14
A16: 11 | B16: 250090600011 | C16: UTU/2506100161 | D16: NISHTHA ARORA | E16: SUNIL ARORA | F16: 53 | G16: 38 | H16: =SUM(F16:G16) -> 91 | I16: 66 | J16: 38 | K16: =SUM(I16:J16) -> 104 | L16: 67 | M16: 50 | N16: =SUM(L16:M16) -> 117 | O16: 55 | P16: 41 | Q16: =SUM(O16:P16) -> 96 | R16: 85 | S16: 34 | T16: =SUM(R16:S16) -> 119 | U16: 16 | V16: 14 | W16: =SUM(U16:V16) -> 30 | X16: NA | Y16: NA | Z16: NA | AA16: NA | AB16: NA | AC16: NA | AD16: NA | AE16: NA | AF16: NA | AG16: 25 | AH16: 15 | AI16: =SUM(AG16:AH16) -> 40 | AJ16: 30 | AK16: 20 | AL16: =SUM(AJ16:AK16) -> 50 | AM16: 25 | AN16: 19 | AO16: =SUM(AM16:AN16) -> 44 | AP16: 25 | AQ16: 17 | AR16: =SUM(AP16:AQ16) -> 42 | AV16: =INDIRECT(_xlfn.TEXTJOIN("",TRUE,"TC_",BC16,"!",ADDRESS(4+A16*(BD16+9),13))) -> 180 | AW16: =INDIRECT(_xlfn.TEXTJOIN("",TRUE,"TC_",BC16,"!",ADDRESS(5+A16*(BD16+9),12))) -> 24 | AX16: =IF(INDIRECT(_xlfn.TEXTJOIN("",TRUE,"TC_",BC16,"!",ADDRESS(4+A16*(BD16+9),23))),SUM(INDIRECT(_xlfn.TEXTJOIN("",TRUE,"TC_",BC16,"!",ADDRESS(4+A16*(BD16+9)-BD16,23),":",ADDRESS(3+A16*(BD16+9),23)))),0) -> 0 | AY16: =AV16/$AW$3 -> 7.5 | BC16: =BC15 -> I | BD16: =BD15 -> 14
A17: 12 | B17: 250090600012 | C17: UTU/2506100155 | D17: OJASWEE BISHT | E17: PRAMOD BISHT | F17: 65 | G17: 46 | H17: =SUM(F17:G17) -> 111 | I17: 59 | J17: 44 | K17: =SUM(I17:J17) -> 103 | L17: 79 | M17: 46 | N17: =SUM(L17:M17) -> 125 | O17: 60 | P17: 41 | Q17: =SUM(O17:P17) -> 101 | R17: 83 | S17: 36 | T17: =SUM(R17:S17) -> 119 | U17: 22 | V17: 15 | W17: =SUM(U17:V17) -> 37 | X17: NA | Y17: NA | Z17: NA | AA17: NA | AB17: NA | AC17: NA | AD17: NA | AE17: NA | AF17: NA | AG17: 28 | AH17: 18 | AI17: =SUM(AG17:AH17) -> 46 | AJ17: 27 | AK17: 18 | AL17: =SUM(AJ17:AK17) -> 45 | AM17: 25 | AN17: 19 | AO17: =SUM(AM17:AN17) -> 44 | AP17: 26 | AQ17: 17 | AR17: =SUM(AP17:AQ17) -> 43 | AV17: =INDIRECT(_xlfn.TEXTJOIN("",TRUE,"TC_",BC17,"!",ADDRESS(4+A17*(BD17+9),13))) -> 189 | AW17: =INDIRECT(_xlfn.TEXTJOIN("",TRUE,"TC_",BC17,"!",ADDRESS(5+A17*(BD17+9),12))) -> 24 | AX17: =IF(INDIRECT(_xlfn.TEXTJOIN("",TRUE,"TC_",BC17,"!",ADDRESS(4+A17*(BD17+9),23))),SUM(INDIRECT(_xlfn.TEXTJOIN("",TRUE,"TC_",BC17,"!",ADDRESS(4+A17*(BD17+9)-BD17,23),":",ADDRESS(3+A17*(BD17+9),23)))),0) -> 0 | AY17: =AV17/$AW$3 -> 7.875 | BC17: =BC16 -> I | BD17: =BD16 -> 14
A18: 13 | B18: 250090600013 | C18: UTU/2506100158 | D18: RATNESH JUYAL | E18: BHAGWAT PRASAD JUYAL | F18: 41 | G18: 36 | H18: =SUM(F18:G18) -> 77 | I18: 41 | J18: 28 | K18: =SUM(I18:J18) -> 69 | L18: 57 | M18: 35 | N18: =SUM(L18:M18) -> 92 | O18: 26 | P18: 31 | Q18: =SUM(O18:P18) -> 57 | R18: 51 | S18: 34 | T18: =SUM(R18:S18) -> 85 | U18: 17 | V18: 12 | W18: =SUM(U18:V18) -> 29 | X18: NA | Y18: NA | Z18: NA | AA18: NA | AB18: NA | AC18: NA | AD18: NA | AE18: NA | AF18: NA | AG18: 23 | AH18: 13 | AI18: =SUM(AG18:AH18) -> 36 | AJ18: 24 | AK18: 16 | AL18: =SUM(AJ18:AK18) -> 40 | AM18: 27 | AN18: 18 | AO18: =SUM(AM18:AN18) -> 45 | AP18: 25 | AQ18: 16 | AR18: =SUM(AP18:AQ18) -> 41 | AV18: =INDIRECT(_xlfn.TEXTJOIN("",TRUE,"TC_",BC18,"!",ADDRESS(4+A18*(BD18+9),13))) -> 144 | AW18: =INDIRECT(_xlfn.TEXTJOIN("",TRUE,"TC_",BC18,"!",ADDRESS(5+A18*(BD18+9),12))) -> 24 | AX18: =IF(INDIRECT(_xlfn.TEXTJOIN("",TRUE,"TC_",BC18,"!",ADDRESS(4+A18*(BD18+9),23))),SUM(INDIRECT(_xlfn.TEXTJOIN("",TRUE,"TC_",BC18,"!",ADDRESS(4+A18*(BD18+9)-BD18,23),":",ADDRESS(3+A18*(BD18+9),23)))),0) -> 4 | AY18: =AV18/$AW$3 -> 6 | BC18: =BC17 -> I | BD18: =BD17 -> 14
A19: 14 | B19: 250090600014 | C19: UTU/2506100138 | D19: REETU SAINI | E19: ARJUN SINGH SAINI | F19: 35 | G19: 33 | H19: =SUM(F19:G19) -> 68 | I19: 58 | J19: 35 | K19: =SUM(I19:J19) -> 93 | L19: 74 | M19: 39 | N19: =SUM(L19:M19) -> 113 | O19: 35 | P19: 47 | Q19: =SUM(O19:P19) -> 82 | R19: 61 | S19: 32 | T19: =SUM(R19:S19) -> 93 | U19: 14 | V19: 12 | W19: =SUM(U19:V19) -> 26 | X19: NA | Y19: NA | Z19: NA | AA19: NA | AB19: NA | AC19: NA | AD19: NA | AE19: NA | AF19: NA | AG19: 24 | AH19: 14 | AI19: =SUM(AG19:AH19) -> 38 | AJ19: 24 | AK19: 16 | AL19: =SUM(AJ19:AK19) -> 40 | AM19: 23 | AN19: 19 | AO19: =SUM(AM19:AN19) -> 42 | AP19: 23 | AQ19: 17 | AR19: =SUM(AP19:AQ19) -> 40 | AV19: =INDIRECT(_xlfn.TEXTJOIN("",TRUE,"TC_",BC19,"!",ADDRESS(4+A19*(BD19+9),13))) -> 159.5 | AW19: =INDIRECT(_xlfn.TEXTJOIN("",TRUE,"TC_",BC19,"!",ADDRESS(5+A19*(BD19+9),12))) -> 24 | AX19: =IF(INDIRECT(_xlfn.TEXTJOIN("",TRUE,"TC_",BC19,"!",ADDRESS(4+A19*(BD19+9),23))),SUM(INDIRECT(_xlfn.TEXTJOIN("",TRUE,"TC_",BC19,"!",ADDRESS(4+A19*(BD19+9)-BD19,23),":",ADDRESS(3+A19*(BD19+9),23)))),0) -> 0 | AY19: =AV19/$AW$3 -> 6.6458333 | BC19: =BC18 -> I | BD19: =BD18 -> 14
A20: 15 | B20: 250090600015 | C20: PUTU/2506100115 | D20: RISHABH KAINTURA | E20: SURENDER KAINTURA | F20: 36 | G20: 32 | H20: =SUM(F20:G20) -> 68 | I20: 35 | J20: 33 | K20: =SUM(I20:J20) -> 68 | L20: 50 | M20: 36 | N20: =SUM(L20:M20) -> 86 | O20: 27 | P20: 30 | Q20: =SUM(O20:P20) -> 57 | R20: 55 | S20: 31 | T20: =SUM(R20:S20) -> 86 | U20: 14 | V20: 13 | W20: =SUM(U20:V20) -> 27 | X20: NA | Y20: NA | Z20: NA | AA20: NA | AB20: NA | AC20: NA | AD20: NA | AE20: NA | AF20: NA | AG20: 23 | AH20: 13 | AI20: =SUM(AG20:AH20) -> 36 | AJ20: 24 | AK20: 16 | AL20: =SUM(AJ20:AK20) -> 40 | AM20: 23 | AN20: 16 | AO20: =SUM(AM20:AN20) -> 39 | AP20: 25 | AQ20: 17 | AR20: =SUM(AP20:AQ20) -> 42 | AV20: =INDIRECT(_xlfn.TEXTJOIN("",TRUE,"TC_",BC20,"!",ADDRESS(4+A20*(BD20+9),13))) -> 138.5 | AW20: =INDIRECT(_xlfn.TEXTJOIN("",TRUE,"TC_",BC20,"!",ADDRESS(5+A20*(BD20+9),12))) -> 24 | AX20: =IF(INDIRECT(_xlfn.TEXTJOIN("",TRUE,"TC_",BC20,"!",ADDRESS(4+A20*(BD20+9),23))),SUM(INDIRECT(_xlfn.TEXTJOIN("",TRUE,"TC_",BC20,"!",ADDRESS(4+A20*(BD20+9)-BD20,23),":",ADDRESS(3+A20*(BD20+9),23)))),0) -> 3 | AY20: =AV20/$AW$3 -> 5.7708333 | BC20: =BC19 -> I | BD20: =BD19 -> 14
A21: 16 | B21: 250090600016 | C21: PUTU/2506100124 | D21: ROHIT SINGH | E21: MAHESH CHANDRA SINGH | F21: 80 | G21: 42 | H21: =SUM(F21:G21) -> 122 | I21: 57 | J21: 39 | K21: =SUM(I21:J21) -> 96 | L21: 79 | M21: 45 | N21: =SUM(L21:M21) -> 124 | O21: 75 | P21: 49 | Q21: =SUM(O21:P21) -> 124 | R21: 83 | S21: 49 | T21: =SUM(R21:S21) -> 132 | U21: 17 | V21: 15 | W21: =SUM(U21:V21) -> 32 | X21: NA | Y21: NA | Z21: NA | AA21: NA | AB21: NA | AC21: NA | AD21: NA | AE21: NA | AF21: NA | AG21: 26 | AH21: 16 | AI21: =SUM(AG21:AH21) -> 42 | AJ21: 27 | AK21: 18 | AL21: =SUM(AJ21:AK21) -> 45 | AM21: 28 | AN21: 19 | AO21: =SUM(AM21:AN21) -> 47 | AP21: 30 | AQ21: 18 | AR21: =SUM(AP21:AQ21) -> 48 | AV21: =INDIRECT(_xlfn.TEXTJOIN("",TRUE,"TC_",BC21,"!",ADDRESS(4+A21*(BD21+9),13))) -> 201.5 | AW21: =INDIRECT(_xlfn.TEXTJOIN("",TRUE,"TC_",BC21,"!",ADDRESS(5+A21*(BD21+9),12))) -> 24 | AX21: =IF(INDIRECT(_xlfn.TEXTJOIN("",TRUE,"TC_",BC21,"!",ADDRESS(4+A21*(BD21+9),23))),SUM(INDIRECT(_xlfn.TEXTJOIN("",TRUE,"TC_",BC21,"!",ADDRESS(4+A21*(BD21+9)-BD21,23),":",ADDRESS(3+A21*(BD21+9),23)))),0) -> 0 | AY21: =AV21/$AW$3 -> 8.3958333 | BC21: =BC20 -> I | BD21: =BD20 -> 14
A22: 17 | B22: 250090600017 | C22: UTU/2506100148 | D22: SAURAV DHAPOLA | E22: NARENDRA SINGH | F22: 58 | G22: 34 | H22: =SUM(F22:G22) -> 92 | I22: 47 | J22: 39 | K22: =SUM(I22:J22) -> 86 | L22: 75 | M22: 46 | N22: =SUM(L22:M22) -> 121 | O22: 38 | P22: 31 | Q22: =SUM(O22:P22) -> 69 | R22: 73 | S22: 34 | T22: =SUM(R22:S22) -> 107 | U22: 16 | V22: 13 | W22: =SUM(U22:V22) -> 29 | X22: NA | Y22: NA | Z22: NA | AA22: NA | AB22: NA | AC22: NA | AD22: NA | AE22: NA | AF22: NA | AG22: 27 | AH22: 17 | AI22: =SUM(AG22:AH22) -> 44 | AJ22: 27 | AK22: 18 | AL22: =SUM(AJ22:AK22) -> 45 | AM22: 27 | AN22: 17 | AO22: =SUM(AM22:AN22) -> 44 | AP22: 26 | AQ22: 16 | AR22: =SUM(AP22:AQ22) -> 42 | AV22: =INDIRECT(_xlfn.TEXTJOIN("",TRUE,"TC_",BC22,"!",ADDRESS(4+A22*(BD22+9),13))) -> 170 | AW22: =INDIRECT(_xlfn.TEXTJOIN("",TRUE,"TC_",BC22,"!",ADDRESS(5+A22*(BD22+9),12))) -> 24 | AX22: =IF(INDIRECT(_xlfn.TEXTJOIN("",TRUE,"TC_",BC22,"!",ADDRESS(4+A22*(BD22+9),23))),SUM(INDIRECT(_xlfn.TEXTJOIN("",TRUE,"TC_",BC22,"!",ADDRESS(4+A22*(BD22+9)-BD22,23),":",ADDRESS(3+A22*(BD22+9),23)))),0) -> 0 | AY22: =AV22/$AW$3 -> 7.0833333 | BC22: =BC21 -> I | BD22: =BD21 -> 14
A23: 18 | B23: 250090600018 | C23: UTU/2506100123 | D23: SHIVANK RAWAT | E23: DEVENDRA SINGH RAWAT | F23: 68 | G23: 43 | H23: =SUM(F23:G23) -> 111 | I23: 57 | J23: 39 | K23: =SUM(I23:J23) -> 96 | L23: 66 | M23: 44 | N23: =SUM(L23:M23) -> 110 | O23: 60 | P23: 42 | Q23: =SUM(O23:P23) -> 102 | R23: 56 | S23: 35 | T23: =SUM(R23:S23) -> 91 | U23: 17 | V23: 16 | W23: =SUM(U23:V23) -> 33 | X23: NA | Y23: NA | Z23: NA | AA23: NA | AB23: NA | AC23: NA | AD23: NA | AE23: NA | AF23: NA | AG23: 25 | AH23: 17 | AI23: =SUM(AG23:AH23) -> 42 | AJ23: 27 | AK23: 18 | AL23: =SUM(AJ23:AK23) -> 45 | AM23: 27 | AN23: 19 | AO23: =SUM(AM23:AN23) -> 46 | AP23: 25 | AQ23: 17 | AR23: =SUM(AP23:AQ23) -> 42 | AV23: =INDIRECT(_xlfn.TEXTJOIN("",TRUE,"TC_",BC23,"!",ADDRESS(4+A23*(BD23+9),13))) -> 176 | AW23: =INDIRECT(_xlfn.TEXTJOIN("",TRUE,"TC_",BC23,"!",ADDRESS(5+A23*(BD23+9),12))) -> 24 | AX23: =IF(INDIRECT(_xlfn.TEXTJOIN("",TRUE,"TC_",BC23,"!",ADDRESS(4+A23*(BD23+9),23))),SUM(INDIRECT(_xlfn.TEXTJOIN("",TRUE,"TC_",BC23,"!",ADDRESS(4+A23*(BD23+9)-BD23,23),":",ADDRESS(3+A23*(BD23+9),23)))),0) -> 0 | AY23: =AV23/$AW$3 -> 7.3333333 | BC23: =BC22 -> I | BD23: =BD22 -> 14
A24: 19 | B24: 250090600019 | C24: UTU/2506100146 | D24: SIMRAN KANDARI | E24: MANMOHAN SINGH | F24: 70 | G24: 40 | H24: =SUM(F24:G24) -> 110 | I24: 71 | J24: 39 | K24: =SUM(I24:J24) -> 110 | L24: 72 | M24: 39 | N24: =SUM(L24:M24) -> 111 | O24: 36 | P24: 44 | Q24: =SUM(O24:P24) -> 80 | R24: 92 | S24: 36 | T24: =SUM(R24:S24) -> 128 | U24: 18 | V24: 16 | W24: =SUM(U24:V24) -> 34 | X24: NA | Y24: NA | Z24: NA | AA24: NA | AB24: NA | AC24: NA | AD24: NA | AE24: NA | AF24: NA | AG24: 26 | AH24: 17 | AI24: =SUM(AG24:AH24) -> 43 | AJ24: 24 | AK24: 16 | AL24: =SUM(AJ24:AK24) -> 40 | AM24: 28 | AN24: 19 | AO24: =SUM(AM24:AN24) -> 47 | AP24: 26 | AQ24: 18 | AR24: =SUM(AP24:AQ24) -> 44 | AV24: =INDIRECT(_xlfn.TEXTJOIN("",TRUE,"TC_",BC24,"!",ADDRESS(4+A24*(BD24+9),13))) -> 184 | AW24: =INDIRECT(_xlfn.TEXTJOIN("",TRUE,"TC_",BC24,"!",ADDRESS(5+A24*(BD24+9),12))) -> 24 | AX24: =IF(INDIRECT(_xlfn.TEXTJOIN("",TRUE,"TC_",BC24,"!",ADDRESS(4+A24*(BD24+9),23))),SUM(INDIRECT(_xlfn.TEXTJOIN("",TRUE,"TC_",BC24,"!",ADDRESS(4+A24*(BD24+9)-BD24,23),":",ADDRESS(3+A24*(BD24+9),23)))),0) -> 0 | AY24: =AV24/$AW$3 -> 7.6666667 | BC24: =BC23 -> I | BD24: =BD23 -> 14
A25: 20 | B25: 250090600020 | C25: UTU/2506100157 | D25: VIVEK | E25: SATYAPAL | F25: 41 | G25: 32 | H25: =SUM(F25:G25) -> 73 | I25: 37 | J25: 30 | K25: =SUM(I25:J25) -> 67 | L25: 51 | M25: 35 | N25: =SUM(L25:M25) -> 86 | O25: 34 | P25: 33 | Q25: =SUM(O25:P25) -> 67 | R25: 68 | S25: 34 | T25: =SUM(R25:S25) -> 102 | U25: 18 | V25: 15 | W25: =SUM(U25:V25) -> 33 | X25: NA | Y25: NA | Z25: NA | AA25: NA | AB25: NA | AC25: NA | AD25: NA | AE25: NA | AF25: NA | AG25: 23 | AH25: 13 | AI25: =SUM(AG25:AH25) -> 36 | AJ25: 24 | AK25: 16 | AL25: =SUM(AJ25:AK25) -> 40 | AM25: 27 | AN25: 18 | AO25: =SUM(AM25:AN25) -> 45 | AP25: 25 | AQ25: 16 | AR25: =SUM(AP25:AQ25) -> 41 | AV25: =INDIRECT(_xlfn.TEXTJOIN("",TRUE,"TC_",BC25,"!",ADDRESS(4+A25*(BD25+9),13))) -> 142 | AW25: =INDIRECT(_xlfn.TEXTJOIN("",TRUE,"TC_",BC25,"!",ADDRESS(5+A25*(BD25+9),12))) -> 24 | AX25: =IF(INDIRECT(_xlfn.TEXTJOIN("",TRUE,"TC_",BC25,"!",ADDRESS(4+A25*(BD25+9),23))),SUM(INDIRECT(_xlfn.TEXTJOIN("",TRUE,"TC_",BC25,"!",ADDRESS(4+A25*(BD25+9)-BD25,23),":",ADDRESS(3+A25*(BD25+9),23)))),0) -> 0 | AY25: =AV25/$AW$3 -> 5.9166667 | BC25: =BC24 -> I | BD25: =BD24 -> 14

Sheet SEM_II
A1: SC | B1: Roll No. | C1: Enroll No. | D1: Student's Name | E1: Father's Name | F1: CAT 009 | I1: CAT 010 | L1: CAT 011 | O1: CAT 012 | R1: CAT 013 | U1: AHT 304 | X1: CAP 004 | AA1: CAP 005 | AD1: CAP 006 | AG1: CAP 007 | AJ1: TGP | AK1: EC | AL1: Grace | AM1: CGPA
A2: SN | F2: Computer Based Numerical and Statistical Techniques | I2: Data Structures and Analysis of Algorithms | L2: Object Oriented Programming with JAVA | O2: Computer Networks | R2: Artificial Intelligence | U2: Accounting and Financial Management ($) | X2: Data Structures and Analysis of Algorithms Lab | AA2: Object Oriented Programming with JAVA Lab | AD2: Computer Networks Lab | AG2: Artificial Intelligence Lab
A3: C | F3: 4 | I3: 4 | L3: 4 | O3: 4 | R3: 4 | U3: 0 | X3: 1 | AA3: 1 | AD3: 1 | AG3: 1 | AK3: =INDIRECT(_xlfn.TEXTJOIN("",TRUE,"SEM_",AN6,"!",ADDRESS(3,5+AP6*3+2)))+SUM(F3:AI3) -> 48
F4: Th. Ex. | G4: Ses. | H4: Total | I4: Th. Ex. | J4: Ses. | K4: Total | L4: Th. Ex. | M4: Ses. | N4: Total | O4: Th. Ex. | P4: Ses. | Q4: Total | R4: Th. Ex. | S4: Ses. | T4: Total | U4: Pr. Ex. | V4: Ses. | W4: Total | X4: Pr. Ex. | Y4: Ses. | Z4: Total | AA4: Pr. Ex. | AB4: Ses. | AC4: Total | AD4: Pr. Ex. | AE4: Ses. | AF4: Total | AG4: Pr. Ex. | AH4: Ses. | AI4: Total
A5: MM | F5: 100 | G5: 50 | H5: 150 | I5: 100 | J5: 50 | K5: 150 | L5: 100 | M5: 50 | N5: 150 | O5: 100 | P5: 50 | Q5: 150 | R5: 100 | S5: 50 | T5: 150 | U5: 0 | V5: 50 | W5: 50 | X5: 30 | Y5: 20 | Z5: 50 | AA5: 30 | AB5: 20 | AC5: 50 | AD5: 30 | AE5: 20 | AF5: 50 | AG5: 30 | AH5: 20 | AI5: 50
A6: 1 | B6: 240090600001 | C6: UTU/2406100187 | D6: ALOK NEGI | E6: PRATAP SINGH NEGI | F6: 58 | G6: 46 | H6: =SUM(F6:G6) -> 104 | I6: 75 | J6: 43 | K6: =SUM(I6:J6) -> 118 | L6: 66 | M6: 44 | N6: =SUM(L6:M6) -> 110 | O6: 54 | P6: 42 | Q6: =SUM(O6:P6) -> 96 | R6: 77 | S6: 46 | T6: =SUM(R6:S6) -> 123 | V6: 27 | W6: =SUM(V6) -> 27 | X6: 24 | Y6: 18 | Z6: =SUM(X6:Y6) -> 42 | AA6: 20 | AB6: 17 | AC6: =SUM(AA6:AB6) -> 37 | AD6: 24 | AE6: 18 | AF6: =SUM(AD6:AE6) -> 42 | AG6: 27 | AH6: 19 | AI6: =SUM(AG6:AH6) -> 46 | AJ6: =IF(LEFT(B6,1)="7",0,INDEX(INDIRECT(_xlfn.TEXTJOIN("",TRUE,"SEM_",AN6,"!",ADDRESS(6,5+AP6*3+1),":",ADDRESS(5+AO6,5+AP6*3+1))),MATCH(B6,INDIRECT(_xlfn.TEXTJOIN("",TRUE,"SEM_",AN6,"!",ADDRESS(6,2),":",ADDRESS(5+AO6,2))),0)))+INDIRECT(_xlfn.TEXTJOIN("",TRUE,"TC_",AQ6,"!",ADDRESS(4+A6*(AR6+9),13))) -> #N/A | AK6: =IF(LEFT(B6,1)="7",0,INDEX(INDIRECT(_xlfn.TEXTJOIN("",TRUE,"SEM_",AN6,"!",ADDRESS(6,5+AP6*3+2),":",ADDRESS(5+AO6,5+AP6*3+2))),MATCH(B6,INDIRECT(_xlfn.TEXTJOIN("",TRUE,"SEM_",AN6,"!",ADDRESS(6,2),":",ADDRESS(5+AO6,2))),0)))+INDIRECT(_xlfn.TEXTJOIN("",TRUE,"TC_",AQ6,"!",ADDRESS(5+A6*(AR6+9),12))) -> #N/A | AL6: =IF(INDIRECT(_xlfn.TEXTJOIN("",TRUE,"TC_",AQ6,"!",ADDRESS(4+A6*(AR6+9),23))),SUM(INDIRECT(_xlfn.TEXTJOIN("",TRUE,"TC_",AQ6,"!",ADDRESS(4+A6*(AR6+9)-AR6,23),":",ADDRESS(3+A6*(AR6+9),23)))),0) -> #N/A | AM6: =IF(LEFT(B6,1)="7",AJ6/$AK$4,AJ6/$AK$3) -> #N/A | AN6: I | AO6: 25 | AP6: 14 | AQ6: II | AR6: 10
A7: 2 | B7: 240090600002 | C7: UTU/2406100171 | D7: AMAN POKHRIYAL | E7: VINOD PRASSAD POKHRIYAL | F7: 40 | G7: 42 | H7: =SUM(F7:G7) -> 82 | I7: 57 | J7: 40 | K7: =SUM(I7:J7) -> 97 | L7: 45 | M7: 36 | N7: =SUM(L7:M7) -> 81 | O7: 32 | P7: 38 | Q7: =SUM(O7:P7) -> 70 | R7: 53 | S7: 48 | T7: =SUM(R7:S7) -> 101 | V7: 35 | W7: =SUM(V7) -> 35 | X7: 23 | Y7: 16 | Z7: =SUM(X7:Y7) -> 39 | AA7: 23 | AB7: 14 | AC7: =SUM(AA7:AB7) -> 37 | AD7: 23 | AE7: 17 | AF7: =SUM(AD7:AE7) -> 40 | AG7: 26 | AH7: 19 | AI7: =SUM(AG7:AH7) -> 45 | AJ7: =IF(LEFT(B7,1)="7",0,INDEX(INDIRECT(_xlfn.TEXTJOIN("",TRUE,"SEM_",AN7,"!",ADDRESS(6,5+AP7*3+1),":",ADDRESS(5+AO7,5+AP7*3+1))),MATCH(B7,INDIRECT(_xlfn.TEXTJOIN("",TRUE,"SEM_",AN7,"!",ADDRESS(6,2),":",ADDRESS(5+AO7,2))),0)))+INDIRECT(_xlfn.TEXTJOIN("",TRUE,"TC_",AQ7,"!",ADDRESS(4+A7*(AR7+9),13))) -> #N/A | AK7: =IF(LEFT(B7,1)="7",0,INDEX(INDIRECT(_xlfn.TEXTJOIN("",TRUE,"SEM_",AN7,"!",ADDRESS(6,5+AP7*3+2),":",ADDRESS(5+AO7,5+AP7*3+2))),MATCH(B7,INDIRECT(_xlfn.TEXTJOIN("",TRUE,"SEM_",AN7,"!",ADDRESS(6,2),":",ADDRESS(5+AO7,2))),0)))+INDIRECT(_xlfn.TEXTJOIN("",TRUE,"TC_",AQ7,"!",ADDRESS(5+A7*(AR7+9),12))) -> #N/A | AL7: =IF(INDIRECT(_xlfn.TEXTJOIN("",TRUE,"TC_",AQ7,"!",ADDRESS(4+A7*(AR7+9),23))),SUM(INDIRECT(_xlfn.TEXTJOIN("",TRUE,"TC_",AQ7,"!",ADDRESS(4+A7*(AR7+9)-AR7,23),":",ADDRESS(3+A7*(AR7+9),23)))),0) -> #N/A | AM7: =IF(LEFT(B7,1)="7",AJ7/$AK$4,AJ7/$AK$3) -> #N/A | AN7: =AN6 -> I | AO7: =AO6 -> 25 | AP7: =AP6 -> 14 | AQ7: =AQ6 -> II | AR7: =AR6 -> 10
A8: 3 | B8: 240090600003 | C8: UTU/2406100173 | D8: ANAS SAIFI | E8: SALMUDDIN SAIFI | F8: 50 | G8: 37 | H8: =SUM(F8:G8) -> 87 | I8: 50 | J8: 37 | K8: =SUM(I8:J8) -> 87 | L8: 41 | M8: 40 | N8: =SUM(L8:M8) -> 81 | O8: 43 | P8: 40 | Q8: =SUM(O8:P8) -> 83 | R8: 61 | S8: 45 | T8: =SUM(R8:S8) -> 106 | V8: 28 | W8: =SUM(V8) -> 28 | X8: 22 | Y8: 15 | Z8: =SUM(X8:Y8) -> 37 | AA8: 20 | AB8: 16 | AC8: =SUM(AA8:AB8) -> 36 | AD8: 22 | AE8: 16 | AF8: =SUM(AD8:AE8) -> 38 | AG8: 24 | AH8: 17 | AI8: =SUM(AG8:AH8) -> 41 | AJ8: =IF(LEFT(B8,1)="7",0,INDEX(INDIRECT(_xlfn.TEXTJOIN("",TRUE,"SEM_",AN8,"!",ADDRESS(6,5+AP8*3+1),":",ADDRESS(5+AO8,5+AP8*3+1))),MATCH(B8,INDIRECT(_xlfn.TEXTJOIN("",TRUE,"SEM_",AN8,"!",ADDRESS(6,2),":",ADDRESS(5+AO8,2))),0)))+INDIRECT(_xlfn.TEXTJOIN("",TRUE,"TC_",AQ8,"!",ADDRESS(4+A8*(AR8+9),13))) -> #N/A | AK8: =IF(LEFT(B8,1)="7",0,INDEX(INDIRECT(_xlfn.TEXTJOIN("",TRUE,"SEM_",AN8,"!",ADDRESS(6,5+AP8*3+2),":",ADDRESS(5+AO8,5+AP8*3+2))),MATCH(B8,INDIRECT(_xlfn.TEXTJOIN("",TRUE,"SEM_",AN8,"!",ADDRESS(6,2),":",ADDRESS(5+AO8,2))),0)))+INDIRECT(_xlfn.TEXTJOIN("",TRUE,"TC_",AQ8,"!",ADDRESS(5+A8*(AR8+9),12))) -> #N/A | AL8: =IF(INDIRECT(_xlfn.TEXTJOIN("",TRUE,"TC_",AQ8,"!",ADDRESS(4+A8*(AR8+9),23))),SUM(INDIRECT(_xlfn.TEXTJOIN("",TRUE,"TC_",AQ8,"!",ADDRESS(4+A8*(AR8+9)-AR8,23),":",ADDRESS(3+A8*(AR8+9),23)))),0) -> #N/A | AM8: =IF(LEFT(B8,1)="7",AJ8/$AK$4,AJ8/$AK$3) -> #N/A | AN8: =AN7 -> I | AO8: =AO7 -> 25 | AP8: =AP7 -> 14 | AQ8: =AQ7 -> II | AR8: =AR7 -> 10
A9: 4 | B9: 240090600004 | C9: UTU/2406100161 | D9: ANJALI GUSAIN | E9: JAIBEER SINGH GUSAIN | F9: 62 | G9: 43 | H9: =SUM(F9:G9) -> 105 | I9: 66 | J9: 37 | K9: =SUM(I9:J9) -> 103 | L9: 40 | M9: 34 | N9: =SUM(L9:M9) -> 74 | O9: 30 | P9: 32 | Q9: =SUM(O9:P9) -> 62 | R9: 42 | S9: 34 | T9: =SUM(R9:S9) -> 76 | V9: 32 | W9: =SUM(V9) -> 32 | X9: 22 | Y9: 15 | Z9: =SUM(X9:Y9) -> 37 | AA9: 21 | AB9: 14 | AC9: =SUM(AA9:AB9) -> 35 | AD9: 25 | AE9: 16 | AF9: =SUM(AD9:AE9) -> 41 | AG9: 24 | AH9: 17 | AI9: =SUM(AG9:AH9) -> 41 | AJ9: =IF(LEFT(B9,1)="7",0,INDEX(INDIRECT(_xlfn.TEXTJOIN("",TRUE,"SEM_",AN9,"!",ADDRESS(6,5+AP9*3+1),":",ADDRESS(5+AO9,5+AP9*3+1))),MATCH(B9,INDIRECT(_xlfn.TEXTJOIN("",TRUE,"SEM_",AN9,"!",ADDRESS(6,2),":",ADDRESS(5+AO9,2))),0)))+INDIRECT(_xlfn.TEXTJOIN("",TRUE,"TC_",AQ9,"!",ADDRESS(4+A9*(AR9+9),13))) -> #N/A | AK9: =IF(LEFT(B9,1)="7",0,INDEX(INDIRECT(_xlfn.TEXTJOIN("",TRUE,"SEM_",AN9,"!",ADDRESS(6,5+AP9*3+2),":",ADDRESS(5+AO9,5+AP9*3+2))),MATCH(B9,INDIRECT(_xlfn.TEXTJOIN("",TRUE,"SEM_",AN9,"!",ADDRESS(6,2),":",ADDRESS(5+AO9,2))),0)))+INDIRECT(_xlfn.TEXTJOIN("",TRUE,"TC_",AQ9,"!",ADDRESS(5+A9*(AR9+9),12))) -> #N/A | AL9: =IF(INDIRECT(_xlfn.TEXTJOIN("",TRUE,"TC_",AQ9,"!",ADDRESS(4+A9*(AR9+9),23))),SUM(INDIRECT(_xlfn.TEXTJOIN("",TRUE,"TC_",AQ9,"!",ADDRESS(4+A9*(AR9+9)-AR9,23),":",ADDRESS(3+A9*(AR9+9),23)))),0) -> #N/A | AM9: =IF(LEFT(B9,1)="7",AJ9/$AK$4,AJ9/$AK$3) -> #N/A | AN9: =AN8 -> I | AO9: =AO8 -> 25 | AP9: =AP8 -> 14 | AQ9: =AQ8 -> II | AR9: =AR8 -> 10
A10: 5 | B10: 240090600005 | C10: UTU/2406100178 | D10: ANJALI PATWAL | E10: SANJAY SINGH PATWAL | F10: 75 | G10: 48 | H10: =SUM(F10:G10) -> 123 | I10: 84 | J10: 45 | K10: =SUM(I10:J10) -> 129 | L10: 49 | M10: 43 | N10: =SUM(L10:M10) -> 92 | O10: 70 | P10: 42 | Q10: =SUM(O10:P10) -> 112 | R10: 90 | S10: 47 | T10: =SUM(R10:S10) -> 137 | V10: 41 | W10: =SUM(V10) -> 41 | X10: 25 | Y10: 18 | Z10: =SUM(X10:Y10) -> 43 | AA10: 24 | AB10: 17 | AC10: =SUM(AA10:AB10) -> 41 | AD10: 21 | AE10: 17 | AF10: =SUM(AD10:AE10) -> 38 | AG10: 27 | AH10: 19 | AI10: =SUM(AG10:AH10) -> 46 | AJ10: =IF(LEFT(B10,1)="7",0,INDEX(INDIRECT(_xlfn.TEXTJOIN("",TRUE,"SEM_",AN10,"!",ADDRESS(6,5+AP10*3+1),":",ADDRESS(5+AO10,5+AP10*3+1))),MATCH(B10,INDIRECT(_xlfn.TEXTJOIN("",TRUE,"SEM_",AN10,"!",ADDRESS(6,2),":",ADDRESS(5+AO10,2))),0)))+INDIRECT(_xlfn.TEXTJOIN("",TRUE,"TC_",AQ10,"!",ADDRESS(4+A10*(AR10+9),13))) -> #N/A | AK10: =IF(LEFT(B10,1)="7",0,INDEX(INDIRECT(_xlfn.TEXTJOIN("",TRUE,"SEM_",AN10,"!",ADDRESS(6,5+AP10*3+2),":",ADDRESS(5+AO10,5+AP10*3+2))),MATCH(B10,INDIRECT(_xlfn.TEXTJOIN("",TRUE,"SEM_",AN10,"!",ADDRESS(6,2),":",ADDRESS(5+AO10,2))),0)))+INDIRECT(_xlfn.TEXTJOIN("",TRUE,"TC_",AQ10,"!",ADDRESS(5+A10*(AR10+9),12))) -> #N/A | AL10: =IF(INDIRECT(_xlfn.TEXTJOIN("",TRUE,"TC_",AQ10,"!",ADDRESS(4+A10*(AR10+9),23))),SUM(INDIRECT(_xlfn.TEXTJOIN("",TRUE,"TC_",AQ10,"!",ADDRESS(4+A10*(AR10+9)-AR10,23),":",ADDRESS(3+A10*(AR10+9),23)))),0) -> #N/A | AM10: =IF(LEFT(B10,1)="7",AJ10/$AK$4,AJ10/$AK$3) -> #N/A | AN10: =AN9 -> I | AO10: =AO9 -> 25 | AP10: =AP9 -> 14 | AQ10: =AQ9 -> II | AR10: =AR9 -> 10
A11: 6 | B11: 240090600006 | C11: UTU/2406100179 | D11: ASMIT BHATT | E11: JANARDHAN BHATT | F11: 57 | G11: 45 | H11: =SUM(F11:G11) -> 102 | I11: 68 | J11: 43 | K11: =SUM(I11:J11) -> 111 | L11: 64 | M11: 41 | N11: =SUM(L11:M11) -> 105 | O11: 55 | P11: 37 | Q11: =SUM(O11:P11) -> 92 | R11: 70 | S11: 47 | T11: =SUM(R11:S11) -> 117 | V11: 32 | W11: =SUM(V11) -> 32 | X11: 25 | Y11: 18 | Z11: =SUM(X11:Y11) -> 43 | AA11: 19 | AB11: 16 | AC11: =SUM(AA11:AB11) -> 35 | AD11: 19 | AE11: 16 | AF11: =SUM(AD11:AE11) -> 35 | AG11: 26 | AH11: 18 | AI11: =SUM(AG11:AH11) -> 44 | AJ11: =IF(LEFT(B11,1)="7",0,INDEX(INDIRECT(_xlfn.TEXTJOIN("",TRUE,"SEM_",AN11,"!",ADDRESS(6,5+AP11*3+1),":",ADDRESS(5+AO11,5+AP11*3+1))),MATCH(B11,INDIRECT(_xlfn.TEXTJOIN("",TRUE,"SEM_",AN11,"!",ADDRESS(6,2),":",ADDRESS(5+AO11,2))),0)))+INDIRECT(_xlfn.TEXTJOIN("",TRUE,"TC_",AQ11,"!",ADDRESS(4+A11*(AR11+9),13))) -> #N/A | AK11: =IF(LEFT(B11,1)="7",0,INDEX(INDIRECT(_xlfn.TEXTJOIN("",TRUE,"SEM_",AN11,"!",ADDRESS(6,5+AP11*3+2),":",ADDRESS(5+AO11,5+AP11*3+2))),MATCH(B11,INDIRECT(_xlfn.TEXTJOIN("",TRUE,"SEM_",AN11,"!",ADDRESS(6,2),":",ADDRESS(5+AO11,2))),0)))+INDIRECT(_xlfn.TEXTJOIN("",TRUE,"TC_",AQ11,"!",ADDRESS(5+A11*(AR11+9),12))) -> #N/A | AL11: =IF(INDIRECT(_xlfn.TEXTJOIN("",TRUE,"TC_",AQ11,"!",ADDRESS(4+A11*(AR11+9),23))),SUM(INDIRECT(_xlfn.TEXTJOIN("",TRUE,"TC_",AQ11,"!",ADDRESS(4+A11*(AR11+9)-AR11,23),":",ADDRESS(3+A11*(AR11+9),23)))),0) -> #N/A | AM11: =IF(LEFT(B11,1)="7",AJ11/$AK$4,AJ11/$AK$3) -> #N/A | AN11: =AN10 -> I | AO11: =AO10 -> 25 | AP11: =AP10 -> 14 | AQ11: =AQ10 -> II | AR11: =AR10 -> 10
A12: 7 | B12: 240090600007 | C12: UTU/2406100174 | D12: AYUSH MAURYA | E12: BABU RAM | F12: 70 | G12: 46 | H12: =SUM(F12:G12) -> 116 | I12: 74 | J12: 47 | K12: =SUM(I12:J12) -> 121 | L12: 49 | M12: 44 | N12: =SUM(L12:M12) -> 93 | O12: 45 | P12: 43 | Q12: =SUM(O12:P12) -> 88 | R12: 94 | S12: 49 | T12: =SUM(R12:S12) -> 143 | V12: 33 | W12: =SUM(V12) -> 33 | X12: 26 | Y12: 19 | Z12: =SUM(X12:Y12) -> 45 | AA12: 22 | AB12: 18 | AC12: =SUM(AA12:AB12) -> 40 | AD12: 25 | AE12: 17 | AF12: =SUM(AD12:AE12) -> 42 | AG12: 28 | AH12: 19 | AI12: =SUM(AG12:AH12) -> 47 | AJ12: =IF(LEFT(B12,1)="7",0,INDEX(INDIRECT(_xlfn.TEXTJOIN("",TRUE,"SEM_",AN12,"!",ADDRESS(6,5+AP12*3+1),":",ADDRESS(5+AO12,5+AP12*3+1))),MATCH(B12,INDIRECT(_xlfn.TEXTJOIN("",TRUE,"SEM_",AN12,"!",ADDRESS(6,2),":",ADDRESS(5+AO12,2))),0)))+INDIRECT(_xlfn.TEXTJOIN("",TRUE,"TC_",AQ12,"!",ADDRESS(4+A12*(AR12+9),13))) -> #N/A | AK12: =IF(LEFT(B12,1)="7",0,INDEX(INDIRECT(_xlfn.TEXTJOIN("",TRUE,"SEM_",AN12,"!",ADDRESS(6,5+AP12*3+2),":",ADDRESS(5+AO12,5+AP12*3+2))),MATCH(B12,INDIRECT(_xlfn.TEXTJOIN("",TRUE,"SEM_",AN12,"!",ADDRESS(6,2),":",ADDRESS(5+AO12,2))),0)))+INDIRECT(_xlfn.TEXTJOIN("",TRUE,"TC_",AQ12,"!",ADDRESS(5+A12*(AR12+9),12))) -> #N/A | AL12: =IF(INDIRECT(_xlfn.TEXTJOIN("",TRUE,"TC_",AQ12,"!",ADDRESS(4+A12*(AR12+9),23))),SUM(INDIRECT(_xlfn.TEXTJOIN("",TRUE,"TC_",AQ12,"!",ADDRESS(4+A12*(AR12+9)-AR12,23),":",ADDRESS(3+A12*(AR12+9),23)))),0) -> #N/A | AM12: =IF(LEFT(B12,1)="7",AJ12/$AK$4,AJ12/$AK$3) -> #N/A | AN12: =AN11 -> I | AO12: =AO11 -> 25 | AP12: =AP11 -> 14 | AQ12: =AQ11 -> II | AR12: =AR11 -> 10
A13: 8 | B13: 240090600008 | C13: UTU/2406100183 | D13: AYUSH RAWAT | E13: MUKESH RAWAT | F13: 69 | G13: 45 | H13: =SUM(F13:G13) -> 114 | I13: 79 | J13: 47 | K13: =SUM(I13:J13) -> 126 | L13: 82 | M13: 43 | N13: =SUM(L13:M13) -> 125 | O13: 38 | P13: 40 | Q13: =SUM(O13:P13) -> 78 | R13: 87 | S13: 48 | T13: =SUM(R13:S13) -> 135 | V13: 29 | W13: =SUM(V13) -> 29 | X13: 27 | Y13: 19 | Z13: =SUM(X13:Y13) -> 46 | AA13: 24 | AB13: 17 | AC13: =SUM(AA13:AB13) -> 41 | AD13: 23 | AE13: 16 | AF13: =SUM(AD13:AE13) -> 39 | AG13: 28 | AH13: 19 | AI13: =SUM(AG13:AH13) -> 47 | AJ13: =IF(LEFT(B13,1)="7",0,INDEX(INDIRECT(_xlfn.TEXTJOIN("",TRUE,"SEM_",AN13,"!",ADDRESS(6,5+AP13*3+1),":",ADDRESS(5+AO13,5+AP13*3+1))),MATCH(B13,INDIRECT(_xlfn.TEXTJOIN("",TRUE,"SEM_",AN13,"!",ADDRESS(6,2),":",ADDRESS(5+AO13,2))),0)))+INDIRECT(_xlfn.TEXTJOIN("",TRUE,"TC_",AQ13,"!",ADDRESS(4+A13*(AR13+9),13))) -> #N/A | AK13: =IF(LEFT(B13,1)="7",0,INDEX(INDIRECT(_xlfn.TEXTJOIN("",TRUE,"SEM_",AN13,"!",ADDRESS(6,5+AP13*3+2),":",ADDRESS(5+AO13,5+AP13*3+2))),MATCH(B13,INDIRECT(_xlfn.TEXTJOIN("",TRUE,"SEM_",AN13,"!",ADDRESS(6,2),":",ADDRESS(5+AO13,2))),0)))+INDIRECT(_xlfn.TEXTJOIN("",TRUE,"TC_",AQ13,"!",ADDRESS(5+A13*(AR13+9),12))) -> #N/A | AL13: =IF(INDIRECT(_xlfn.TEXTJOIN("",TRUE,"TC_",AQ13,"!",ADDRESS(4+A13*(AR13+9),23))),SUM(INDIRECT(_xlfn.TEXTJOIN("",TRUE,"TC_",AQ13,"!",ADDRESS(4+A13*(AR13+9)-AR13,23),":",ADDRESS(3+A13*(AR13+9),23)))),0) -> #N/A | AM13: =IF(LEFT(B13,1)="7",AJ13/$AK$4,AJ13/$AK$3) -> #N/A | AN13: =AN12 -> I | AO13: =AO12 -> 25 | AP13: =AP12 -> 14 | AQ13: =AQ12 -> II | AR13: =AR12 -> 10
A14: 9 | B14: 240090600009 | C14: UTU/2406100172 | D14: CHIRAG KASHYAP | E14: NARENDRA SINGH | F14: 81 | G14: 47 | H14: =SUM(F14:G14) -> 128 | I14: 79 | J14: 44 | K14: =SUM(I14:J14) -> 123 | L14: 73 | M14: 50 | N14: =SUM(L14:M14) -> 123 | O14: 58 | P14: 42 | Q14: =SUM(O14:P14) -> 100 | R14: 77 | S14: 45 | T14: =SUM(R14:S14) -> 122 | V14: 34 | W14: =SUM(V14) -> 34 | X14: 27 | Y14: 18 | Z14: =SUM(X14:Y14) -> 45 | AA14: 24 | AB14: 20 | AC14: =SUM(AA14:AB14) -> 44 | AD14: 23 | AE14: 18 | AF14: =SUM(AD14:AE14) -> 41 | AG14: 28 | AH14: 18 | AI14: =SUM(AG14:AH14) -> 46 | AJ14: =IF(LEFT(B14,1)="7",0,INDEX(INDIRECT(_xlfn.TEXTJOIN("",TRUE,"SEM_",AN14,"!",ADDRESS(6,5+AP14*3+1),":",ADDRESS(5+AO14,5+AP14*3+1))),MATCH(B14,INDIRECT(_xlfn.TEXTJOIN("",TRUE,"SEM_",AN14,"!",ADDRESS(6,2),":",ADDRESS(5+AO14,2))),0)))+INDIRECT(_xlfn.TEXTJOIN("",TRUE,"TC_",AQ14,"!",ADDRESS(4+A14*(AR14+9),13))) -> #N/A | AK14: =IF(LEFT(B14,1)="7",0,INDEX(INDIRECT(_xlfn.TEXTJOIN("",TRUE,"SEM_",AN14,"!",ADDRESS(6,5+AP14*3+2),":",ADDRESS(5+AO14,5+AP14*3+2))),MATCH(B14,INDIRECT(_xlfn.TEXTJOIN("",TRUE,"SEM_",AN14,"!",ADDRESS(6,2),":",ADDRESS(5+AO14,2))),0)))+INDIRECT(_xlfn.TEXTJOIN("",TRUE,"TC_",AQ14,"!",ADDRESS(5+A14*(AR14+9),12))) -> #N/A | AL14: =IF(INDIRECT(_xlfn.TEXTJOIN("",TRUE,"TC_",AQ14,"!",ADDRESS(4+A14*(AR14+9),23))),SUM(INDIRECT(_xlfn.TEXTJOIN("",TRUE,"TC_",AQ14,"!",ADDRESS(4+A14*(AR14+9)-AR14,23),":",ADDRESS(3+A14*(AR14+9),23)))),0) -> #N/A | AM14: =IF(LEFT(B14,1)="7",AJ14/$AK$4,AJ14/$AK$3) -> #N/A | AN14: =AN13 -> I | AO14: =AO13 -> 25 | AP14: =AP13 -> 14 | AQ14: =AQ13 -> II | AR14: =AR13 -> 10
A15: 10 | B15: 240090600010 | C15: UTU/2406100181 | D15: DEVENDRA SINGH RANA | E15: DHYAN SINGH RANA | F15: 36 | G15: 40 | H15: =SUM(F15:G15) -> 76 | I15: 50 | J15: 43 | K15: =SUM(I15:J15) -> 93 | L15: 60 | M15: 35 | N15: =SUM(L15:M15) -> 95 | O15: 32 | P15: 34 | Q15: =SUM(O15:P15) -> 66 | R15: 55 | S15: 41 | T15: =SUM(R15:S15) -> 96 | V15: 24 | W15: =SUM(V15) -> 24 | X15: 25 | Y15: 18 | Z15: =SUM(X15:Y15) -> 43 | AA15: 21 | AB15: 14 | AC15: =SUM(AA15:AB15) -> 35 | AD15: 21 | AE15: 17 | AF15: =SUM(AD15:AE15) -> 38 | AG15: 25 | AH15: 17 | AI15: =SUM(AG15:AH15) -> 42 | AJ15: =IF(LEFT(B15,1)="7",0,INDEX(INDIRECT(_xlfn.TEXTJOIN("",TRUE,"SEM_",AN15,"!",ADDRESS(6,5+AP15*3+1),":",ADDRESS(5+AO15,5+AP15*3+1))),MATCH(B15,INDIRECT(_xlfn.TEXTJOIN("",TRUE,"SEM_",AN15,"!",ADDRESS(6,2),":",ADDRESS(5+AO15,2))),0)))+INDIRECT(_xlfn.TEXTJOIN("",TRUE,"TC_",AQ15,"!",ADDRESS(4+A15*(AR15+9),13))) -> #N/A | AK15: =IF(LEFT(B15,1)="7",0,INDEX(INDIRECT(_xlfn.TEXTJOIN("",TRUE,"SEM_",AN15,"!",ADDRESS(6,5+AP15*3+2),":",ADDRESS(5+AO15,5+AP15*3+2))),MATCH(B15,INDIRECT(_xlfn.TEXTJOIN("",TRUE,"SEM_",AN15,"!",ADDRESS(6,2),":",ADDRESS(5+AO15,2))),0)))+INDIRECT(_xlfn.TEXTJOIN("",TRUE,"TC_",AQ15,"!",ADDRESS(5+A15*(AR15+9),12))) -> #N/A | AL15: =IF(INDIRECT(_xlfn.TEXTJOIN("",TRUE,"TC_",AQ15,"!",ADDRESS(4+A15*(AR15+9),23))),SUM(INDIRECT(_xlfn.TEXTJOIN("",TRUE,"TC_",AQ15,"!",ADDRESS(4+A15*(AR15+9)-AR15,23),":",ADDRESS(3+A15*(AR15+9),23)))),0) -> #N/A | AM15: =IF(LEFT(B15,1)="7",AJ15/$AK$4,AJ15/$AK$3) -> #N/A | AN15: =AN14 -> I | AO15: =AO14 -> 25 | AP15: =AP14 -> 14 | AQ15: =AQ14 -> II | AR15: =AR14 -> 10
A16: 11 | B16: 240090600011 | C16: UTU/2406100185 | D16: DIKSHA PHARTYAL | E16: UPENDRA SINGH PHARTYAL | F16: 76 | G16: 47 | H16: =SUM(F16:G16) -> 123 | I16: 85 | J16: 47 | K16: =SUM(I16:J16) -> 132 | L16: 54 | M16: 46 | N16: =SUM(L16:M16) -> 100 | O16: 49 | P16: 41 | Q16: =SUM(O16:P16) -> 90 | R16: 73 | S16: 46 | T16: =SUM(R16:S16) -> 119 | V16: 35 | W16: =SUM(V16) -> 35 | X16: 27 | Y16: 19 | Z16: =SUM(X16:Y16) -> 46 | AA16: 21 | AB16: 18 | AC16: =SUM(AA16:AB16) -> 39 | AD16: 25 | AE16: 16 | AF16: =SUM(AD16:AE16) -> 41 | AG16: 28 | AH16: 19 | AI16: =SUM(AG16:AH16) -> 47 | AJ16: =IF(LEFT(B16,1)="7",0,INDEX(INDIRECT(_xlfn.TEXTJOIN("",TRUE,"SEM_",AN16,"!",ADDRESS(6,5+AP16*3+1),":",ADDRESS(5+AO16,5+AP16*3+1))),MATCH(B16,INDIRECT(_xlfn.TEXTJOIN("",TRUE,"SEM_",AN16,"!",ADDRESS(6,2),":",ADDRESS(5+AO16,2))),0)))+INDIRECT(_xlfn.TEXTJOIN("",TRUE,"TC_",AQ16,"!",ADDRESS(4+A16*(AR16+9),13))) -> #N/A | AK16: =IF(LEFT(B16,1)="7",0,INDEX(INDIRECT(_xlfn.TEXTJOIN("",TRUE,"SEM_",AN16,"!",ADDRESS(6,5+AP16*3+2),":",ADDRESS(5+AO16,5+AP16*3+2))),MATCH(B16,INDIRECT(_xlfn.TEXTJOIN("",TRUE,"SEM_",AN16,"!",ADDRESS(6,2),":",ADDRESS(5+AO16,2))),0)))+INDIRECT(_xlfn.TEXTJOIN("",TRUE,"TC_",AQ16,"!",ADDRESS(5+A16*(AR16+9),12))) -> #N/A | AL16: =IF(INDIRECT(_xlfn.TEXTJOIN("",TRUE,"TC_",AQ16,"!",ADDRESS(4+A16*(AR16+9),23))),SUM(INDIRECT(_xlfn.TEXTJOIN("",TRUE,"TC_",AQ16,"!",ADDRESS(4+A16*(AR16+9)-AR16,23),":",ADDRESS(3+A16*(AR16+9),23)))),0) -> #N/A | AM16: =IF(LEFT(B16,1)="7",AJ16/$AK$4,AJ16/$AK$3) -> #N/A | AN16: =AN15 -> I | AO16: =AO15 -> 25 | AP16: =AP15 -> 14 | AQ16: =AQ15 -> II | AR16: =AR15 -> 10
A17: 12 | B17: 240090600012 | C17: UTU/2406100182 | D17: KAMAL SINGH BISHT | E17: SHIV SINGH BISHT | F17: 46 | G17: 44 | H17: =SUM(F17:G17) -> 90 | I17: 51 | J17: 35 | K17: =SUM(I17:J17) -> 86 | L17: 32 | M17: 34 | N17: =SUM(L17:M17) -> 66 | O17: 15 | P17: 38 | Q17: =SUM(O17:P17) -> 53 | R17: 26 | S17: 41 | T17: =SUM(R17:S17) -> 67 | V17: 25 | W17: =SUM(V17) -> 25 | X17: 25 | Y17: 18 | Z17: =SUM(X17:Y17) -> 43 | AA17: 19 | AB17: 13 | AC17: =SUM(AA17:AB17) -> 32 | AD17: 20 | AE17: 16 | AF17: =SUM(AD17:AE17) -> 36 | AG17: 27 | AH17: 18 | AI17: =SUM(AG17:AH17) -> 45 | AJ17: =IF(LEFT(B17,1)="7",0,INDEX(INDIRECT(_xlfn.TEXTJOIN("",TRUE,"SEM_",AN17,"!",ADDRESS(6,5+AP17*3+1),":",ADDRESS(5+AO17,5+AP17*3+1))),MATCH(B17,INDIRECT(_xlfn.TEXTJOIN("",TRUE,"SEM_",AN17,"!",ADDRESS(6,2),":",ADDRESS(5+AO17,2))),0)))+INDIRECT(_xlfn.TEXTJOIN("",TRUE,"TC_",AQ17,"!",ADDRESS(4+A17*(AR17+9),13))) -> #N/A | AK17: =IF(LEFT(B17,1)="7",0,INDEX(INDIRECT(_xlfn.TEXTJOIN("",TRUE,"SEM_",AN17,"!",ADDRESS(6,5+AP17*3+2),":",ADDRESS(5+AO17,5+AP17*3+2))),MATCH(B17,INDIRECT(_xlfn.TEXTJOIN("",TRUE,"SEM_",AN17,"!",ADDRESS(6,2),":",ADDRESS(5+AO17,2))),0)))+INDIRECT(_xlfn.TEXTJOIN("",TRUE,"TC_",AQ17,"!",ADDRESS(5+A17*(AR17+9),12))) -> #N/A | AL17: =IF(INDIRECT(_xlfn.TEXTJOIN("",TRUE,"TC_",AQ17,"!",ADDRESS(4+A17*(AR17+9),23))),SUM(INDIRECT(_xlfn.TEXTJOIN("",TRUE,"TC_",AQ17,"!",ADDRESS(4+A17*(AR17+9)-AR17,23),":",ADDRESS(3+A17*(AR17+9),23)))),0) -> #N/A | AM17: =IF(LEFT(B17,1)="7",AJ17/$AK$4,AJ17/$AK$3) -> #N/A | AN17: =AN16 -> I | AO17: =AO16 -> 25 | AP17: =AP16 -> 14 | AQ17: =AQ16 -> II | AR17: =AR16 -> 10
A18: 13 | B18: 240090600013 | C18: UTU/2406100175 | D18: KRISHNA BHATT | E18: HARENDRA PRASAD BHATT | F18: 42 | G18: 46 | H18: =SUM(F18:G18) -> 88 | I18: 63 | J18: 39 | K18: =SUM(I18:J18) -> 102 | L18: 47 | M18: 39 | N18: =SUM(L18:M18) -> 86 | O18: 45 | P18: 40 | Q18: =SUM(O18:P18) -> 85 | R18: 41 | S18: 44 | T18: =SUM(R18:S18) -> 85 | V18: 28 | W18: =SUM(V18) -> 28 | X18: 26 | Y18: 19 | Z18: =SUM(X18:Y18) -> 45 | AA18: 22 | AB18: 15 | AC18: =SUM(AA18:AB18) -> 37 | AD18: 25 | AE18: 16 | AF18: =SUM(AD18:AE18) -> 41 | AG18: 27 | AH18: 18 | AI18: =SUM(AG18:AH18) -> 45 | AJ18: =IF(LEFT(B18,1)="7",0,INDEX(INDIRECT(_xlfn.TEXTJOIN("",TRUE,"SEM_",AN18,"!",ADDRESS(6,5+AP18*3+1),":",ADDRESS(5+AO18,5+AP18*3+1))),MATCH(B18,INDIRECT(_xlfn.TEXTJOIN("",TRUE,"SEM_",AN18,"!",ADDRESS(6,2),":",ADDRESS(5+AO18,2))),0)))+INDIRECT(_xlfn.TEXTJOIN("",TRUE,"TC_",AQ18,"!",ADDRESS(4+A18*(AR18+9),13))) -> #N/A | AK18: =IF(LEFT(B18,1)="7",0,INDEX(INDIRECT(_xlfn.TEXTJOIN("",TRUE,"SEM_",AN18,"!",ADDRESS(6,5+AP18*3+2),":",ADDRESS(5+AO18,5+AP18*3+2))),MATCH(B18,INDIRECT(_xlfn.TEXTJOIN("",TRUE,"SEM_",AN18,"!",ADDRESS(6,2),":",ADDRESS(5+AO18,2))),0)))+INDIRECT(_xlfn.TEXTJOIN("",TRUE,"TC_",AQ18,"!",ADDRESS(5+A18*(AR18+9),12))) -> #N/A | AL18: =IF(INDIRECT(_xlfn.TEXTJOIN("",TRUE,"TC_",AQ18,"!",ADDRESS(4+A18*(AR18+9),23))),SUM(INDIRECT(_xlfn.TEXTJOIN("",TRUE,"TC_",AQ18,"!",ADDRESS(4+A18*(AR18+9)-AR18,23),":",ADDRESS(3+A18*(AR18+9),23)))),0) -> #N/A | AM18: =IF(LEFT(B18,1)="7",AJ18/$AK$4,AJ18/$AK$3) -> #N/A | AN18: =AN17 -> I | AO18: =AO17 -> 25 | AP18: =AP17 -> 14 | AQ18: =AQ17 -> II | AR18: =AR17 -> 10
... A30: 25 | B30: 240090600025 | C30: UTU/2406100189 | D30: SURAJ SINGH BISHT | E30: KHUSHAL SINGH | F30: 47 | G30: 41 | H30: =SUM(F30:G30) -> 88 | I30: 45 | J30: 38 | K30: =SUM(I30:J30) -> 83 | L30: 49 | M30: 36 | N30: =SUM(L30:M30) -> 85 | O30: 22 | P30: 31 | Q30: =SUM(O30:P30) -> 53 | R30: 51 | S30: 33 | T30: =SUM(R30:S30) -> 84 | V30: 25 | W30: =SUM(V30) -> 25 | X30: 23 | Y30: 17 | Z30: =SUM(X30:Y30) -> 40 | AA30: 23 | AB30: 14 | AC30: =SUM(AA30:AB30) -> 37 | AD30: 21 | AE30: 16 | AF30: =SUM(AD30:AE30) -> 37 | AG30: 24 | AH30: 16 | AI30: =SUM(AG30:AH30) -> 40 | AJ30: =IF(LEFT(B30,1)="7",0,INDEX(INDIRECT(_xlfn.TEXTJOIN("",TRUE,"SEM_",AN30,"!",ADDRESS(6,5+AP30*3+1),":",ADDRESS(5+AO30,5+AP30*3+1))),MATCH(B30,INDIRECT(_xlfn.TEXTJOIN("",TRUE,"SEM_",AN30,"!",ADDRESS(6,2),":",ADDRESS(5+AO30,2))),0)))+INDIRECT(_xlfn.TEXTJOIN("",TRUE,"TC_",AQ30,"!",ADDRESS(4+A30*(AR30+9),13))) -> #N/A | AK30: =IF(LEFT(B30,1)="7",0,INDEX(INDIRECT(_xlfn.TEXTJOIN("",TRUE,"SEM_",AN30,"!",ADDRESS(6,5+AP30*3+2),":",ADDRESS(5+AO30,5+AP30*3+2))),MATCH(B30,INDIRECT(_xlfn.TEXTJOIN("",TRUE,"SEM_",AN30,"!",ADDRESS(6,2),":",ADDRESS(5+AO30,2))),0)))+INDIRECT(_xlfn.TEXTJOIN("",TRUE,"TC_",AQ30,"!",ADDRESS(5+A30*(AR30+9),12))) -> #N/A | AL30: =IF(INDIRECT(_xlfn.TEXTJOIN("",TRUE,"TC_",AQ30,"!",ADDRESS(4+A30*(AR30+9),23))),SUM(INDIRECT(_xlfn.TEXTJOIN("",TRUE,"TC_",AQ30,"!",ADDRESS(4+A30*(AR30+9)-AR30,23),":",ADDRESS(3+A30*(AR30+9),23)))),0) -> #N/A | AM30: =IF(LEFT(B30,1)="7",AJ30/$AK$4,AJ30/$AK$3) -> #N/A | AN30: =AN29 -> I | AO30: =AO29 -> 25 | AP30: =AP29 -> 14 | AQ30: =AQ29 -> II | AR30: =AR29 -> 10

Sheet SEM_III
A1: SC | B1: Roll No. | C1: Enroll No. | D1: Student's Name | E1: Father's Name | F1: CAT 014 | I1: CAT 015 | L1: CAT 016 | O1: CAT 020 | R1: AHT 313 | U1: TOE 83 | X1: AHT 310 | AA1: CAP 008 | AD1: CAP 009 | AG1: CAP 010 | AJ1: TGP | AK1: EC | AL1: Grace | AM1: CGPA
A2: SN | F2: Graph Theory | I2: Software Engineering | L2: Big Data Analytics | O2: Cloud Computing | R2: Principal of Management | U2: Project Management | X2: Universal Human Value | AA2: Software Engineering Lab | AD2: Seminar | AG2: Minor Project
A3: C | F3: 4 | I3: 4 | L3: 4 | O3: 4 | R3: 4 | U3: 4 | X3: 3 | AA3: 1 | AD3: 2 | AG3: 2 | AK3: =INDIRECT(_xlfn.TEXTJOIN("",TRUE,"SEM_",AN6,"!",ADDRESS(3,5+AP6*3+2)))+SUM(F3:AI3)-4-4 -> 72
F4: Th. Ex. | G4: Ses. | H4: Total | I4: Th. Ex. | J4: Ses. | K4: Total | L4: Th. Ex. | M4: Ses. | N4: Total | O4: Th. Ex. | P4: Ses. | Q4: Total | R4: Th. Ex. | S4: Ses. | T4: Total | U4: Pr. Ex. | V4: Ses. | W4: Total | X4: Pr. Ex. | Y4: Ses. | Z4: Total | AA4: Pr. Ex. | AB4: Ses. | AC4: Total | AD4: Pr. Ex. | AE4: Ses. | AF4: Total | AG4: Pr. Ex. | AH4: Ses. | AI4: Total | AK4: =SUM(F3:AI3)-4-4 -> 24
A5: MM | F5: 100 | G5: 50 | H5: 150 | I5: 100 | J5: 50 | K5: 150 | L5: 100 | M5: 50 | N5: 150 | O5: 100 | P5: 50 | Q5: 150 | R5: 100 | S5: 50 | T5: 150 | U5: 100 | V5: 50 | W5: 150 | X5: 100 | Y5: 50 | Z5: 150 | AA5: 30 | AB5: 20 | AC5: 50 | AD5: 0 | AE5: 100 | AF5: 100 | AG5: 50 | AH5: 50 | AI5: 100
A6: 1 | B6: 240090600001 | C6: UTU/2406100187 | D6: ALOK NEGI | E6: PRATAP SINGH NEGI | AJ6: =IF(LEFT(B6,1)="7",0,INDEX(INDIRECT(_xlfn.TEXTJOIN("",TRUE,"SEM_",AN6,"!",ADDRESS(6,5+AP6*3+1),":",ADDRESS(5+AO6,5+AP6*3+1))),MATCH(B6,INDIRECT(_xlfn.TEXTJOIN("",TRUE,"SEM_",AN6,"!",ADDRESS(6,2),":",ADDRESS(5+AO6,2))),0)))+INDIRECT(_xlfn.TEXTJOIN("",TRUE,"TC_",AQ6,"!",ADDRESS(4+A6*(AR6+9),13))) -> #N/A | AK6: =IF(LEFT(B6,1)="7",0,INDEX(INDIRECT(_xlfn.TEXTJOIN("",TRUE,"SEM_",AN6,"!",ADDRESS(6,5+AP6*3+2),":",ADDRESS(5+AO6,5+AP6*3+2))),MATCH(B6,INDIRECT(_xlfn.TEXTJOIN("",TRUE,"SEM_",AN6,"!",ADDRESS(6,2),":",ADDRESS(5+AO6,2))),0)))+INDIRECT(_xlfn.TEXTJOIN("",TRUE,"TC_",AQ6,"!",ADDRESS(5+A6*(AR6+9),12))) -> #N/A | AL6: =IF(INDIRECT(_xlfn.TEXTJOIN("",TRUE,"TC_",AQ6,"!",ADDRESS(4+A6*(AR6+9),23))),SUM(INDIRECT(_xlfn.TEXTJOIN("",TRUE,"TC_",AQ6,"!",ADDRESS(4+A6*(AR6+9)-AR6,23),":",ADDRESS(3+A6*(AR6+9),23)))),0) -> 0 | AM6: =IF(LEFT(B6,1)="7",AJ6/$AK$4,AJ6/$AK$3) -> #N/A | AN6: II | AO6: 25 | AP6: 10 | AQ6: III | AR6: 8
A7: 2 | B7: 240090600002 | C7: UTU/2406100171 | D7: AMAN POKHRIYAL | E7: VINOD PRASSAD POKHRIYAL | AJ7: =IF(LEFT(B7,1)="7",0,INDEX(INDIRECT(_xlfn.TEXTJOIN("",TRUE,"SEM_",AN7,"!",ADDRESS(6,5+AP7*3+1),":",ADDRESS(5+AO7,5+AP7*3+1))),MATCH(B7,INDIRECT(_xlfn.TEXTJOIN("",TRUE,"SEM_",AN7,"!",ADDRESS(6,2),":",ADDRESS(5+AO7,2))),0)))+INDIRECT(_xlfn.TEXTJOIN("",TRUE,"TC_",AQ7,"!",ADDRESS(4+A7*(AR7+9),13))) -> #N/A | AK7: =IF(LEFT(B7,1)="7",0,INDEX(INDIRECT(_xlfn.TEXTJOIN("",TRUE,"SEM_",AN7,"!",ADDRESS(6,5+AP7*3+2),":",ADDRESS(5+AO7,5+AP7*3+2))),MATCH(B7,INDIRECT(_xlfn.TEXTJOIN("",TRUE,"SEM_",AN7,"!",ADDRESS(6,2),":",ADDRESS(5+AO7,2))),0)))+INDIRECT(_xlfn.TEXTJOIN("",TRUE,"TC_",AQ7,"!",ADDRESS(5+A7*(AR7+9),12))) -> #N/A | AL7: =IF(INDIRECT(_xlfn.TEXTJOIN("",TRUE,"TC_",AQ7,"!",ADDRESS(4+A7*(AR7+9),23))),SUM(INDIRECT(_xlfn.TEXTJOIN("",TRUE,"TC_",AQ7,"!",ADDRESS(4+A7*(AR7+9)-AR7,23),":",ADDRESS(3+A7*(AR7+9),23)))),0) -> 0 | AM7: =IF(LEFT(B7,1)="7",AJ7/$AK$4,AJ7/$AK$3) -> #N/A | AN7: =AN6 -> II | AO7: =AO6 -> 25 | AP7: =AP6 -> 10 | AQ7: =AQ6 -> III | AR7: =AR6 -> 8
A8: 3 | B8: 240090600003 | C8: UTU/2406100173 | D8: ANAS SAIFI | E8: SALMUDDIN SAIFI | AJ8: =IF(LEFT(B8,1)="7",0,INDEX(INDIRECT(_xlfn.TEXTJOIN("",TRUE,"SEM_",AN8,"!",ADDRESS(6,5+AP8*3+1),":",ADDRESS(5+AO8,5+AP8*3+1))),MATCH(B8,INDIRECT(_xlfn.TEXTJOIN("",TRUE,"SEM_",AN8,"!",ADDRESS(6,2),":",ADDRESS(5+AO8,2))),0)))+INDIRECT(_xlfn.TEXTJOIN("",TRUE,"TC_",AQ8,"!",ADDRESS(4+A8*(AR8+9),13))) -> #N/A | AK8: =IF(LEFT(B8,1)="7",0,INDEX(INDIRECT(_xlfn.TEXTJOIN("",TRUE,"SEM_",AN8,"!",ADDRESS(6,5+AP8*3+2),":",ADDRESS(5+AO8,5+AP8*3+2))),MATCH(B8,INDIRECT(_xlfn.TEXTJOIN("",TRUE,"SEM_",AN8,"!",ADDRESS(6,2),":",ADDRESS(5+AO8,2))),0)))+INDIRECT(_xlfn.TEXTJOIN("",TRUE,"TC_",AQ8,"!",ADDRESS(5+A8*(AR8+9),12))) -> #N/A | AL8: =IF(INDIRECT(_xlfn.TEXTJOIN("",TRUE,"TC_",AQ8,"!",ADDRESS(4+A8*(AR8+9),23))),SUM(INDIRECT(_xlfn.TEXTJOIN("",TRUE,"TC_",AQ8,"!",ADDRESS(4+A8*(AR8+9)-AR8,23),":",ADDRESS(3+A8*(AR8+9),23)))),0) -> 0 | AM8: =IF(LEFT(B8,1)="7",AJ8/$AK$4,AJ8/$AK$3) -> #N/A | AN8: =AN7 -> II | AO8: =AO7 -> 25 | AP8: =AP7 -> 10 | AQ8: =AQ7 -> III | AR8: =AR7 -> 8
A9: 4 | B9: 240090600004 | C9: UTU/2406100161 | D9: ANJALI GUSAIN | E9: JAIBEER SINGH GUSAIN | AJ9: =IF(LEFT(B9,1)="7",0,INDEX(INDIRECT(_xlfn.TEXTJOIN("",TRUE,"SEM_",AN9,"!",ADDRESS(6,5+AP9*3+1),":",ADDRESS(5+AO9,5+AP9*3+1))),MATCH(B9,INDIRECT(_xlfn.TEXTJOIN("",TRUE,"SEM_",AN9,"!",ADDRESS(6,2),":",ADDRESS(5+AO9,2))),0)))+INDIRECT(_xlfn.TEXTJOIN("",TRUE,"TC_",AQ9,"!",ADDRESS(4+A9*(AR9+9),13))) -> #N/A | AK9: =IF(LEFT(B9,1)="7",0,INDEX(INDIRECT(_xlfn.TEXTJOIN("",TRUE,"SEM_",AN9,"!",ADDRESS(6,5+AP9*3+2),":",ADDRESS(5+AO9,5+AP9*3+2))),MATCH(B9,INDIRECT(_xlfn.TEXTJOIN("",TRUE,"SEM_",AN9,"!",ADDRESS(6,2),":",ADDRESS(5+AO9,2))),0)))+INDIRECT(_xlfn.TEXTJOIN("",TRUE,"TC_",AQ9,"!",ADDRESS(5+A9*(AR9+9),12))) -> #N/A | AL9: =IF(INDIRECT(_xlfn.TEXTJOIN("",TRUE,"TC_",AQ9,"!",ADDRESS(4+A9*(AR9+9),23))),SUM(INDIRECT(_xlfn.TEXTJOIN("",TRUE,"TC_",AQ9,"!",ADDRESS(4+A9*(AR9+9)-AR9,23),":",ADDRESS(3+A9*(AR9+9),23)))),0) -> 0 | AM9: =IF(LEFT(B9,1)="7",AJ9/$AK$4,AJ9/$AK$3) -> #N/A | AN9: =AN8 -> II | AO9: =AO8 -> 25 | AP9: =AP8 -> 10 | AQ9: =AQ8 -> III | AR9: =AR8 -> 8
A10: 5 | B10: 240090600005 | C10: UTU/2406100178 | D10: ANJALI PATWAL | E10: SANJAY SINGH PATWAL | AJ10: =IF(LEFT(B10,1)="7",0,INDEX(INDIRECT(_xlfn.TEXTJOIN("",TRUE,"SEM_",AN10,"!",ADDRESS(6,5+AP10*3+1),":",ADDRESS(5+AO10,5+AP10*3+1))),MATCH(B10,INDIRECT(_xlfn.TEXTJOIN("",TRUE,"SEM_",AN10,"!",ADDRESS(6,2),":",ADDRESS(5+AO10,2))),0)))+INDIRECT(_xlfn.TEXTJOIN("",TRUE,"TC_",AQ10,"!",ADDRESS(4+A10*(AR10+9),13))) -> #N/A | AK10: =IF(LEFT(B10,1)="7",0,INDEX(INDIRECT(_xlfn.TEXTJOIN("",TRUE,"SEM_",AN10,"!",ADDRESS(6,5+AP10*3+2),":",ADDRESS(5+AO10,5+AP10*3+2))),MATCH(B10,INDIRECT(_xlfn.TEXTJOIN("",TRUE,"SEM_",AN10,"!",ADDRESS(6,2),":",ADDRESS(5+AO10,2))),0)))+INDIRECT(_xlfn.TEXTJOIN("",TRUE,"TC_",AQ10,"!",ADDRESS(5+A10*(AR10+9),12))) -> #N/A | AL10: =IF(INDIRECT(_xlfn.TEXTJOIN("",TRUE,"TC_",AQ10,"!",ADDRESS(4+A10*(AR10+9),23))),SUM(INDIRECT(_xlfn.TEXTJOIN("",TRUE,"TC_",AQ10,"!",ADDRESS(4+A10*(AR10+9)-AR10,23),":",ADDRESS(3+A10*(AR10+9),23)))),0) -> 0 | AM10: =IF(LEFT(B10,1)="7",AJ10/$AK$4,AJ10/$AK$3) -> #N/A | AN10: =AN9 -> II | AO10: =AO9 -> 25 | AP10: =AP9 -> 10 | AQ10: =AQ9 -> III | AR10: =AR9 -> 8
A11: 6 | B11: 240090600006 | C11: UTU/2406100179 | D11: ASMIT BHATT | E11: JANARDHAN BHATT | AJ11: =IF(LEFT(B11,1)="7",0,INDEX(INDIRECT(_xlfn.TEXTJOIN("",TRUE,"SEM_",AN11,"!",ADDRESS(6,5+AP11*3+1),":",ADDRESS(5+AO11,5+AP11*3+1))),MATCH(B11,INDIRECT(_xlfn.TEXTJOIN("",TRUE,"SEM_",AN11,"!",ADDRESS(6,2),":",ADDRESS(5+AO11,2))),0)))+INDIRECT(_xlfn.TEXTJOIN("",TRUE,"TC_",AQ11,"!",ADDRESS(4+A11*(AR11+9),13))) -> #N/A | AK11: =IF(LEFT(B11,1)="7",0,INDEX(INDIRECT(_xlfn.TEXTJOIN("",TRUE,"SEM_",AN11,"!",ADDRESS(6,5+AP11*3+2),":",ADDRESS(5+AO11,5+AP11*3+2))),MATCH(B11,INDIRECT(_xlfn.TEXTJOIN("",TRUE,"SEM_",AN11,"!",ADDRESS(6,2),":",ADDRESS(5+AO11,2))),0)))+INDIRECT(_xlfn.TEXTJOIN("",TRUE,"TC_",AQ11,"!",ADDRESS(5+A11*(AR11+9),12))) -> #N/A | AL11: =IF(INDIRECT(_xlfn.TEXTJOIN("",TRUE,"TC_",AQ11,"!",ADDRESS(4+A11*(AR11+9),23))),SUM(INDIRECT(_xlfn.TEXTJOIN("",TRUE,"TC_",AQ11,"!",ADDRESS(4+A11*(AR11+9)-AR11,23),":",ADDRESS(3+A11*(AR11+9),23)))),0) -> 0 | AM11: =IF(LEFT(B11,1)="7",AJ11/$AK$4,AJ11/$AK$3) -> #N/A | AN11: =AN10 -> II | AO11: =AO10 -> 25 | AP11: =AP10 -> 10 | AQ11: =AQ10 -> III | AR11: =AR10 -> 8
A12: 7 | B12: 240090600007 | C12: UTU/2406100174 | D12: AYUSH MAURYA | E12: BABU RAM | AJ12: =IF(LEFT(B12,1)="7",0,INDEX(INDIRECT(_xlfn.TEXTJOIN("",TRUE,"SEM_",AN12,"!",ADDRESS(6,5+AP12*3+1),":",ADDRESS(5+AO12,5+AP12*3+1))),MATCH(B12,INDIRECT(_xlfn.TEXTJOIN("",TRUE,"SEM_",AN12,"!",ADDRESS(6,2),":",ADDRESS(5+AO12,2))),0)))+INDIRECT(_xlfn.TEXTJOIN("",TRUE,"TC_",AQ12,"!",ADDRESS(4+A12*(AR12+9),13))) -> #N/A | AK12: =IF(LEFT(B12,1)="7",0,INDEX(INDIRECT(_xlfn.TEXTJOIN("",TRUE,"SEM_",AN12,"!",ADDRESS(6,5+AP12*3+2),":",ADDRESS(5+AO12,5+AP12*3+2))),MATCH(B12,INDIRECT(_xlfn.TEXTJOIN("",TRUE,"SEM_",AN12,"!",ADDRESS(6,2),":",ADDRESS(5+AO12,2))),0)))+INDIRECT(_xlfn.TEXTJOIN("",TRUE,"TC_",AQ12,"!",ADDRESS(5+A12*(AR12+9),12))) -> #N/A | AL12: =IF(INDIRECT(_xlfn.TEXTJOIN("",TRUE,"TC_",AQ12,"!",ADDRESS(4+A12*(AR12+9),23))),SUM(INDIRECT(_xlfn.TEXTJOIN("",TRUE,"TC_",AQ12,"!",ADDRESS(4+A12*(AR12+9)-AR12,23),":",ADDRESS(3+A12*(AR12+9),23)))),0) -> 0 | AM12: =IF(LEFT(B12,1)="7",AJ12/$AK$4,AJ12/$AK$3) -> #N/A | AN12: =AN11 -> II | AO12: =AO11 -> 25 | AP12: =AP11 -> 10 | AQ12: =AQ11 -> III | AR12: =AR11 -> 8
A13: 8 | B13: 240090600008 | C13: UTU/2406100183 | D13: AYUSH RAWAT | E13: MUKESH RAWAT | AJ13: =IF(LEFT(B13,1)="7",0,INDEX(INDIRECT(_xlfn.TEXTJOIN("",TRUE,"SEM_",AN13,"!",ADDRESS(6,5+AP13*3+1),":",ADDRESS(5+AO13,5+AP13*3+1))),MATCH(B13,INDIRECT(_xlfn.TEXTJOIN("",TRUE,"SEM_",AN13,"!",ADDRESS(6,2),":",ADDRESS(5+AO13,2))),0)))+INDIRECT(_xlfn.TEXTJOIN("",TRUE,"TC_",AQ13,"!",ADDRESS(4+A13*(AR13+9),13))) -> #N/A | AK13: =IF(LEFT(B13,1)="7",0,INDEX(INDIRECT(_xlfn.TEXTJOIN("",TRUE,"SEM_",AN13,"!",ADDRESS(6,5+AP13*3+2),":",ADDRESS(5+AO13,5+AP13*3+2))),MATCH(B13,INDIRECT(_xlfn.TEXTJOIN("",TRUE,"SEM_",AN13,"!",ADDRESS(6,2),":",ADDRESS(5+AO13,2))),0)))+INDIRECT(_xlfn.TEXTJOIN("",TRUE,"TC_",AQ13,"!",ADDRESS(5+A13*(AR13+9),12))) -> #N/A | AL13: =IF(INDIRECT(_xlfn.TEXTJOIN("",TRUE,"TC_",AQ13,"!",ADDRESS(4+A13*(AR13+9),23))),SUM(INDIRECT(_xlfn.TEXTJOIN("",TRUE,"TC_",AQ13,"!",ADDRESS(4+A13*(AR13+9)-AR13,23),":",ADDRESS(3+A13*(AR13+9),23)))),0) -> 0 | AM13: =IF(LEFT(B13,1)="7",AJ13/$AK$4,AJ13/$AK$3) -> #N/A | AN13: =AN12 -> II | AO13: =AO12 -> 25 | AP13: =AP12 -> 10 | AQ13: =AQ12 -> III | AR13: =AR12 -> 8
A14: 9 | B14: 240090600009 | C14: UTU/2406100172 | D14: CHIRAG KASHYAP | E14: NARENDRA SINGH | AJ14: =IF(LEFT(B14,1)="7",0,INDEX(INDIRECT(_xlfn.TEXTJOIN("",TRUE,"SEM_",AN14,"!",ADDRESS(6,5+AP14*3+1),":",ADDRESS(5+AO14,5+AP14*3+1))),MATCH(B14,INDIRECT(_xlfn.TEXTJOIN("",TRUE,"SEM_",AN14,"!",ADDRESS(6,2),":",ADDRESS(5+AO14,2))),0)))+INDIRECT(_xlfn.TEXTJOIN("",TRUE,"TC_",AQ14,"!",ADDRESS(4+A14*(AR14+9),13))) -> #N/A | AK14: =IF(LEFT(B14,1)="7",0,INDEX(INDIRECT(_xlfn.TEXTJOIN("",TRUE,"SEM_",AN14,"!",ADDRESS(6,5+AP14*3+2),":",ADDRESS(5+AO14,5+AP14*3+2))),MATCH(B14,INDIRECT(_xlfn.TEXTJOIN("",TRUE,"SEM_",AN14,"!",ADDRESS(6,2),":",ADDRESS(5+AO14,2))),0)))+INDIRECT(_xlfn.TEXTJOIN("",TRUE,"TC_",AQ14,"!",ADDRESS(5+A14*(AR14+9),12))) -> #N/A | AL14: =IF(INDIRECT(_xlfn.TEXTJOIN("",TRUE,"TC_",AQ14,"!",ADDRESS(4+A14*(AR14+9),23))),SUM(INDIRECT(_xlfn.TEXTJOIN("",TRUE,"TC_",AQ14,"!",ADDRESS(4+A14*(AR14+9)-AR14,23),":",ADDRESS(3+A14*(AR14+9),23)))),0) -> 0 | AM14: =IF(LEFT(B14,1)="7",AJ14/$AK$4,AJ14/$AK$3) -> #N/A | AN14: =AN13 -> II | AO14: =AO13 -> 25 | AP14: =AP13 -> 10 | AQ14: =AQ13 -> III | AR14: =AR13 -> 8
